
#######################################################################
# +-----------------------------------------------------------------+ #
# |                            BO3 object                           | #
# +-----------------------------------------------------------------+ #
#######################################################################

Author: Unknown

Description: No description

Version: 3

SettingsMode: WriteWithoutComments


#######################################################################
# +-----------------------------------------------------------------+ #
# |                          Main settings                          | #
# +-----------------------------------------------------------------+ #
#######################################################################

Tree: false

Frequency: 1

Rarity: 100.0

RotateRandomly: true

SpawnHeight: randomY

SpawnHeightOffset: 0

SpawnHeightVariance: 0

##############################
# Height Limits for the BO3. #
##############################

MinHeight: 58

MaxHeight: 67

######################
# Extrusion settings #
######################

ExtrudeMode: None

ExtrudeThroughBlocks: AIR

MaxBranchDepth: 10

ExcludedBiomes: All


#######################################################################
# +-----------------------------------------------------------------+ #
# |                      Source block settings                      | #
# +-----------------------------------------------------------------+ #
#######################################################################

SourceBlocks: GRASS,DIRT,GRAVEL,SAND,SAND:1,SANDSTONE,STONE,STONE:1,STONE:3,STONE:5,DIRT:1,CLAY,CONCRETE,CONCRETE,RED_ROSE,RED_ROSE:1,RED_ROSE:2,RED_ROSE:3,RED_ROSE:4,RED_ROSE:5,RED_ROSE:6,RED_ROSE:7,RED_ROSE:8,BROWN_MUSHROOM,RED_MUSHROOM,DOUBLE_PLANT,DOUBLE_PLANT:1,DOUBLE_PLANT:2,DOUBLE_PLANT:3,DOUBLE_PLANT:4,DOUBLE_PLANT:5,LONG_GRASS,LONG_GRASS:1,LONG_GRASS:2,DEAD_BUSH,COAL_ORE,IRON_ORE,GOLD_ORE,REDSTONE_ORE,DIAMOND_ORE,LAPIS_ORE,EMERALD_ORE,VINE,AIR,STATIONARY_WATER

MaxPercentageOutsideSourceBlock: 20

OutsideSourceBlock: placeAnyway

DoReplaceBlocks: true

IsOTGPlus: false


#######################################################################
# +-----------------------------------------------------------------+ #
# |                              Blocks                             | #
# +-----------------------------------------------------------------+ #
#######################################################################

Block(-8,3,-2,CONCRETE)
Block(-8,4,-3,CONCRETE)
Block(-8,4,-2,CONCRETE)
Block(-7,2,-4,CONCRETE)
Block(-7,2,-3,CONCRETE)
Block(-7,2,-2,CONCRETE)
Block(-7,3,-5,CONCRETE)
Block(-7,3,-4,CONCRETE)
Block(-7,3,-3,CONCRETE)
Block(-7,3,-2,CONCRETE)
Block(-7,3,-1,CONCRETE)
Block(-7,4,-7,CONCRETE)
Block(-7,4,-5,CONCRETE)
Block(-7,4,-4,CONCRETE)
Block(-7,4,-3,CONCRETE)
Block(-7,4,-2,CONCRETE)
Block(-7,4,-1,CONCRETE)
Block(-7,5,-5,CONCRETE)
Block(-7,5,-4,CONCRETE)
Block(-7,5,-3,CONCRETE)
Block(-7,5,-2,CONCRETE)
Block(-7,5,-1,CONCRETE)
Block(-7,6,-4,CONCRETE)
Block(-7,6,-2,CONCRETE)
Block(-6,1,-1,CONCRETE)
Block(-6,2,-6,CONCRETE)
Block(-6,2,-5,CONCRETE)
Block(-6,2,-4,CONCRETE)
Block(-6,2,-3,CONCRETE)
Block(-6,2,-2,CONCRETE)
Block(-6,2,-1,CONCRETE)
Block(-6,3,-6,CONCRETE)
Block(-6,3,-5,CONCRETE)
Block(-6,3,-4,CONCRETE)
Block(-6,3,-3,CONCRETE)
Block(-6,3,-2,CONCRETE)
Block(-6,3,-1,CONCRETE)
Block(-6,3,0,CONCRETE)
Block(-6,4,-7,CONCRETE)
Block(-6,4,-6,CONCRETE)
Block(-6,4,-5,CONCRETE)
Block(-6,4,-4,CONCRETE)
Block(-6,4,-3,CONCRETE)
Block(-6,4,-2,CONCRETE)
Block(-6,4,-1,CONCRETE)
Block(-6,4,0,CONCRETE)
Block(-6,5,-6,CONCRETE)
Block(-6,5,-5,CONCRETE)
Block(-6,5,-4,CONCRETE)
Block(-6,5,-3,CONCRETE)
Block(-6,5,-2,CONCRETE)
Block(-6,5,-1,CONCRETE)
Block(-6,5,0,CONCRETE)
Block(-6,6,-6,CONCRETE)
Block(-6,6,-5,CONCRETE)
Block(-6,6,-4,CONCRETE)
Block(-6,6,-3,CONCRETE)
Block(-6,6,-2,CONCRETE)
Block(-6,6,-1,CONCRETE)
Block(-6,7,-1,CONCRETE)
Block(-5,0,-4,CONCRETE)
Block(-5,0,-1,CONCRETE)
Block(-5,1,-5,CONCRETE)
Block(-5,1,-4,CONCRETE)
Block(-5,1,-3,CONCRETE)
Block(-5,1,-2,CONCRETE)
Block(-5,1,-1,CONCRETE)
Block(-5,1,0,CONCRETE)
Block(-5,2,-7,CONCRETE)
Block(-5,2,-6,CONCRETE)
Block(-5,2,-5,CONCRETE)
Block(-5,2,-4,CONCRETE)
Block(-5,2,-3,CONCRETE)
Block(-5,2,-2,CONCRETE)
Block(-5,2,-1,CONCRETE)
Block(-5,2,0,CONCRETE)
Block(-5,3,-7,CONCRETE)
Block(-5,3,-6,CONCRETE)
Block(-5,3,-5,CONCRETE)
Block(-5,3,-4,CONCRETE)
Block(-5,3,-3,CONCRETE)
Block(-5,3,-2,CONCRETE)
Block(-5,3,-1,CONCRETE)
Block(-5,3,0,CONCRETE)
Block(-5,4,-7,CONCRETE)
Block(-5,4,-6,CONCRETE)
Block(-5,4,-5,CONCRETE)
Block(-5,4,-4,CONCRETE)
Block(-5,4,-3,CONCRETE)
Block(-5,4,-2,CONCRETE)
Block(-5,4,-1,CONCRETE)
Block(-5,4,0,CONCRETE)
Block(-5,5,-7,CONCRETE)
Block(-5,5,-6,CONCRETE)
Block(-5,5,-5,CONCRETE)
Block(-5,5,-4,CONCRETE)
Block(-5,5,-3,CONCRETE)
Block(-5,5,-2,CONCRETE)
Block(-5,5,-1,CONCRETE)
Block(-5,5,0,CONCRETE)
Block(-5,6,-7,CONCRETE)
Block(-5,6,-6,CONCRETE)
Block(-5,6,-5,CONCRETE)
Block(-5,6,-4,CONCRETE)
Block(-5,6,-3,CONCRETE)
Block(-5,6,-2,CONCRETE)
Block(-5,6,-1,CONCRETE)
Block(-5,6,0,CONCRETE)
Block(-5,7,-5,CONCRETE)
Block(-5,7,-4,CONCRETE)
Block(-5,7,-3,CONCRETE)
Block(-5,7,-2,CONCRETE)
Block(-5,7,-1,CONCRETE)
Block(-5,7,0,CONCRETE)
Block(-5,8,-4,CONCRETE)
Block(-5,8,-1,CONCRETE)
Block(-4,0,-5,CONCRETE)
Block(-4,0,-4,CONCRETE)
Block(-4,0,-3,CONCRETE)
Block(-4,0,-1,CONCRETE)
Block(-4,1,-6,CONCRETE)
Block(-4,1,-5,CONCRETE)
Block(-4,1,-4,CONCRETE)
Block(-4,1,-3,CONCRETE)
Block(-4,1,-2,CONCRETE)
Block(-4,1,-1,CONCRETE)
Block(-4,2,-6,CONCRETE)
Block(-4,2,-5,CONCRETE)
Block(-4,2,-4,CONCRETE)
Block(-4,2,-3,CONCRETE)
Block(-4,2,-2,CONCRETE)
Block(-4,2,-1,CONCRETE)
Block(-4,2,0,CONCRETE)
Block(-4,3,-6,CONCRETE)
Block(-4,3,-5,CONCRETE)
Block(-4,3,-4,CONCRETE)
Block(-4,3,-3,CONCRETE)
Block(-4,3,-2,CONCRETE)
Block(-4,3,-1,CONCRETE)
Block(-4,4,-7,CONCRETE)
Block(-4,4,-6,CONCRETE)
Block(-4,4,-5,CONCRETE)
Block(-4,4,-4,CONCRETE)
Block(-4,4,-3,CONCRETE)
Block(-4,4,-2,CONCRETE)
Block(-4,4,-1,CONCRETE)
Block(-4,5,-6,CONCRETE)
Block(-4,5,-5,CONCRETE)
Block(-4,5,-4,CONCRETE)
Block(-4,5,-3,CONCRETE)
Block(-4,5,-2,CONCRETE)
Block(-4,5,-1,CONCRETE)
Block(-4,5,0,CONCRETE)
Block(-4,6,-6,CONCRETE)
Block(-4,6,-5,CONCRETE)
Block(-4,6,-4,CONCRETE)
Block(-4,6,-3,CONCRETE)
Block(-4,6,-2,CONCRETE)
Block(-4,6,-1,CONCRETE)
Block(-4,6,0,CONCRETE)
Block(-4,7,-6,CONCRETE)
Block(-4,7,-5,CONCRETE)
Block(-4,7,-4,CONCRETE)
Block(-4,7,-3,CONCRETE)
Block(-4,7,-2,CONCRETE)
Block(-4,7,-1,CONCRETE)
Block(-4,8,-5,CONCRETE)
Block(-4,8,-4,CONCRETE)
Block(-4,8,-3,CONCRETE)
Block(-4,8,-1,CONCRETE)
Block(-3,0,-4,CONCRETE)
Block(-3,0,-3,CONCRETE)
Block(-3,0,-2,CONCRETE)
Block(-3,0,-1,CONCRETE)
Block(-3,1,-5,CONCRETE)
Block(-3,1,-4,CONCRETE)
Block(-3,1,-3,CONCRETE)
Block(-3,1,-2,CONCRETE)
Block(-3,1,-1,CONCRETE)
Block(-3,2,-5,CONCRETE)
Block(-3,2,-4,CONCRETE)
Block(-3,2,-3,CONCRETE)
Block(-3,2,-2,CONCRETE)
Block(-3,2,-1,CONCRETE)
Block(-3,3,-6,CONCRETE)
Block(-3,3,-5,CONCRETE)
Block(-3,3,-4,CONCRETE)
Block(-3,3,-3,CONCRETE)
Block(-3,3,-2,CONCRETE)
Block(-3,3,-1,CONCRETE)
Block(-3,4,-6,CONCRETE)
Block(-3,4,-5,CONCRETE)
Block(-3,4,-4,CONCRETE)
Block(-3,4,-3,CONCRETE)
Block(-3,4,-2,CONCRETE)
Block(-3,4,-1,CONCRETE)
Block(-3,5,-6,CONCRETE)
Block(-3,5,-5,CONCRETE)
Block(-3,5,-4,CONCRETE)
Block(-3,5,-3,CONCRETE)
Block(-3,5,-2,CONCRETE)
Block(-3,5,-1,CONCRETE)
Block(-3,6,-5,CONCRETE)
Block(-3,6,-4,CONCRETE)
Block(-3,6,-3,CONCRETE)
Block(-3,6,-2,CONCRETE)
Block(-3,6,-1,CONCRETE)
Block(-3,7,-5,CONCRETE)
Block(-3,7,-4,CONCRETE)
Block(-3,7,-3,CONCRETE)
Block(-3,7,-2,CONCRETE)
Block(-3,7,-1,CONCRETE)
Block(-3,8,-4,CONCRETE)
Block(-3,8,-3,CONCRETE)
Block(-3,8,-2,CONCRETE)
Block(-3,9,-3,CONCRETE)
Block(-2,0,-4,CONCRETE)
Block(-2,0,-3,CONCRETE)
Block(-2,0,-2,CONCRETE)
Block(-2,1,-5,CONCRETE)
Block(-2,1,-4,CONCRETE)
Block(-2,1,-3,CONCRETE)
Block(-2,1,-2,CONCRETE)
Block(-2,1,-1,CONCRETE)
Block(-2,2,-6,CONCRETE)
Block(-2,2,-5,CONCRETE)
Block(-2,2,-4,CONCRETE)
Block(-2,2,-3,CONCRETE)
Block(-2,2,-2,CONCRETE)
Block(-2,2,-1,CONCRETE)
Block(-2,2,0,CONCRETE)
Block(-2,3,-5,CONCRETE)
Block(-2,3,-4,CONCRETE)
Block(-2,3,-3,CONCRETE)
Block(-2,3,-2,CONCRETE)
Block(-2,3,-1,CONCRETE)
Block(-2,3,0,CONCRETE)
Block(-2,4,-5,CONCRETE)
Block(-2,4,-4,CONCRETE)
Block(-2,4,-3,CONCRETE)
Block(-2,4,-2,CONCRETE)
Block(-2,4,-1,CONCRETE)
Block(-2,4,0,CONCRETE)
Block(-2,5,-6,CONCRETE)
Block(-2,5,-5,CONCRETE)
Block(-2,5,-4,CONCRETE)
Block(-2,5,-3,CONCRETE)
Block(-2,5,-2,CONCRETE)
Block(-2,5,-1,CONCRETE)
Block(-2,6,-6,CONCRETE)
Block(-2,6,-5,CONCRETE)
Block(-2,6,-4,CONCRETE)
Block(-2,6,-3,CONCRETE)
Block(-2,6,-2,CONCRETE)
Block(-2,6,-1,CONCRETE)
Block(-2,7,-5,CONCRETE)
Block(-2,7,-4,CONCRETE)
Block(-2,7,-3,CONCRETE)
Block(-2,7,-2,CONCRETE)
Block(-2,8,-4,CONCRETE)
Block(-2,8,-3,CONCRETE)
Block(-2,8,-2,CONCRETE)
Block(-2,9,-3,CONCRETE)
Block(-1,1,-4,CONCRETE)
Block(-1,1,-3,CONCRETE)
Block(-1,2,-5,CONCRETE)
Block(-1,2,-4,CONCRETE)
Block(-1,2,-3,CONCRETE)
Block(-1,2,-2,CONCRETE)
Block(-1,2,-1,CONCRETE)
Block(-1,3,-5,CONCRETE)
Block(-1,3,-4,CONCRETE)
Block(-1,3,-3,CONCRETE)
Block(-1,3,-2,CONCRETE)
Block(-1,3,-1,CONCRETE)
Block(-1,3,0,CONCRETE)
Block(-1,4,-4,CONCRETE)
Block(-1,4,-3,CONCRETE)
Block(-1,4,-2,CONCRETE)
Block(-1,4,-1,CONCRETE)
Block(-1,4,0,CONCRETE)
Block(-1,5,-5,CONCRETE)
Block(-1,5,-4,CONCRETE)
Block(-1,5,-3,CONCRETE)
Block(-1,5,-2,CONCRETE)
Block(-1,5,-1,CONCRETE)
Block(-1,5,0,CONCRETE)
Block(-1,6,-5,CONCRETE)
Block(-1,6,-4,CONCRETE)
Block(-1,6,-3,CONCRETE)
Block(-1,6,-2,CONCRETE)
Block(-1,6,-1,CONCRETE)
Block(-1,7,-4,CONCRETE)
Block(-1,7,-3,CONCRETE)
Block(0,3,-1,CONCRETE)
Block(0,4,-3,CONCRETE)
Block(0,4,-2,CONCRETE)
Block(0,4,-1,CONCRETE)
Block(0,5,-3,CONCRETE)
Block(0,5,-2,CONCRETE)
Block(0,5,-1,CONCRETE)

#######################################################################
# +-----------------------------------------------------------------+ #
# |                            BO3 checks                           | #
# +-----------------------------------------------------------------+ #
#######################################################################

BlockCheck(0,4,0,CONCRETE)

#######################################################################
# +-----------------------------------------------------------------+ #
# |                             Branches                            | #
# +-----------------------------------------------------------------+ #
#######################################################################


#######################################################################
# +-----------------------------------------------------------------+ #
# |                             Entities                            | #
# +-----------------------------------------------------------------+ #
#######################################################################


#######################################################################
# +-----------------------------------------------------------------+ #
# |                            Particles                            | #
# +-----------------------------------------------------------------+ #
#######################################################################


#######################################################################
# +-----------------------------------------------------------------+ #
# |                             Spawners                            | #
# +-----------------------------------------------------------------+ #
#######################################################################


#######################################################################
# +-----------------------------------------------------------------+ #
# |                             ModData                             | #
# +-----------------------------------------------------------------+ #
#######################################################################

