
#######################################################################
# +-----------------------------------------------------------------+ #
# |                            BO3 object                           | #
# +-----------------------------------------------------------------+ #
#######################################################################

Author: Unknown

Description: No description

Version: 3

SettingsMode: WriteWithoutComments


#######################################################################
# +-----------------------------------------------------------------+ #
# |                          Main settings                          | #
# +-----------------------------------------------------------------+ #
#######################################################################

Tree: false

Frequency: 1

Rarity: 100.0

RotateRandomly: true

SpawnHeight: randomY

SpawnHeightOffset: 0

SpawnHeightVariance: 0

##############################
# Height Limits for the BO3. #
##############################

MinHeight: 58

MaxHeight: 67

######################
# Extrusion settings #
######################

ExtrudeMode: None

ExtrudeThroughBlocks: AIR

MaxBranchDepth: 10

ExcludedBiomes: All


#######################################################################
# +-----------------------------------------------------------------+ #
# |                      Source block settings                      | #
# +-----------------------------------------------------------------+ #
#######################################################################

SourceBlocks: GRASS,DIRT,GRAVEL,SAND,SAND:1,SANDSTONE,STONE,STONE:1,STONE:3,STONE:5,DIRT:1,CLAY,CONCRETE,CONCRETE,RED_ROSE,RED_ROSE:1,RED_ROSE:2,RED_ROSE:3,RED_ROSE:4,RED_ROSE:5,RED_ROSE:6,RED_ROSE:7,RED_ROSE:8,BROWN_MUSHROOM,RED_MUSHROOM,DOUBLE_PLANT,DOUBLE_PLANT:1,DOUBLE_PLANT:2,DOUBLE_PLANT:3,DOUBLE_PLANT:4,DOUBLE_PLANT:5,LONG_GRASS,LONG_GRASS:1,LONG_GRASS:2,DEAD_BUSH,COAL_ORE,IRON_ORE,GOLD_ORE,REDSTONE_ORE,DIAMOND_ORE,LAPIS_ORE,EMERALD_ORE,VINE,AIR,STATIONARY_WATER

MaxPercentageOutsideSourceBlock: 20

OutsideSourceBlock: placeAnyway

DoReplaceBlocks: true

IsOTGPlus: false


#######################################################################
# +-----------------------------------------------------------------+ #
# |                              Blocks                             | #
# +-----------------------------------------------------------------+ #
#######################################################################

Block(-8,2,-4,CONCRETE:1)
Block(-7,0,-4,CONCRETE:1)
Block(-7,1,-5,CONCRETE:1)
Block(-7,1,-4,CONCRETE:1)
Block(-7,1,-3,CONCRETE:1)
Block(-7,2,-6,CONCRETE:1)
Block(-7,2,-5,CONCRETE:1)
Block(-7,2,-4,CONCRETE:1)
Block(-7,2,-3,CONCRETE:1)
Block(-7,2,-2,CONCRETE:1)
Block(-7,3,-5,CONCRETE:1)
Block(-7,3,-4,CONCRETE:1)
Block(-7,3,-3,CONCRETE:1)
Block(-7,4,-4,CONCRETE:1)
Block(-6,0,-5,CONCRETE:1)
Block(-6,0,-4,CONCRETE:1)
Block(-6,0,-3,CONCRETE:1)
Block(-6,1,-5,CONCRETE:1)
Block(-6,1,-4,CONCRETE:1)
Block(-6,1,-3,CONCRETE:1)
Block(-6,1,-2,CONCRETE:1)
Block(-6,2,-5,CONCRETE:1)
Block(-6,2,-4,CONCRETE:1)
Block(-6,2,-3,CONCRETE:1)
Block(-6,2,-2,CONCRETE:1)
Block(-6,2,-1,CONCRETE:1)
Block(-6,3,-5,CONCRETE:1)
Block(-6,3,-4,CONCRETE:1)
Block(-6,3,-3,CONCRETE:1)
Block(-6,3,-2,CONCRETE:1)
Block(-6,4,-5,CONCRETE:1)
Block(-6,4,-4,CONCRETE:1)
Block(-6,4,-3,CONCRETE:1)
Block(-5,0,-5,CONCRETE:1)
Block(-5,0,-4,CONCRETE:1)
Block(-5,0,-3,CONCRETE:1)
Block(-5,0,-2,CONCRETE:1)
Block(-5,0,-1,CONCRETE:1)
Block(-5,1,-6,CONCRETE:1)
Block(-5,1,-5,CONCRETE:1)
Block(-5,1,-4,CONCRETE:1)
Block(-5,1,-3,CONCRETE:1)
Block(-5,1,-2,CONCRETE:1)
Block(-5,1,-1,CONCRETE:1)
Block(-5,2,-6,CONCRETE:1)
Block(-5,2,-5,CONCRETE:1)
Block(-5,2,-4,CONCRETE:1)
Block(-5,2,-3,CONCRETE:1)
Block(-5,2,-2,CONCRETE:1)
Block(-5,2,-1,CONCRETE:1)
Block(-5,2,0,CONCRETE:1)
Block(-5,3,-6,CONCRETE:1)
Block(-5,3,-5,CONCRETE:1)
Block(-5,3,-4,CONCRETE:1)
Block(-5,3,-3,CONCRETE:1)
Block(-5,3,-2,CONCRETE:1)
Block(-5,3,-1,CONCRETE:1)
Block(-5,4,-5,CONCRETE:1)
Block(-5,4,-4,CONCRETE:1)
Block(-5,4,-3,CONCRETE:1)
Block(-5,4,-2,CONCRETE:1)
Block(-5,4,-1,CONCRETE:1)
Block(-4,0,-5,CONCRETE:1)
Block(-4,0,-4,CONCRETE:1)
Block(-4,0,-3,CONCRETE:1)
Block(-4,0,-2,CONCRETE:1)
Block(-4,0,-1,CONCRETE:1)
Block(-4,1,-5,CONCRETE:1)
Block(-4,1,-4,CONCRETE:1)
Block(-4,1,-3,CONCRETE:1)
Block(-4,1,-2,CONCRETE:1)
Block(-4,1,-1,CONCRETE:1)
Block(-4,1,0,CONCRETE:1)
Block(-4,2,-5,CONCRETE:1)
Block(-4,2,-4,CONCRETE:1)
Block(-4,2,-3,CONCRETE:1)
Block(-4,2,-2,CONCRETE:1)
Block(-4,2,-1,CONCRETE:1)
Block(-4,2,0,CONCRETE:1)
Block(-4,2,1,CONCRETE:1)
Block(-4,3,-5,CONCRETE:1)
Block(-4,3,-4,CONCRETE:1)
Block(-4,3,-3,CONCRETE:1)
Block(-4,3,-2,CONCRETE:1)
Block(-4,3,-1,CONCRETE:1)
Block(-4,3,0,CONCRETE:1)
Block(-4,4,-5,CONCRETE:1)
Block(-4,4,-4,CONCRETE:1)
Block(-4,4,-3,CONCRETE:1)
Block(-4,4,-2,CONCRETE:1)
Block(-4,4,-1,CONCRETE:1)
Block(-3,0,-5,CONCRETE:1)
Block(-3,0,-4,CONCRETE:1)
Block(-3,0,-3,CONCRETE:1)
Block(-3,0,-2,CONCRETE:1)
Block(-3,0,-1,CONCRETE:1)
Block(-3,0,0,CONCRETE:1)
Block(-3,1,-5,CONCRETE:1)
Block(-3,1,-4,CONCRETE:1)
Block(-3,1,-3,CONCRETE:1)
Block(-3,1,-2,CONCRETE:1)
Block(-3,1,-1,CONCRETE:1)
Block(-3,1,0,CONCRETE:1)
Block(-3,1,1,CONCRETE:1)
Block(-3,2,-5,CONCRETE:1)
Block(-3,2,-4,CONCRETE:1)
Block(-3,2,-3,CONCRETE:1)
Block(-3,2,-2,CONCRETE:1)
Block(-3,2,-1,CONCRETE:1)
Block(-3,2,0,CONCRETE:1)
Block(-3,2,1,CONCRETE:1)
Block(-3,3,-5,CONCRETE:1)
Block(-3,3,-4,CONCRETE:1)
Block(-3,3,-3,CONCRETE:1)
Block(-3,3,-2,CONCRETE:1)
Block(-3,3,-1,CONCRETE:1)
Block(-3,3,0,CONCRETE:1)
Block(-3,3,1,CONCRETE:1)
Block(-3,4,-6,CONCRETE:1)
Block(-3,4,-5,CONCRETE:1)
Block(-3,4,-4,CONCRETE:1)
Block(-3,4,-3,CONCRETE:1)
Block(-3,4,-2,CONCRETE:1)
Block(-3,4,-1,CONCRETE:1)
Block(-3,4,0,CONCRETE:1)
Block(-2,0,-6,CONCRETE:1)
Block(-2,0,-5,CONCRETE:1)
Block(-2,0,-4,CONCRETE:1)
Block(-2,0,-3,CONCRETE:1)
Block(-2,0,-2,CONCRETE:1)
Block(-2,0,-1,CONCRETE:1)
Block(-2,1,-6,CONCRETE:1)
Block(-2,1,-5,CONCRETE:1)
Block(-2,1,-4,CONCRETE:1)
Block(-2,1,-3,CONCRETE:1)
Block(-2,1,-2,CONCRETE:1)
Block(-2,1,-1,CONCRETE:1)
Block(-2,1,0,CONCRETE:1)
Block(-2,2,-6,CONCRETE:1)
Block(-2,2,-5,CONCRETE:1)
Block(-2,2,-4,CONCRETE:1)
Block(-2,2,-3,CONCRETE:1)
Block(-2,2,-2,CONCRETE:1)
Block(-2,2,-1,CONCRETE:1)
Block(-2,2,0,CONCRETE:1)
Block(-2,3,-6,CONCRETE:1)
Block(-2,3,-5,CONCRETE:1)
Block(-2,3,-4,CONCRETE:1)
Block(-2,3,-3,CONCRETE:1)
Block(-2,3,-2,CONCRETE:1)
Block(-2,3,-1,CONCRETE:1)
Block(-2,3,0,CONCRETE:1)
Block(-2,4,-6,CONCRETE:1)
Block(-2,4,-5,CONCRETE:1)
Block(-2,4,-4,CONCRETE:1)
Block(-2,4,-3,CONCRETE:1)
Block(-2,4,-2,CONCRETE:1)
Block(-2,4,-1,CONCRETE:1)
Block(-1,0,-6,CONCRETE:1)
Block(-1,0,-5,CONCRETE:1)
Block(-1,0,-4,CONCRETE:1)
Block(-1,0,-3,CONCRETE:1)
Block(-1,0,-2,CONCRETE:1)
Block(-1,0,-1,CONCRETE:1)
Block(-1,1,-6,CONCRETE:1)
Block(-1,1,-5,CONCRETE:1)
Block(-1,1,-4,CONCRETE:1)
Block(-1,1,-3,CONCRETE:1)
Block(-1,1,-2,CONCRETE:1)
Block(-1,1,-1,CONCRETE:1)
Block(-1,1,0,CONCRETE:1)
Block(-1,2,-6,CONCRETE:1)
Block(-1,2,-5,CONCRETE:1)
Block(-1,2,-4,CONCRETE:1)
Block(-1,2,-3,CONCRETE:1)
Block(-1,2,-2,CONCRETE:1)
Block(-1,2,-1,CONCRETE:1)
Block(-1,2,0,CONCRETE:1)
Block(-1,3,-6,CONCRETE:1)
Block(-1,3,-5,CONCRETE:1)
Block(-1,3,-4,CONCRETE:1)
Block(-1,3,-3,CONCRETE:1)
Block(-1,3,-2,CONCRETE:1)
Block(-1,3,-1,CONCRETE:1)
Block(-1,3,0,CONCRETE:1)
Block(-1,4,-6,CONCRETE:1)
Block(-1,4,-5,CONCRETE:1)
Block(-1,4,-4,CONCRETE:1)
Block(-1,4,-3,CONCRETE:1)
Block(-1,4,-2,CONCRETE:1)
Block(-1,4,-1,CONCRETE:1)
Block(0,0,-6,CONCRETE:1)
Block(0,0,-5,CONCRETE:1)
Block(0,0,-4,CONCRETE:1)
Block(0,0,-3,CONCRETE:1)
Block(0,0,-2,CONCRETE:1)
Block(0,0,-1,CONCRETE:1)
Block(0,1,-6,CONCRETE:1)
Block(0,1,-5,CONCRETE:1)
Block(0,1,-4,CONCRETE:1)
Block(0,1,-3,CONCRETE:1)
Block(0,1,-2,CONCRETE:1)
Block(0,1,-1,CONCRETE:1)
Block(0,1,0,CONCRETE:1)
Block(0,2,-7,CONCRETE:1)
Block(0,2,-6,CONCRETE:1)
Block(0,2,-5,CONCRETE:1)
Block(0,2,-4,CONCRETE:1)
Block(0,2,-3,CONCRETE:1)
Block(0,2,-2,CONCRETE:1)
Block(0,2,-1,CONCRETE:1)
Block(0,2,0,CONCRETE:1)
Block(0,3,-6,CONCRETE:1)
Block(0,3,-5,CONCRETE:1)
Block(0,3,-4,CONCRETE:1)
Block(0,3,-3,CONCRETE:1)
Block(0,3,-2,CONCRETE:1)
Block(0,4,-5,CONCRETE:1)
Block(0,4,-4,CONCRETE:1)
Block(0,4,-3,CONCRETE:1)
Block(0,4,-2,CONCRETE:1)
Block(1,0,-6,CONCRETE:1)
Block(1,0,-5,CONCRETE:1)
Block(1,0,-4,CONCRETE:1)
Block(1,0,-3,CONCRETE:1)
Block(1,0,-2,CONCRETE:1)
Block(1,0,-1,CONCRETE:1)
Block(1,1,-6,CONCRETE:1)
Block(1,1,-5,CONCRETE:1)
Block(1,1,-4,CONCRETE:1)
Block(1,1,-3,CONCRETE:1)
Block(1,1,-2,CONCRETE:1)
Block(1,1,-1,CONCRETE:1)
Block(1,2,-7,CONCRETE:1)
Block(1,2,-6,CONCRETE:1)
Block(1,2,-5,CONCRETE:1)
Block(1,2,-4,CONCRETE:1)
Block(1,2,-3,CONCRETE:1)
Block(1,2,-2,CONCRETE:1)
Block(1,2,-1,CONCRETE:1)
Block(1,3,-6,CONCRETE:1)
Block(1,3,-5,CONCRETE:1)
Block(1,3,-4,CONCRETE:1)
Block(1,3,-3,CONCRETE:1)
Block(1,3,-2,CONCRETE:1)
Block(1,4,-5,CONCRETE:1)
Block(1,4,-4,CONCRETE:1)
Block(1,4,-3,CONCRETE:1)
Block(2,0,-5,CONCRETE:1)
Block(2,0,-4,CONCRETE:1)
Block(2,0,-3,CONCRETE:1)
Block(2,0,-2,CONCRETE:1)
Block(2,0,-1,CONCRETE:1)
Block(2,1,-6,CONCRETE:1)
Block(2,1,-5,CONCRETE:1)
Block(2,1,-4,CONCRETE:1)
Block(2,1,-3,CONCRETE:1)
Block(2,1,-2,CONCRETE:1)
Block(2,1,-1,CONCRETE:1)
Block(2,2,-6,CONCRETE:1)
Block(2,2,-5,CONCRETE:1)
Block(2,2,-4,CONCRETE:1)
Block(2,2,-3,CONCRETE:1)
Block(2,2,-2,CONCRETE:1)
Block(2,2,-1,CONCRETE:1)
Block(2,3,-5,CONCRETE:1)
Block(2,3,-4,CONCRETE:1)
Block(2,3,-3,CONCRETE:1)
Block(2,4,-4,CONCRETE:1)
Block(3,0,-4,CONCRETE:1)
Block(3,0,-3,CONCRETE:1)
Block(3,0,-2,CONCRETE:1)
Block(3,1,-5,CONCRETE:1)
Block(3,1,-4,CONCRETE:1)
Block(3,1,-3,CONCRETE:1)
Block(3,1,-2,CONCRETE:1)
Block(3,1,-1,CONCRETE:1)
Block(3,2,-6,CONCRETE:1)
Block(3,2,-5,CONCRETE:1)
Block(3,2,-4,CONCRETE:1)
Block(3,2,-3,CONCRETE:1)
Block(3,2,-2,CONCRETE:1)
Block(3,3,-4,CONCRETE:1)
Block(3,3,-3,CONCRETE:1)

#######################################################################
# +-----------------------------------------------------------------+ #
# |                            BO3 checks                           | #
# +-----------------------------------------------------------------+ #
#######################################################################

BlockCheck(0,2,0,CONCRETE:1)

#######################################################################
# +-----------------------------------------------------------------+ #
# |                             Branches                            | #
# +-----------------------------------------------------------------+ #
#######################################################################


#######################################################################
# +-----------------------------------------------------------------+ #
# |                             Entities                            | #
# +-----------------------------------------------------------------+ #
#######################################################################


#######################################################################
# +-----------------------------------------------------------------+ #
# |                            Particles                            | #
# +-----------------------------------------------------------------+ #
#######################################################################


#######################################################################
# +-----------------------------------------------------------------+ #
# |                             Spawners                            | #
# +-----------------------------------------------------------------+ #
#######################################################################


#######################################################################
# +-----------------------------------------------------------------+ #
# |                             ModData                             | #
# +-----------------------------------------------------------------+ #
#######################################################################

