
#######################################################################
# +-----------------------------------------------------------------+ #
# |                            BO3 object                           | #
# +-----------------------------------------------------------------+ #
#######################################################################

Author: LordSmellyPants

Description: No description given

Version: 3

SettingsMode: WriteWithoutComments


#######################################################################
# +-----------------------------------------------------------------+ #
# |                          Main settings                          | #
# +-----------------------------------------------------------------+ #
#######################################################################

Tree: false

Frequency: 1

Rarity: 4.0

RotateRandomly: true

SpawnHeight: randomY

SpawnHeightOffset: 0

SpawnHeightVariance: 0

##############################
# Height Limits for the BO3. #
##############################

MinHeight: 53

MaxHeight: 63

######################
# Extrusion settings #
######################

ExtrudeMode: None

ExtrudeThroughBlocks: AIR

MaxBranchDepth: 10

ExcludedBiomes: All


#######################################################################
# +-----------------------------------------------------------------+ #
# |                      Source block settings                      | #
# +-----------------------------------------------------------------+ #
#######################################################################

SourceBlocks: GRASS,DIRT,GRAVEL,SAND,SAND:1,SANDSTONE,STONE,STONE:1,STONE:3,STONE:5,DIRT:1,CLAY,CONCRETE,CONCRETE,RED_ROSE,RED_ROSE:1,RED_ROSE:2,RED_ROSE:3,RED_ROSE:4,RED_ROSE:5,RED_ROSE:6,RED_ROSE:7,RED_ROSE:8,BROWN_MUSHROOM,RED_MUSHROOM,DOUBLE_PLANT,DOUBLE_PLANT:1,DOUBLE_PLANT:2,DOUBLE_PLANT:3,DOUBLE_PLANT:4,DOUBLE_PLANT:5,LONG_GRASS,LONG_GRASS:1,LONG_GRASS:2,DEAD_BUSH,COAL_ORE,IRON_ORE,GOLD_ORE,REDSTONE_ORE,DIAMOND_ORE,LAPIS_ORE,EMERALD_ORE,VINE,AIR,STATIONARY_WATER

MaxPercentageOutsideSourceBlock: 20

OutsideSourceBlock: placeAnyway


#######################################################################
# +-----------------------------------------------------------------+ #
# |                              Blocks                             | #
# +-----------------------------------------------------------------+ #
#######################################################################

B(-5,-2,0,CONCRETE:1)
B(-5,-1,-1,CONCRETE:1)
B(-5,-1,0,CONCRETE:1)
B(-5,-1,1,CONCRETE:1)
B(-5,0,-2,CONCRETE:1)
B(-5,0,-1,CONCRETE:1)
B(-5,0,0,CONCRETE:1)
B(-5,0,1,CONCRETE:1)
B(-5,1,-2,CONCRETE:1)
B(-5,1,-1,CONCRETE:1)
B(-5,1,0,CONCRETE:1)
B(-5,1,1,CONCRETE:1)
B(-5,2,-2,CONCRETE:1)
B(-5,2,-1,CONCRETE:1)
B(-5,2,0,CONCRETE:1)
B(-5,2,1,CONCRETE:1)
B(-5,3,0,CONCRETE:1)
B(-5,4,0,CONCRETE:4)
B(-4,-3,1,CONCRETE:1)
B(-4,-2,-1,CONCRETE:1)
B(-4,-2,0,CONCRETE:1)
B(-4,-2,1,CONCRETE:1)
B(-4,-2,2,CONCRETE:1)
B(-4,-1,-2,CONCRETE:1)
B(-4,-1,-1,CONCRETE:1)
B(-4,-1,0,CONCRETE:1)
B(-4,-1,1,CONCRETE:1)
B(-4,-1,2,CONCRETE:1)
B(-4,0,-2,CONCRETE:1)
B(-4,0,-1,CONCRETE:1)
B(-4,0,0,CONCRETE:1)
B(-4,0,1,CONCRETE:1)
B(-4,0,2,CONCRETE:1)
B(-4,1,-2,CONCRETE:1)
B(-4,1,-1,CONCRETE:1)
B(-4,1,0,CONCRETE:1)
B(-4,1,1,CONCRETE:1)
B(-4,1,2,CONCRETE:1)
B(-4,2,-2,CONCRETE:1)
B(-4,2,-1,CONCRETE:1)
B(-4,2,0,CONCRETE:1)
B(-4,2,1,CONCRETE:1)
B(-4,2,2,CONCRETE:1)
B(-4,3,-2,CONCRETE:1)
B(-4,3,-1,CONCRETE:1)
B(-4,3,0,CONCRETE:1)
B(-4,3,1,CONCRETE:1)
B(-4,3,2,CONCRETE:1)
B(-4,4,-2,CONCRETE:1)
B(-4,4,-1,CONCRETE:4)
B(-4,4,0,CONCRETE:4)
B(-4,4,1,CONCRETE:1)
B(-4,4,2,CONCRETE:1)
B(-4,5,-1,CONCRETE:4)
B(-4,5,0,CONCRETE:4)
B(-4,5,1,CONCRETE:4)
B(-4,5,2,CONCRETE:1)
B(-4,6,-1,CONCRETE:1)
B(-4,6,0,CONCRETE:1)
B(-4,6,1,CONCRETE:1)
B(-4,6,2,CONCRETE:1)
B(-4,7,-1,CONCRETE:1)
B(-4,7,0,CONCRETE:1)
B(-4,7,1,CONCRETE:1)
B(-4,7,2,CONCRETE:1)
B(-4,8,-1,CONCRETE:1)
B(-4,8,0,CONCRETE:1)
B(-4,8,1,CONCRETE:1)
B(-4,9,-1,CONCRETE:1)
B(-3,-4,1,CONCRETE:1)
B(-3,-3,0,CONCRETE:1)
B(-3,-3,1,CONCRETE:1)
B(-3,-3,2,CONCRETE:1)
B(-3,-2,-2,CONCRETE:1)
B(-3,-2,-1,CONCRETE:1)
B(-3,-2,0,CONCRETE:1)
B(-3,-2,1,CONCRETE:1)
B(-3,-2,2,CONCRETE:1)
B(-3,-1,-2,CONCRETE:1)
B(-3,-1,-1,CONCRETE:1)
B(-3,-1,0,CONCRETE:1)
B(-3,-1,1,CONCRETE:1)
B(-3,-1,2,CONCRETE:1)
B(-3,-1,3,CONCRETE:1)
B(-3,0,-2,CONCRETE:1)
B(-3,0,-1,CONCRETE:1)
B(-3,0,0,CONCRETE:1)
B(-3,0,1,CONCRETE:1)
B(-3,0,2,CONCRETE:1)
B(-3,0,3,CONCRETE:1)
B(-3,1,-2,CONCRETE:1)
B(-3,1,-1,CONCRETE:1)
B(-3,1,0,CONCRETE:1)
B(-3,1,1,CONCRETE:1)
B(-3,1,2,CONCRETE:1)
B(-3,1,3,CONCRETE:1)
B(-3,2,-2,CONCRETE:1)
B(-3,2,-1,CONCRETE:1)
B(-3,2,0,CONCRETE:1)
B(-3,2,1,CONCRETE:1)
B(-3,2,2,CONCRETE:1)
B(-3,2,3,CONCRETE:1)
B(-3,3,-2,CONCRETE:1)
B(-3,3,-1,CONCRETE:1)
B(-3,3,0,CONCRETE:1)
B(-3,3,1,CONCRETE:1)
B(-3,3,2,CONCRETE:1)
B(-3,3,3,CONCRETE:1)
B(-3,4,-2,CONCRETE:4)
B(-3,4,-1,CONCRETE:1)
B(-3,4,0,CONCRETE:1)
B(-3,4,1,CONCRETE:1)
B(-3,4,2,CONCRETE:1)
B(-3,4,3,CONCRETE:4)
B(-3,5,-2,CONCRETE:4)
B(-3,5,-1,CONCRETE:1)
B(-3,5,0,CONCRETE:1)
B(-3,5,1,CONCRETE:4)
B(-3,5,2,CONCRETE:4)
B(-3,5,3,CONCRETE:4)
B(-3,6,-2,CONCRETE:1)
B(-3,6,-1,CONCRETE:1)
B(-3,6,0,CONCRETE:1)
B(-3,6,1,CONCRETE:1)
B(-3,6,2,CONCRETE:1)
B(-3,6,3,CONCRETE:1)
B(-3,7,-1,CONCRETE:1)
B(-3,7,0,CONCRETE:1)
B(-3,7,1,CONCRETE:1)
B(-3,7,2,CONCRETE:1)
B(-3,7,3,CONCRETE:1)
B(-3,8,-1,CONCRETE:1)
B(-3,8,0,CONCRETE:1)
B(-3,8,1,CONCRETE:1)
B(-3,8,2,CONCRETE:1)
B(-3,9,-1,CONCRETE:1)
B(-3,9,0,CONCRETE:1)
B(-3,9,1,CONCRETE:1)
B(-3,9,2,CONCRETE:1)
B(-3,10,-1,CONCRETE:1)
B(-3,10,0,CONCRETE:1)
B(-3,10,1,CONCRETE:1)
B(-3,10,2,CONCRETE:1)
B(-3,11,0,CONCRETE:1)
B(-3,11,1,CONCRETE:1)
B(-3,11,2,CONCRETE:1)
B(-3,12,0,CONCRETE:1)
B(-3,12,1,CONCRETE:1)
B(-3,12,2,CONCRETE:1)
B(-3,13,0,CONCRETE:1)
B(-3,13,1,CONCRETE:1)
B(-3,13,2,CONCRETE:1)
B(-3,14,0,CONCRETE:1)
B(-3,14,1,CONCRETE:1)
B(-3,14,2,CONCRETE:1)
B(-3,15,0,CONCRETE:14)
B(-3,15,1,CONCRETE:14)
B(-3,15,2,CONCRETE:14)
B(-3,16,0,CONCRETE:14)
B(-3,16,1,CONCRETE:14)
B(-3,16,2,CONCRETE:14)
B(-3,17,0,CONCRETE:12)
B(-3,17,1,CONCRETE:12)
B(-3,17,2,CONCRETE:12)
B(-3,18,0,CONCRETE:12)
B(-3,18,1,CONCRETE:12)
B(-3,18,2,CONCRETE:12)
B(-3,19,0,CONCRETE:1)
B(-3,19,1,CONCRETE:1)
B(-3,19,2,CONCRETE:1)
B(-2,-4,0,CONCRETE:1)
B(-2,-4,1,CONCRETE:1)
B(-2,-4,2,CONCRETE:1)
B(-2,-3,-1,CONCRETE:1)
B(-2,-3,0,CONCRETE:1)
B(-2,-3,1,CONCRETE:1)
B(-2,-3,2,CONCRETE:1)
B(-2,-3,3,CONCRETE:1)
B(-2,-2,-2,CONCRETE:1)
B(-2,-2,-1,CONCRETE:1)
B(-2,-2,0,CONCRETE:1)
B(-2,-2,1,CONCRETE:1)
B(-2,-2,2,CONCRETE:1)
B(-2,-2,3,CONCRETE:1)
B(-2,-1,-2,CONCRETE:1)
B(-2,-1,-1,CONCRETE:1)
B(-2,-1,0,CONCRETE:1)
B(-2,-1,1,CONCRETE:1)
B(-2,-1,2,CONCRETE:1)
B(-2,-1,3,CONCRETE:1)
B(-2,-1,4,CONCRETE:1)
B(-2,0,-2,CONCRETE:1)
B(-2,0,-1,CONCRETE:1)
B(-2,0,0,CONCRETE:1)
B(-2,0,1,CONCRETE:1)
B(-2,0,2,CONCRETE:1)
B(-2,0,3,CONCRETE:1)
B(-2,0,4,CONCRETE:1)
B(-2,1,-2,CONCRETE:1)
B(-2,1,-1,CONCRETE:1)
B(-2,1,0,CONCRETE:1)
B(-2,1,1,CONCRETE:1)
B(-2,1,2,CONCRETE:1)
B(-2,1,3,CONCRETE:1)
B(-2,1,4,CONCRETE:1)
B(-2,2,-2,CONCRETE:1)
B(-2,2,-1,CONCRETE:1)
B(-2,2,0,CONCRETE:1)
B(-2,2,1,CONCRETE:1)
B(-2,2,2,CONCRETE:1)
B(-2,2,3,CONCRETE:1)
B(-2,2,4,CONCRETE:1)
B(-2,3,-2,CONCRETE:1)
B(-2,3,-1,CONCRETE:1)
B(-2,3,0,CONCRETE:1)
B(-2,3,1,CONCRETE:1)
B(-2,3,2,CONCRETE:1)
B(-2,3,3,CONCRETE:1)
B(-2,3,4,CONCRETE:1)
B(-2,4,-2,CONCRETE:4)
B(-2,4,-1,CONCRETE:1)
B(-2,4,0,CONCRETE:1)
B(-2,4,1,CONCRETE:1)
B(-2,4,2,CONCRETE:1)
B(-2,4,3,CONCRETE:1)
B(-2,4,4,CONCRETE:4)
B(-2,5,-2,CONCRETE:4)
B(-2,5,-1,CONCRETE:1)
B(-2,5,0,CONCRETE:1)
B(-2,5,1,CONCRETE:1)
B(-2,5,2,CONCRETE:4)
B(-2,5,3,CONCRETE:4)
B(-2,5,4,CONCRETE:4)
B(-2,6,-2,CONCRETE:1)
B(-2,6,-1,CONCRETE:1)
B(-2,6,0,CONCRETE:1)
B(-2,6,1,CONCRETE:1)
B(-2,6,2,CONCRETE:1)
B(-2,6,3,CONCRETE:1)
B(-2,6,4,CONCRETE:1)
B(-2,7,-2,CONCRETE:1)
B(-2,7,-1,CONCRETE:1)
B(-2,7,0,CONCRETE:1)
B(-2,7,1,CONCRETE:1)
B(-2,7,2,CONCRETE:1)
B(-2,7,3,CONCRETE:1)
B(-2,8,-2,CONCRETE:1)
B(-2,8,-1,CONCRETE:1)
B(-2,8,0,CONCRETE:1)
B(-2,8,1,CONCRETE:1)
B(-2,8,2,CONCRETE:1)
B(-2,8,3,CONCRETE:1)
B(-2,9,-2,CONCRETE:1)
B(-2,9,-1,CONCRETE:1)
B(-2,9,0,CONCRETE:1)
B(-2,9,1,CONCRETE:1)
B(-2,9,2,CONCRETE:1)
B(-2,9,3,CONCRETE:1)
B(-2,10,-1,CONCRETE:1)
B(-2,10,0,CONCRETE:1)
B(-2,10,1,CONCRETE:1)
B(-2,10,2,CONCRETE:1)
B(-2,11,-1,CONCRETE:1)
B(-2,11,0,CONCRETE:1)
B(-2,11,1,CONCRETE:1)
B(-2,11,2,CONCRETE:1)
B(-2,12,-1,CONCRETE:1)
B(-2,12,0,CONCRETE:1)
B(-2,12,1,CONCRETE:1)
B(-2,12,2,CONCRETE:1)
B(-2,13,-1,CONCRETE:1)
B(-2,13,0,CONCRETE:1)
B(-2,13,1,CONCRETE:1)
B(-2,13,2,CONCRETE:1)
B(-2,14,-1,CONCRETE:1)
B(-2,14,0,CONCRETE:1)
B(-2,14,1,CONCRETE:1)
B(-2,14,2,CONCRETE:1)
B(-2,15,-1,CONCRETE:1)
B(-2,15,0,CONCRETE:14)
B(-2,15,1,CONCRETE:14)
B(-2,15,2,CONCRETE:14)
B(-2,16,0,CONCRETE:14)
B(-2,16,1,CONCRETE:14)
B(-2,16,2,CONCRETE:14)
B(-2,17,0,CONCRETE:12)
B(-2,17,1,CONCRETE:12)
B(-2,17,2,CONCRETE:12)
B(-2,18,0,CONCRETE:1)
B(-2,18,1,CONCRETE:12)
B(-2,18,2,CONCRETE:12)
B(-2,19,0,CONCRETE:1)
B(-2,19,1,CONCRETE:1)
B(-2,19,2,CONCRETE:1)
B(-1,-4,-1,CONCRETE:1)
B(-1,-4,0,CONCRETE:1)
B(-1,-4,1,CONCRETE:1)
B(-1,-4,2,CONCRETE:1)
B(-1,-4,3,CONCRETE:1)
B(-1,-3,-1,CONCRETE:1)
B(-1,-3,0,CONCRETE:1)
B(-1,-3,1,CONCRETE:1)
B(-1,-3,2,CONCRETE:1)
B(-1,-3,3,CONCRETE:1)
B(-1,-2,-3,CONCRETE:1)
B(-1,-2,-2,CONCRETE:1)
B(-1,-2,-1,CONCRETE:1)
B(-1,-2,0,CONCRETE:1)
B(-1,-2,1,CONCRETE:1)
B(-1,-2,2,CONCRETE:1)
B(-1,-2,3,CONCRETE:1)
B(-1,-2,4,CONCRETE:1)
B(-1,-1,-3,CONCRETE:1)
B(-1,-1,-2,CONCRETE:1)
B(-1,-1,-1,CONCRETE:1)
B(-1,-1,0,CONCRETE:1)
B(-1,-1,1,CONCRETE:1)
B(-1,-1,2,CONCRETE:1)
B(-1,-1,3,CONCRETE:1)
B(-1,-1,4,CONCRETE:1)
B(-1,0,-3,CONCRETE:1)
B(-1,0,-2,CONCRETE:1)
B(-1,0,-1,CONCRETE:1)
B(-1,0,0,CONCRETE:1)
B(-1,0,1,CONCRETE:1)
B(-1,0,2,CONCRETE:1)
B(-1,0,3,CONCRETE:1)
B(-1,0,4,CONCRETE:1)
B(-1,1,-3,CONCRETE:1)
B(-1,1,-2,CONCRETE:1)
B(-1,1,-1,CONCRETE:1)
B(-1,1,0,CONCRETE:1)
B(-1,1,1,CONCRETE:1)
B(-1,1,2,CONCRETE:1)
B(-1,1,3,CONCRETE:1)
B(-1,1,4,CONCRETE:1)
B(-1,2,-3,CONCRETE:1)
B(-1,2,-2,CONCRETE:1)
B(-1,2,-1,CONCRETE:1)
B(-1,2,0,CONCRETE:1)
B(-1,2,1,CONCRETE:1)
B(-1,2,2,CONCRETE:1)
B(-1,2,3,CONCRETE:1)
B(-1,2,4,CONCRETE:1)
B(-1,3,-2,CONCRETE:1)
B(-1,3,-1,CONCRETE:1)
B(-1,3,0,CONCRETE:1)
B(-1,3,1,CONCRETE:1)
B(-1,3,2,CONCRETE:1)
B(-1,3,3,CONCRETE:1)
B(-1,3,4,CONCRETE:1)
B(-1,4,-2,CONCRETE:4)
B(-1,4,-1,CONCRETE:1)
B(-1,4,0,CONCRETE:1)
B(-1,4,1,CONCRETE:1)
B(-1,4,2,CONCRETE:1)
B(-1,4,3,CONCRETE:4)
B(-1,4,4,CONCRETE:4)
B(-1,5,-2,CONCRETE:4)
B(-1,5,-1,CONCRETE:1)
B(-1,5,0,CONCRETE:1)
B(-1,5,1,CONCRETE:1)
B(-1,5,2,CONCRETE:1)
B(-1,5,3,CONCRETE:1)
B(-1,5,4,CONCRETE:4)
B(-1,6,-2,CONCRETE:1)
B(-1,6,-1,CONCRETE:1)
B(-1,6,0,CONCRETE:1)
B(-1,6,1,CONCRETE:1)
B(-1,6,2,CONCRETE:1)
B(-1,6,3,CONCRETE:1)
B(-1,6,4,CONCRETE:1)
B(-1,7,-2,CONCRETE:1)
B(-1,7,-1,CONCRETE:1)
B(-1,7,0,CONCRETE:1)
B(-1,7,1,CONCRETE:1)
B(-1,7,2,CONCRETE:1)
B(-1,7,3,CONCRETE:1)
B(-1,7,4,CONCRETE:1)
B(-1,8,-1,CONCRETE:1)
B(-1,8,0,CONCRETE:1)
B(-1,8,1,CONCRETE:1)
B(-1,8,2,CONCRETE:1)
B(-1,8,3,CONCRETE:1)
B(-1,8,4,CONCRETE:1)
B(-1,9,-1,CONCRETE:1)
B(-1,9,0,CONCRETE:1)
B(-1,9,1,CONCRETE:1)
B(-1,9,2,CONCRETE:1)
B(-1,9,3,CONCRETE:1)
B(-1,10,-1,CONCRETE:1)
B(-1,10,0,CONCRETE:1)
B(-1,10,1,CONCRETE:1)
B(-1,10,2,CONCRETE:1)
B(-1,10,3,CONCRETE:1)
B(-1,11,-1,CONCRETE:1)
B(-1,11,0,CONCRETE:1)
B(-1,11,1,CONCRETE:1)
B(-1,11,2,CONCRETE:1)
B(-1,11,3,CONCRETE:1)
B(-1,12,0,CONCRETE:1)
B(-1,12,1,CONCRETE:1)
B(-1,12,2,CONCRETE:1)
B(-1,13,0,CONCRETE:1)
B(-1,13,1,CONCRETE:1)
B(-1,13,2,CONCRETE:1)
B(-1,14,0,CONCRETE:1)
B(-1,14,1,CONCRETE:1)
B(-1,14,2,CONCRETE:1)
B(-1,15,0,CONCRETE:14)
B(-1,15,1,CONCRETE:14)
B(-1,15,2,CONCRETE:14)
B(-1,16,0,CONCRETE:1)
B(-1,16,1,CONCRETE:14)
B(-1,17,0,CONCRETE:1)
B(-1,17,1,CONCRETE:12)
B(-1,18,0,CONCRETE:1)
B(-1,18,1,CONCRETE:12)
B(-1,19,0,CONCRETE:1)
B(-1,19,1,CONCRETE:1)
B(0,-4,-1,CONCRETE:1)
B(0,-4,0,CONCRETE:1)
B(0,-4,1,CONCRETE:1)
B(0,-4,2,CONCRETE:1)
B(0,-4,3,CONCRETE:1)
B(0,-3,-2,CONCRETE:1)
B(0,-3,-1,CONCRETE:1)
B(0,-3,0,CONCRETE:1)
B(0,-3,1,CONCRETE:1)
B(0,-3,2,CONCRETE:1)
B(0,-3,3,CONCRETE:1)
B(0,-3,4,CONCRETE:1)
B(0,-2,-3,CONCRETE:1)
B(0,-2,-2,CONCRETE:1)
B(0,-2,-1,CONCRETE:1)
B(0,-2,0,CONCRETE:1)
B(0,-2,1,CONCRETE:1)
B(0,-2,2,CONCRETE:1)
B(0,-2,3,CONCRETE:1)
B(0,-2,4,CONCRETE:1)
B(0,-1,-3,CONCRETE:1)
B(0,-1,-2,CONCRETE:1)
B(0,-1,-1,CONCRETE:1)
B(0,-1,0,CONCRETE:1)
B(0,-1,1,CONCRETE:1)
B(0,-1,2,CONCRETE:1)
B(0,-1,3,CONCRETE:1)
B(0,-1,4,CONCRETE:1)
B(0,0,-3,CONCRETE:1)
B(0,0,-2,CONCRETE:1)
B(0,0,-1,CONCRETE:1)
B(0,0,0,CONCRETE:1)
B(0,0,1,CONCRETE:1)
B(0,0,2,CONCRETE:1)
B(0,0,3,CONCRETE:1)
B(0,0,4,CONCRETE:1)
B(0,1,-3,CONCRETE:1)
B(0,1,-2,CONCRETE:1)
B(0,1,-1,CONCRETE:1)
B(0,1,0,CONCRETE:1)
B(0,1,1,CONCRETE:1)
B(0,1,2,CONCRETE:1)
B(0,1,3,CONCRETE:1)
B(0,1,4,CONCRETE:1)
B(0,2,-3,CONCRETE:1)
B(0,2,-2,CONCRETE:1)
B(0,2,-1,CONCRETE:1)
B(0,2,0,CONCRETE:1)
B(0,2,1,CONCRETE:1)
B(0,2,2,CONCRETE:1)
B(0,2,3,CONCRETE:1)
B(0,2,4,CONCRETE:1)
B(0,3,-3,CONCRETE:1)
B(0,3,-2,CONCRETE:1)
B(0,3,-1,CONCRETE:1)
B(0,3,0,CONCRETE:1)
B(0,3,1,CONCRETE:1)
B(0,3,2,CONCRETE:1)
B(0,3,3,CONCRETE:1)
B(0,3,4,CONCRETE:1)
B(0,4,-2,CONCRETE:4)
B(0,4,-1,CONCRETE:1)
B(0,4,0,CONCRETE:1)
B(0,4,1,CONCRETE:1)
B(0,4,2,CONCRETE:1)
B(0,4,3,CONCRETE:1)
B(0,4,4,CONCRETE:4)
B(0,5,-2,CONCRETE:4)
B(0,5,-1,CONCRETE:1)
B(0,5,0,CONCRETE:1)
B(0,5,1,CONCRETE:1)
B(0,5,2,CONCRETE:1)
B(0,5,3,CONCRETE:1)
B(0,5,4,CONCRETE:4)
B(0,6,-2,CONCRETE:1)
B(0,6,-1,CONCRETE:1)
B(0,6,0,CONCRETE:1)
B(0,6,1,CONCRETE:1)
B(0,6,2,CONCRETE:1)
B(0,6,3,CONCRETE:1)
B(0,6,4,CONCRETE:1)
B(0,7,-1,CONCRETE:1)
B(0,7,0,CONCRETE:1)
B(0,7,1,CONCRETE:1)
B(0,7,2,CONCRETE:1)
B(0,7,3,CONCRETE:1)
B(0,8,-1,CONCRETE:1)
B(0,8,0,CONCRETE:1)
B(0,8,1,CONCRETE:1)
B(0,8,2,CONCRETE:1)
B(0,9,-1,CONCRETE:1)
B(0,9,0,CONCRETE:1)
B(0,9,1,CONCRETE:1)
B(0,10,-1,CONCRETE:1)
B(0,10,0,CONCRETE:1)
B(0,10,1,CONCRETE:1)
B(0,11,-1,CONCRETE:1)
B(0,11,0,CONCRETE:1)
B(1,-4,0,CONCRETE:1)
B(1,-4,1,CONCRETE:1)
B(1,-3,-1,CONCRETE:1)
B(1,-3,0,CONCRETE:1)
B(1,-3,1,CONCRETE:1)
B(1,-3,2,CONCRETE:1)
B(1,-3,3,CONCRETE:1)
B(1,-2,-3,CONCRETE:1)
B(1,-2,-2,CONCRETE:1)
B(1,-2,-1,CONCRETE:1)
B(1,-2,0,CONCRETE:1)
B(1,-2,1,CONCRETE:1)
B(1,-2,2,CONCRETE:1)
B(1,-2,3,CONCRETE:1)
B(1,-2,4,CONCRETE:1)
B(1,-1,-3,CONCRETE:1)
B(1,-1,-2,CONCRETE:1)
B(1,-1,-1,CONCRETE:1)
B(1,-1,0,CONCRETE:1)
B(1,-1,1,CONCRETE:1)
B(1,-1,2,CONCRETE:1)
B(1,-1,3,CONCRETE:1)
B(1,-1,4,CONCRETE:1)
B(1,0,-3,CONCRETE:1)
B(1,0,-2,CONCRETE:1)
B(1,0,-1,CONCRETE:1)
B(1,0,0,CONCRETE:1)
B(1,0,1,CONCRETE:1)
B(1,0,2,CONCRETE:1)
B(1,0,3,CONCRETE:1)
B(1,0,4,CONCRETE:1)
B(1,1,-3,CONCRETE:1)
B(1,1,-2,CONCRETE:1)
B(1,1,-1,CONCRETE:1)
B(1,1,0,CONCRETE:1)
B(1,1,1,CONCRETE:1)
B(1,1,2,CONCRETE:1)
B(1,1,3,CONCRETE:1)
B(1,1,4,CONCRETE:1)
B(1,2,-3,CONCRETE:1)
B(1,2,-2,CONCRETE:1)
B(1,2,-1,CONCRETE:1)
B(1,2,0,CONCRETE:1)
B(1,2,1,CONCRETE:1)
B(1,2,2,CONCRETE:1)
B(1,2,3,CONCRETE:1)
B(1,2,4,CONCRETE:1)
B(1,3,-3,CONCRETE:1)
B(1,3,-2,CONCRETE:1)
B(1,3,-1,CONCRETE:1)
B(1,3,0,CONCRETE:1)
B(1,3,1,CONCRETE:1)
B(1,3,2,CONCRETE:1)
B(1,3,3,CONCRETE:1)
B(1,3,4,CONCRETE:1)
B(1,4,-3,CONCRETE:4)
B(1,4,-2,CONCRETE:1)
B(1,4,-1,CONCRETE:1)
B(1,4,0,CONCRETE:1)
B(1,4,1,CONCRETE:1)
B(1,4,2,CONCRETE:1)
B(1,4,3,CONCRETE:1)
B(1,4,4,CONCRETE:4)
B(1,5,-2,CONCRETE:4)
B(1,5,-1,CONCRETE:1)
B(1,5,0,CONCRETE:1)
B(1,5,1,CONCRETE:1)
B(1,5,2,CONCRETE:1)
B(1,5,3,CONCRETE:1)
B(1,5,4,CONCRETE:4)
B(1,6,-2,CONCRETE:1)
B(1,6,-1,CONCRETE:1)
B(1,6,0,CONCRETE:1)
B(1,6,1,CONCRETE:1)
B(1,6,2,CONCRETE:1)
B(1,6,3,CONCRETE:1)
B(1,7,-1,CONCRETE:1)
B(1,7,0,CONCRETE:1)
B(1,7,1,CONCRETE:1)
B(1,7,2,CONCRETE:1)
B(1,8,0,CONCRETE:1)
B(1,8,1,CONCRETE:1)
B(1,9,0,CONCRETE:1)
B(1,10,0,CONCRETE:1)
B(2,-3,-1,CONCRETE:1)
B(2,-3,0,CONCRETE:1)
B(2,-2,-2,CONCRETE:1)
B(2,-2,-1,CONCRETE:1)
B(2,-2,0,CONCRETE:1)
B(2,-1,-3,CONCRETE:1)
B(2,-1,-2,CONCRETE:1)
B(2,-1,-1,CONCRETE:1)
B(2,-1,0,CONCRETE:1)
B(2,-1,1,CONCRETE:1)
B(2,-1,2,CONCRETE:1)
B(2,0,-3,CONCRETE:1)
B(2,0,-2,CONCRETE:1)
B(2,0,-1,CONCRETE:1)
B(2,0,0,CONCRETE:1)
B(2,0,1,CONCRETE:1)
B(2,0,2,CONCRETE:1)
B(2,0,3,CONCRETE:1)
B(2,1,-3,CONCRETE:1)
B(2,1,-2,CONCRETE:1)
B(2,1,-1,CONCRETE:1)
B(2,1,0,CONCRETE:1)
B(2,1,1,CONCRETE:1)
B(2,1,2,CONCRETE:1)
B(2,1,3,CONCRETE:1)
B(2,2,-3,CONCRETE:1)
B(2,2,-2,CONCRETE:1)
B(2,2,-1,CONCRETE:1)
B(2,2,0,CONCRETE:1)
B(2,2,1,CONCRETE:1)
B(2,2,2,CONCRETE:1)
B(2,2,3,CONCRETE:1)
B(2,3,-2,CONCRETE:1)
B(2,3,-1,CONCRETE:1)
B(2,3,0,CONCRETE:1)
B(2,3,1,CONCRETE:1)
B(2,3,2,CONCRETE:1)
B(2,3,3,CONCRETE:1)
B(2,4,-2,CONCRETE:4)
B(2,4,-1,CONCRETE:4)
B(2,4,0,CONCRETE:1)
B(2,4,1,CONCRETE:1)
B(2,4,2,CONCRETE:1)
B(2,4,3,CONCRETE:4)
B(2,5,-1,CONCRETE:4)
B(2,5,0,CONCRETE:1)
B(2,5,1,CONCRETE:1)
B(2,5,2,CONCRETE:1)
B(2,5,3,CONCRETE:4)
B(2,6,-1,CONCRETE:1)
B(2,6,0,CONCRETE:1)
B(2,6,1,CONCRETE:1)
B(2,6,2,CONCRETE:1)
B(2,7,0,CONCRETE:1)
B(2,7,1,CONCRETE:1)
B(2,8,0,CONCRETE:1)
B(3,-3,0,CONCRETE:1)
B(3,-2,0,CONCRETE:1)
B(3,-1,-2,CONCRETE:1)
B(3,-1,-1,CONCRETE:1)
B(3,-1,0,CONCRETE:1)
B(3,-1,1,CONCRETE:1)
B(3,0,-2,CONCRETE:1)
B(3,0,-1,CONCRETE:1)
B(3,0,0,CONCRETE:1)
B(3,0,1,CONCRETE:1)
B(3,0,2,CONCRETE:1)
B(3,1,-2,CONCRETE:1)
B(3,1,-1,CONCRETE:1)
B(3,1,0,CONCRETE:1)
B(3,1,1,CONCRETE:1)
B(3,1,2,CONCRETE:1)
B(3,2,-2,CONCRETE:1)
B(3,2,-1,CONCRETE:1)
B(3,2,0,CONCRETE:1)
B(3,2,1,CONCRETE:1)
B(3,2,2,CONCRETE:1)
B(3,3,0,CONCRETE:1)
B(3,3,1,CONCRETE:1)
B(3,3,2,CONCRETE:1)
B(3,4,0,CONCRETE:1)
B(3,4,1,CONCRETE:4)
B(3,4,2,CONCRETE:4)
B(3,5,0,CONCRETE:1)
B(3,5,1,CONCRETE:4)
B(3,5,2,CONCRETE:1)
B(3,6,0,CONCRETE:1)
B(3,6,1,CONCRETE:1)

#######################################################################
# +-----------------------------------------------------------------+ #
# |                            BO3 checks                           | #
# +-----------------------------------------------------------------+ #
#######################################################################


#######################################################################
# +-----------------------------------------------------------------+ #
# |                             Branches                            | #
# +-----------------------------------------------------------------+ #
#######################################################################


#######################################################################
# +-----------------------------------------------------------------+ #
# |                         EntityFunctions                         | #
# +-----------------------------------------------------------------+ #
#######################################################################

