
#######################################################################
# +-----------------------------------------------------------------+ #
# |                            BO3 object                           | #
# +-----------------------------------------------------------------+ #
#######################################################################

Author: LordSmellyPants

Description: No description given

Version: 3

SettingsMode: WriteWithoutComments


#######################################################################
# +-----------------------------------------------------------------+ #
# |                          Main settings                          | #
# +-----------------------------------------------------------------+ #
#######################################################################

Tree: false

Frequency: 1

Rarity: 3.0

RotateRandomly: true

SpawnHeight: randomY

SpawnHeightOffset: 0

SpawnHeightVariance: 0

##############################
# Height Limits for the BO3. #
##############################

MinHeight: 53

MaxHeight: 61

######################
# Extrusion settings #
######################

ExtrudeMode: None

ExtrudeThroughBlocks: AIR

MaxBranchDepth: 10

ExcludedBiomes: All


#######################################################################
# +-----------------------------------------------------------------+ #
# |                      Source block settings                      | #
# +-----------------------------------------------------------------+ #
#######################################################################

SourceBlocks: GRASS,DIRT,GRAVEL,SAND,SAND:1,SANDSTONE,STONE,STONE:1,STONE:3,STONE:5,DIRT:1,CLAY,CONCRETE,CONCRETE,RED_ROSE,RED_ROSE:1,RED_ROSE:2,RED_ROSE:3,RED_ROSE:4,RED_ROSE:5,RED_ROSE:6,RED_ROSE:7,RED_ROSE:8,BROWN_MUSHROOM,RED_MUSHROOM,DOUBLE_PLANT,DOUBLE_PLANT:1,DOUBLE_PLANT:2,DOUBLE_PLANT:3,DOUBLE_PLANT:4,DOUBLE_PLANT:5,LONG_GRASS,LONG_GRASS:1,LONG_GRASS:2,DEAD_BUSH,COAL_ORE,IRON_ORE,GOLD_ORE,REDSTONE_ORE,DIAMOND_ORE,LAPIS_ORE,EMERALD_ORE,VINE,AIR,STATIONARY_WATER

MaxPercentageOutsideSourceBlock: 20

OutsideSourceBlock: placeAnyway


#######################################################################
# +-----------------------------------------------------------------+ #
# |                              Blocks                             | #
# +-----------------------------------------------------------------+ #
#######################################################################

B(-5,0,-4,CONCRETE:1)
B(-5,0,-2,CONCRETE:1)
B(-5,1,-4,CONCRETE:1)
B(-5,1,-3,CONCRETE:1)
B(-5,1,-2,CONCRETE:1)
B(-5,1,0,CONCRETE:1)
B(-5,1,1,CONCRETE:1)
B(-5,1,2,CONCRETE:1)
B(-5,1,3,CONCRETE:1)
B(-5,2,-4,CONCRETE:1)
B(-5,2,-3,CONCRETE:1)
B(-5,2,-2,CONCRETE:1)
B(-5,2,-1,CONCRETE:1)
B(-5,2,1,CONCRETE:1)
B(-5,2,2,CONCRETE:1)
B(-5,2,3,CONCRETE:1)
B(-5,3,-4,CONCRETE:1)
B(-5,3,-3,CONCRETE:1)
B(-5,3,-2,CONCRETE:1)
B(-5,3,-1,CONCRETE:1)
B(-5,3,0,CONCRETE:1)
B(-5,3,1,CONCRETE:1)
B(-5,3,2,CONCRETE:1)
B(-5,3,3,CONCRETE:1)
B(-5,4,-2,CONCRETE:1)
B(-5,4,-1,CONCRETE:1)
B(-4,-1,-2,CONCRETE:1)
B(-4,-1,-1,CONCRETE:1)
B(-4,0,-4,CONCRETE:1)
B(-4,0,-3,CONCRETE:1)
B(-4,0,-2,CONCRETE:1)
B(-4,0,-1,CONCRETE:1)
B(-4,0,0,CONCRETE:1)
B(-4,0,1,CONCRETE:1)
B(-4,0,2,CONCRETE:1)
B(-4,0,3,CONCRETE:1)
B(-4,0,4,CONCRETE:1)
B(-4,1,-5,CONCRETE:1)
B(-4,1,-4,CONCRETE:1)
B(-4,1,-3,CONCRETE:1)
B(-4,1,-2,CONCRETE:1)
B(-4,1,-1,CONCRETE:1)
B(-4,1,0,CONCRETE:1)
B(-4,1,1,CONCRETE:1)
B(-4,1,2,CONCRETE:1)
B(-4,1,3,CONCRETE:1)
B(-4,1,4,CONCRETE:1)
B(-4,2,-5,CONCRETE:1)
B(-4,2,-4,CONCRETE:1)
B(-4,2,-3,CONCRETE:1)
B(-4,2,-2,CONCRETE:1)
B(-4,2,-1,CONCRETE:1)
B(-4,2,0,CONCRETE:1)
B(-4,2,1,CONCRETE:1)
B(-4,2,2,CONCRETE:1)
B(-4,2,3,CONCRETE:1)
B(-4,2,4,CONCRETE:1)
B(-4,3,-5,CONCRETE:1)
B(-4,3,-4,CONCRETE:1)
B(-4,3,-3,CONCRETE:1)
B(-4,3,-2,CONCRETE:1)
B(-4,3,-1,CONCRETE:1)
B(-4,3,0,CONCRETE:1)
B(-4,3,1,CONCRETE:1)
B(-4,3,2,CONCRETE:1)
B(-4,3,3,CONCRETE:1)
B(-4,3,4,CONCRETE:1)
B(-4,4,-4,CONCRETE:1)
B(-4,4,-3,CONCRETE:1)
B(-4,4,-2,CONCRETE:1)
B(-4,4,-1,CONCRETE:1)
B(-4,4,0,CONCRETE:1)
B(-4,4,1,CONCRETE:1)
B(-4,4,2,CONCRETE:1)
B(-4,4,3,CONCRETE:1)
B(-4,5,-3,CONCRETE:4)
B(-4,5,-2,CONCRETE:4)
B(-4,5,-1,CONCRETE:4)
B(-4,5,0,CONCRETE:4)
B(-4,5,1,CONCRETE:4)
B(-4,6,-3,CONCRETE:4)
B(-4,6,-2,CONCRETE:4)
B(-3,-3,-1,CONCRETE:1)
B(-3,-2,-3,CONCRETE:1)
B(-3,-2,-2,CONCRETE:1)
B(-3,-2,-1,CONCRETE:1)
B(-3,-2,0,CONCRETE:1)
B(-3,-2,2,CONCRETE:1)
B(-3,-1,-3,CONCRETE:1)
B(-3,-1,-2,CONCRETE:1)
B(-3,-1,-1,CONCRETE:1)
B(-3,-1,0,CONCRETE:1)
B(-3,-1,1,CONCRETE:1)
B(-3,-1,2,CONCRETE:1)
B(-3,-1,3,CONCRETE:1)
B(-3,-1,4,CONCRETE:1)
B(-3,0,-5,CONCRETE:1)
B(-3,0,-4,CONCRETE:1)
B(-3,0,-3,CONCRETE:1)
B(-3,0,-2,CONCRETE:1)
B(-3,0,-1,CONCRETE:1)
B(-3,0,0,CONCRETE:1)
B(-3,0,1,CONCRETE:1)
B(-3,0,2,CONCRETE:1)
B(-3,0,3,CONCRETE:1)
B(-3,0,4,CONCRETE:1)
B(-3,1,-6,CONCRETE:1)
B(-3,1,-5,CONCRETE:1)
B(-3,1,-4,CONCRETE:1)
B(-3,1,-3,CONCRETE:1)
B(-3,1,-2,CONCRETE:1)
B(-3,1,-1,CONCRETE:1)
B(-3,1,0,CONCRETE:1)
B(-3,1,1,CONCRETE:1)
B(-3,1,2,CONCRETE:1)
B(-3,1,3,CONCRETE:1)
B(-3,1,4,CONCRETE:1)
B(-3,1,5,CONCRETE:1)
B(-3,2,-6,CONCRETE:1)
B(-3,2,-5,CONCRETE:1)
B(-3,2,-4,CONCRETE:1)
B(-3,2,-3,CONCRETE:1)
B(-3,2,-2,CONCRETE:1)
B(-3,2,-1,CONCRETE:1)
B(-3,2,0,CONCRETE:1)
B(-3,2,1,CONCRETE:1)
B(-3,2,2,CONCRETE:1)
B(-3,2,3,CONCRETE:1)
B(-3,2,4,CONCRETE:1)
B(-3,2,5,CONCRETE:1)
B(-3,3,-6,CONCRETE:1)
B(-3,3,-5,CONCRETE:1)
B(-3,3,-4,CONCRETE:1)
B(-3,3,-3,CONCRETE:1)
B(-3,3,-2,CONCRETE:1)
B(-3,3,-1,CONCRETE:1)
B(-3,3,0,CONCRETE:1)
B(-3,3,1,CONCRETE:1)
B(-3,3,2,CONCRETE:1)
B(-3,3,3,CONCRETE:1)
B(-3,3,4,CONCRETE:1)
B(-3,3,5,CONCRETE:1)
B(-3,4,-5,CONCRETE:1)
B(-3,4,-4,CONCRETE:1)
B(-3,4,-3,CONCRETE:1)
B(-3,4,-2,CONCRETE:1)
B(-3,4,-1,CONCRETE:1)
B(-3,4,0,CONCRETE:1)
B(-3,4,1,CONCRETE:1)
B(-3,4,2,CONCRETE:1)
B(-3,4,3,CONCRETE:1)
B(-3,4,4,CONCRETE:1)
B(-3,5,-4,CONCRETE:4)
B(-3,5,-3,CONCRETE)
B(-3,5,-2,CONCRETE)
B(-3,5,-1,CONCRETE:1)
B(-3,5,0,CONCRETE:1)
B(-3,5,1,CONCRETE:1)
B(-3,5,2,CONCRETE:4)
B(-3,5,3,CONCRETE:4)
B(-3,6,-4,CONCRETE:4)
B(-3,6,-3,CONCRETE)
B(-3,6,-2,CONCRETE)
B(-3,6,-1,CONCRETE:4)
B(-3,6,0,CONCRETE:4)
B(-3,6,1,CONCRETE:4)
B(-3,7,-3,CONCRETE)
B(-3,7,-2,CONCRETE)
B(-3,8,-3,CONCRETE)
B(-3,8,-2,CONCRETE)
B(-3,9,-3,CONCRETE)
B(-3,9,-2,CONCRETE)
B(-3,10,-3,CONCRETE:1)
B(-3,10,-2,CONCRETE:1)
B(-3,11,-2,CONCRETE)
B(-2,-3,-3,CONCRETE:1)
B(-2,-3,-2,CONCRETE:1)
B(-2,-3,-1,CONCRETE:1)
B(-2,-3,0,CONCRETE:1)
B(-2,-2,-4,CONCRETE:1)
B(-2,-2,-3,CONCRETE:1)
B(-2,-2,-2,CONCRETE:1)
B(-2,-2,-1,CONCRETE:1)
B(-2,-2,0,CONCRETE:1)
B(-2,-2,1,CONCRETE:1)
B(-2,-2,2,CONCRETE:1)
B(-2,-2,3,CONCRETE:1)
B(-2,-2,4,CONCRETE:1)
B(-2,-1,-4,CONCRETE:1)
B(-2,-1,-3,CONCRETE:1)
B(-2,-1,-2,CONCRETE:1)
B(-2,-1,-1,CONCRETE:1)
B(-2,-1,0,CONCRETE:1)
B(-2,-1,1,CONCRETE:1)
B(-2,-1,2,CONCRETE:1)
B(-2,-1,3,CONCRETE:1)
B(-2,-1,4,CONCRETE:1)
B(-2,0,-6,CONCRETE:1)
B(-2,0,-5,CONCRETE:1)
B(-2,0,-4,CONCRETE:1)
B(-2,0,-3,CONCRETE:1)
B(-2,0,-2,CONCRETE:1)
B(-2,0,-1,CONCRETE:1)
B(-2,0,0,CONCRETE:1)
B(-2,0,1,CONCRETE:1)
B(-2,0,2,CONCRETE:1)
B(-2,0,3,CONCRETE:1)
B(-2,0,4,CONCRETE:1)
B(-2,0,5,CONCRETE:1)
B(-2,0,6,CONCRETE:1)
B(-2,1,-7,CONCRETE:1)
B(-2,1,-6,CONCRETE:1)
B(-2,1,-5,CONCRETE:1)
B(-2,1,-4,CONCRETE:1)
B(-2,1,-3,CONCRETE:1)
B(-2,1,-2,CONCRETE:1)
B(-2,1,-1,CONCRETE:1)
B(-2,1,0,CONCRETE:1)
B(-2,1,1,CONCRETE:1)
B(-2,1,2,CONCRETE:1)
B(-2,1,3,CONCRETE:1)
B(-2,1,4,CONCRETE:1)
B(-2,1,5,CONCRETE:1)
B(-2,1,6,CONCRETE:1)
B(-2,2,-7,CONCRETE:1)
B(-2,2,-6,CONCRETE:1)
B(-2,2,-5,CONCRETE:1)
B(-2,2,-4,CONCRETE:1)
B(-2,2,-3,CONCRETE:1)
B(-2,2,-2,CONCRETE:1)
B(-2,2,-1,CONCRETE:1)
B(-2,2,0,CONCRETE:1)
B(-2,2,1,CONCRETE:1)
B(-2,2,2,CONCRETE:1)
B(-2,2,3,CONCRETE:1)
B(-2,2,4,CONCRETE:1)
B(-2,2,5,CONCRETE:1)
B(-2,2,6,CONCRETE:1)
B(-2,3,-7,CONCRETE:1)
B(-2,3,-6,CONCRETE:1)
B(-2,3,-5,CONCRETE:1)
B(-2,3,-4,CONCRETE:1)
B(-2,3,-3,CONCRETE:1)
B(-2,3,-2,CONCRETE:1)
B(-2,3,-1,CONCRETE:1)
B(-2,3,0,CONCRETE:1)
B(-2,3,1,CONCRETE:1)
B(-2,3,2,CONCRETE:1)
B(-2,3,3,CONCRETE:1)
B(-2,3,4,CONCRETE:1)
B(-2,3,5,CONCRETE:1)
B(-2,3,6,CONCRETE:1)
B(-2,4,-6,CONCRETE:1)
B(-2,4,-5,CONCRETE:1)
B(-2,4,-4,CONCRETE:1)
B(-2,4,-3,CONCRETE:1)
B(-2,4,-2,CONCRETE:1)
B(-2,4,-1,CONCRETE:1)
B(-2,4,0,CONCRETE:1)
B(-2,4,1,CONCRETE:1)
B(-2,4,2,CONCRETE:1)
B(-2,4,3,CONCRETE:1)
B(-2,4,4,CONCRETE:1)
B(-2,4,5,CONCRETE:1)
B(-2,5,-5,CONCRETE:4)
B(-2,5,-4,CONCRETE)
B(-2,5,-3,CONCRETE)
B(-2,5,-2,CONCRETE)
B(-2,5,-1,CONCRETE)
B(-2,5,0,CONCRETE)
B(-2,5,1,CONCRETE)
B(-2,5,2,CONCRETE)
B(-2,5,3,CONCRETE:1)
B(-2,5,4,CONCRETE:4)
B(-2,6,-4,CONCRETE:4)
B(-2,6,-3,CONCRETE)
B(-2,6,-2,CONCRETE)
B(-2,6,-1,CONCRETE)
B(-2,6,0,CONCRETE:4)
B(-2,6,1,CONCRETE:4)
B(-2,6,2,CONCRETE:4)
B(-2,6,3,CONCRETE:4)
B(-2,7,-4,CONCRETE)
B(-2,7,-3,CONCRETE)
B(-2,7,-2,CONCRETE)
B(-2,7,-1,CONCRETE)
B(-2,7,0,CONCRETE)
B(-2,7,1,CONCRETE)
B(-2,7,2,CONCRETE)
B(-2,8,-4,CONCRETE)
B(-2,8,-3,CONCRETE)
B(-2,8,-2,CONCRETE)
B(-2,8,-1,CONCRETE)
B(-2,8,0,CONCRETE)
B(-2,8,1,CONCRETE)
B(-2,8,2,CONCRETE)
B(-2,9,-3,CONCRETE)
B(-2,9,-2,CONCRETE)
B(-2,9,-1,CONCRETE)
B(-2,9,0,CONCRETE)
B(-2,9,1,CONCRETE)
B(-2,9,2,CONCRETE)
B(-2,10,-3,CONCRETE:1)
B(-2,10,-2,CONCRETE)
B(-2,10,-1,CONCRETE:1)
B(-2,10,0,CONCRETE:1)
B(-2,10,1,CONCRETE:1)
B(-2,11,-3,CONCRETE)
B(-2,11,-2,CONCRETE)
B(-2,11,-1,CONCRETE)
B(-2,11,0,CONCRETE)
B(-2,11,1,CONCRETE)
B(-2,12,-2,CONCRETE)
B(-2,12,-1,CONCRETE)
B(-2,12,0,CONCRETE)
B(-2,12,1,CONCRETE)
B(-2,13,-2,CONCRETE:1)
B(-2,13,-1,CONCRETE:1)
B(-2,13,0,CONCRETE:1)
B(-2,13,1,CONCRETE:1)
B(-2,14,-2,CONCRETE)
B(-2,14,-1,CONCRETE)
B(-2,14,0,CONCRETE)
B(-2,14,1,CONCRETE)
B(-2,15,-2,CONCRETE)
B(-2,15,-1,CONCRETE)
B(-2,15,0,CONCRETE)
B(-2,15,1,CONCRETE)
B(-2,16,-2,CONCRETE:14)
B(-2,16,-1,CONCRETE:14)
B(-2,16,0,CONCRETE:14)
B(-2,16,1,CONCRETE:14)
B(-2,17,-2,CONCRETE:14)
B(-2,17,-1,CONCRETE:14)
B(-2,17,0,CONCRETE:14)
B(-2,17,1,CONCRETE:14)
B(-2,18,-2,CONCRETE:12)
B(-2,18,-1,CONCRETE:12)
B(-2,18,0,CONCRETE:12)
B(-2,19,-1,CONCRETE:12)
B(-2,19,0,CONCRETE:12)
B(-2,20,-1,CONCRETE)
B(-2,20,0,CONCRETE)
B(-1,-3,-4,CONCRETE:1)
B(-1,-3,-3,CONCRETE:1)
B(-1,-3,-2,CONCRETE:1)
B(-1,-3,-1,CONCRETE:1)
B(-1,-3,0,CONCRETE:1)
B(-1,-3,1,CONCRETE:1)
B(-1,-2,-4,CONCRETE:1)
B(-1,-2,-3,CONCRETE:1)
B(-1,-2,-2,CONCRETE:1)
B(-1,-2,-1,CONCRETE:1)
B(-1,-2,0,CONCRETE:1)
B(-1,-2,1,CONCRETE:1)
B(-1,-2,2,CONCRETE:1)
B(-1,-2,3,CONCRETE:1)
B(-1,-2,4,CONCRETE:1)
B(-1,-1,-5,CONCRETE:1)
B(-1,-1,-4,CONCRETE:1)
B(-1,-1,-3,CONCRETE:1)
B(-1,-1,-2,CONCRETE:1)
B(-1,-1,-1,CONCRETE:1)
B(-1,-1,0,CONCRETE:1)
B(-1,-1,1,CONCRETE:1)
B(-1,-1,2,CONCRETE:1)
B(-1,-1,3,CONCRETE:1)
B(-1,-1,4,CONCRETE:1)
B(-1,0,-6,CONCRETE:1)
B(-1,0,-5,CONCRETE:1)
B(-1,0,-4,CONCRETE:1)
B(-1,0,-3,CONCRETE:1)
B(-1,0,-2,CONCRETE:1)
B(-1,0,-1,CONCRETE:1)
B(-1,0,0,CONCRETE:1)
B(-1,0,1,CONCRETE:1)
B(-1,0,2,CONCRETE:1)
B(-1,0,3,CONCRETE:1)
B(-1,0,4,CONCRETE:1)
B(-1,0,5,CONCRETE:1)
B(-1,1,-7,CONCRETE:1)
B(-1,1,-6,CONCRETE:1)
B(-1,1,-5,CONCRETE:1)
B(-1,1,-4,CONCRETE:1)
B(-1,1,-3,CONCRETE:1)
B(-1,1,-2,CONCRETE:1)
B(-1,1,-1,CONCRETE:1)
B(-1,1,0,CONCRETE:1)
B(-1,1,1,CONCRETE:1)
B(-1,1,2,CONCRETE:1)
B(-1,1,3,CONCRETE:1)
B(-1,1,4,CONCRETE:1)
B(-1,1,5,CONCRETE:1)
B(-1,1,6,CONCRETE:1)
B(-1,2,-7,CONCRETE:1)
B(-1,2,-6,CONCRETE:1)
B(-1,2,-5,CONCRETE:1)
B(-1,2,-4,CONCRETE:1)
B(-1,2,-3,CONCRETE:1)
B(-1,2,-2,CONCRETE:1)
B(-1,2,-1,CONCRETE:1)
B(-1,2,0,CONCRETE:1)
B(-1,2,1,CONCRETE:1)
B(-1,2,2,CONCRETE:1)
B(-1,2,3,CONCRETE:1)
B(-1,2,4,CONCRETE:1)
B(-1,2,5,CONCRETE:1)
B(-1,2,6,CONCRETE:1)
B(-1,3,-7,CONCRETE:1)
B(-1,3,-6,CONCRETE:1)
B(-1,3,-5,CONCRETE:1)
B(-1,3,-4,CONCRETE:1)
B(-1,3,-3,CONCRETE:1)
B(-1,3,-2,CONCRETE:1)
B(-1,3,-1,CONCRETE:1)
B(-1,3,0,CONCRETE:1)
B(-1,3,1,CONCRETE:1)
B(-1,3,2,CONCRETE:1)
B(-1,3,3,CONCRETE:1)
B(-1,3,4,CONCRETE:1)
B(-1,3,5,CONCRETE:1)
B(-1,3,6,CONCRETE:1)
B(-1,4,-7,CONCRETE:1)
B(-1,4,-6,CONCRETE:1)
B(-1,4,-5,CONCRETE:1)
B(-1,4,-4,CONCRETE:1)
B(-1,4,-3,CONCRETE:1)
B(-1,4,-2,CONCRETE:1)
B(-1,4,-1,CONCRETE:1)
B(-1,4,0,CONCRETE:1)
B(-1,4,1,CONCRETE:1)
B(-1,4,2,CONCRETE:1)
B(-1,4,3,CONCRETE:1)
B(-1,4,4,CONCRETE:1)
B(-1,4,5,CONCRETE:1)
B(-1,5,-6,CONCRETE:4)
B(-1,5,-5,CONCRETE)
B(-1,5,-4,CONCRETE)
B(-1,5,-3,CONCRETE)
B(-1,5,-2,CONCRETE)
B(-1,5,-1,CONCRETE)
B(-1,5,0,CONCRETE)
B(-1,5,1,CONCRETE)
B(-1,5,2,CONCRETE)
B(-1,5,3,CONCRETE)
B(-1,5,4,CONCRETE:4)
B(-1,6,-5,CONCRETE:4)
B(-1,6,-4,CONCRETE)
B(-1,6,-3,CONCRETE)
B(-1,6,-2,CONCRETE)
B(-1,6,-1,CONCRETE:4)
B(-1,6,0,CONCRETE:4)
B(-1,6,1,CONCRETE:4)
B(-1,6,2,CONCRETE:4)
B(-1,6,3,CONCRETE:4)
B(-1,6,4,CONCRETE:4)
B(-1,7,-4,CONCRETE)
B(-1,7,-3,CONCRETE)
B(-1,7,-2,CONCRETE)
B(-1,7,-1,CONCRETE)
B(-1,7,0,CONCRETE)
B(-1,7,1,CONCRETE)
B(-1,7,2,CONCRETE)
B(-1,7,3,CONCRETE)
B(-1,8,-4,CONCRETE)
B(-1,8,-3,CONCRETE)
B(-1,8,-2,CONCRETE)
B(-1,8,-1,CONCRETE)
B(-1,8,0,CONCRETE)
B(-1,8,1,CONCRETE)
B(-1,8,2,CONCRETE)
B(-1,9,-4,CONCRETE)
B(-1,9,-3,CONCRETE)
B(-1,9,-2,CONCRETE)
B(-1,9,-1,CONCRETE)
B(-1,9,0,CONCRETE)
B(-1,9,1,CONCRETE)
B(-1,9,2,CONCRETE)
B(-1,10,-4,CONCRETE:1)
B(-1,10,-3,CONCRETE)
B(-1,10,-2,CONCRETE)
B(-1,10,-1,CONCRETE)
B(-1,10,0,CONCRETE)
B(-1,10,1,CONCRETE)
B(-1,10,2,CONCRETE:1)
B(-1,11,-4,CONCRETE)
B(-1,11,-3,CONCRETE)
B(-1,11,-2,CONCRETE)
B(-1,11,-1,CONCRETE)
B(-1,11,0,CONCRETE)
B(-1,11,1,CONCRETE)
B(-1,11,2,CONCRETE)
B(-1,12,-4,CONCRETE)
B(-1,12,-3,CONCRETE)
B(-1,12,-2,CONCRETE)
B(-1,12,-1,CONCRETE)
B(-1,12,0,CONCRETE)
B(-1,12,1,CONCRETE)
B(-1,12,2,CONCRETE)
B(-1,13,-3,CONCRETE:1)
B(-1,13,-2,CONCRETE)
B(-1,13,-1,CONCRETE)
B(-1,13,0,CONCRETE)
B(-1,13,1,CONCRETE)
B(-1,13,2,CONCRETE:1)
B(-1,14,-3,CONCRETE)
B(-1,14,-2,CONCRETE)
B(-1,14,-1,CONCRETE)
B(-1,14,0,CONCRETE)
B(-1,14,1,CONCRETE)
B(-1,14,2,CONCRETE)
B(-1,15,-3,CONCRETE)
B(-1,15,-2,CONCRETE)
B(-1,15,-1,CONCRETE)
B(-1,15,0,CONCRETE)
B(-1,15,1,CONCRETE)
B(-1,15,2,CONCRETE)
B(-1,16,-3,CONCRETE:14)
B(-1,16,-2,CONCRETE)
B(-1,16,-1,CONCRETE)
B(-1,16,0,CONCRETE)
B(-1,16,1,CONCRETE)
B(-1,16,2,CONCRETE:14)
B(-1,17,-3,CONCRETE:14)
B(-1,17,-2,CONCRETE)
B(-1,17,-1,CONCRETE)
B(-1,17,0,CONCRETE)
B(-1,17,1,CONCRETE)
B(-1,17,2,CONCRETE:14)
B(-1,18,-3,CONCRETE:12)
B(-1,18,-2,CONCRETE)
B(-1,18,-1,CONCRETE)
B(-1,18,0,CONCRETE)
B(-1,18,1,CONCRETE:12)
B(-1,18,2,CONCRETE:12)
B(-1,19,-3,CONCRETE:12)
B(-1,19,-2,CONCRETE:12)
B(-1,19,-1,CONCRETE)
B(-1,19,0,CONCRETE)
B(-1,19,1,CONCRETE:12)
B(-1,19,2,CONCRETE:12)
B(-1,20,-3,CONCRETE)
B(-1,20,-2,CONCRETE)
B(-1,20,-1,CONCRETE)
B(-1,20,0,CONCRETE)
B(-1,20,1,CONCRETE)
B(-1,20,2,CONCRETE)
B(-1,21,-1,CONCRETE)
B(-1,21,0,CONCRETE)
B(-1,22,-1,CONCRETE)
B(-1,22,0,CONCRETE)
B(-1,23,-1,CONCRETE:8)
B(-1,23,0,CONCRETE:8)
B(-1,24,-1,CONCRETE)
B(-1,25,-1,CONCRETE:1)
B(-1,26,-1,CONCRETE)
B(-1,27,-1,CONCRETE)
B(-1,28,-1,CONCRETE)
B(0,-3,-3,CONCRETE:1)
B(0,-3,-2,CONCRETE:1)
B(0,-3,-1,CONCRETE:1)
B(0,-3,0,CONCRETE:1)
B(0,-3,1,CONCRETE:1)
B(0,-3,2,CONCRETE:1)
B(0,-2,-4,CONCRETE:1)
B(0,-2,-3,CONCRETE:1)
B(0,-2,-2,CONCRETE:1)
B(0,-2,-1,CONCRETE:1)
B(0,-2,0,CONCRETE:1)
B(0,-2,1,CONCRETE:1)
B(0,-2,2,CONCRETE:1)
B(0,-2,3,CONCRETE:1)
B(0,-2,4,CONCRETE:1)
B(0,-1,-5,CONCRETE:1)
B(0,-1,-4,CONCRETE:1)
B(0,-1,-3,CONCRETE:1)
B(0,-1,-2,CONCRETE:1)
B(0,-1,-1,CONCRETE:1)
B(0,-1,0,CONCRETE:1)
B(0,-1,1,CONCRETE:1)
B(0,-1,2,CONCRETE:1)
B(0,-1,3,CONCRETE:1)
B(0,-1,4,CONCRETE:1)
B(0,0,-5,CONCRETE:1)
B(0,0,-4,CONCRETE:1)
B(0,0,-3,CONCRETE:1)
B(0,0,-2,CONCRETE:1)
B(0,0,-1,CONCRETE:1)
B(0,0,0,CONCRETE:1)
B(0,0,1,CONCRETE:1)
B(0,0,2,CONCRETE:1)
B(0,0,3,CONCRETE:1)
B(0,0,4,CONCRETE:1)
B(0,0,5,CONCRETE:1)
B(0,1,-6,CONCRETE:1)
B(0,1,-5,CONCRETE:1)
B(0,1,-4,CONCRETE:1)
B(0,1,-3,CONCRETE:1)
B(0,1,-2,CONCRETE:1)
B(0,1,-1,CONCRETE:1)
B(0,1,0,CONCRETE:1)
B(0,1,1,CONCRETE:1)
B(0,1,2,CONCRETE:1)
B(0,1,3,CONCRETE:1)
B(0,1,4,CONCRETE:1)
B(0,1,5,CONCRETE:1)
B(0,1,6,CONCRETE:1)
B(0,2,-7,CONCRETE:1)
B(0,2,-6,CONCRETE:1)
B(0,2,-5,CONCRETE:1)
B(0,2,-4,CONCRETE:1)
B(0,2,-3,CONCRETE:1)
B(0,2,-2,CONCRETE:1)
B(0,2,-1,CONCRETE:1)
B(0,2,0,CONCRETE:1)
B(0,2,1,CONCRETE:1)
B(0,2,2,CONCRETE:1)
B(0,2,3,CONCRETE:1)
B(0,2,4,CONCRETE:1)
B(0,2,5,CONCRETE:1)
B(0,2,6,CONCRETE:1)
B(0,3,-7,CONCRETE:1)
B(0,3,-6,CONCRETE:1)
B(0,3,-5,CONCRETE:1)
B(0,3,-4,CONCRETE:1)
B(0,3,-3,CONCRETE:1)
B(0,3,-2,CONCRETE:1)
B(0,3,-1,CONCRETE:1)
B(0,3,0,CONCRETE:1)
B(0,3,1,CONCRETE:1)
B(0,3,2,CONCRETE:1)
B(0,3,3,CONCRETE:1)
B(0,3,4,CONCRETE:1)
B(0,3,5,CONCRETE:1)
B(0,3,6,CONCRETE:1)
B(0,4,-7,CONCRETE:1)
B(0,4,-6,CONCRETE:1)
B(0,4,-5,CONCRETE:1)
B(0,4,-4,CONCRETE:1)
B(0,4,-3,CONCRETE:1)
B(0,4,-2,CONCRETE:1)
B(0,4,-1,CONCRETE:1)
B(0,4,0,CONCRETE:1)
B(0,4,1,CONCRETE:1)
B(0,4,2,CONCRETE:1)
B(0,4,3,CONCRETE:1)
B(0,4,4,CONCRETE:1)
B(0,4,5,CONCRETE:1)
B(0,4,6,CONCRETE:1)
B(0,5,-6,CONCRETE:4)
B(0,5,-5,CONCRETE)
B(0,5,-4,CONCRETE)
B(0,5,-3,CONCRETE)
B(0,5,-2,CONCRETE)
B(0,5,-1,CONCRETE)
B(0,5,0,CONCRETE)
B(0,5,1,CONCRETE)
B(0,5,2,CONCRETE)
B(0,5,3,CONCRETE)
B(0,5,4,CONCRETE:1)
B(0,5,5,CONCRETE:4)
B(0,6,-6,CONCRETE:4)
B(0,6,-5,CONCRETE)
B(0,6,-4,CONCRETE)
B(0,6,-3,CONCRETE)
B(0,6,-2,CONCRETE)
B(0,6,-1,CONCRETE)
B(0,6,0,CONCRETE)
B(0,6,1,CONCRETE:4)
B(0,6,2,CONCRETE:4)
B(0,6,3,CONCRETE:4)
B(0,6,4,CONCRETE:4)
B(0,7,-5,CONCRETE:1)
B(0,7,-4,CONCRETE)
B(0,7,-3,CONCRETE)
B(0,7,-2,CONCRETE)
B(0,7,-1,CONCRETE)
B(0,7,0,CONCRETE)
B(0,7,1,CONCRETE)
B(0,7,2,CONCRETE)
B(0,7,3,CONCRETE)
B(0,8,-5,CONCRETE:1)
B(0,8,-4,CONCRETE)
B(0,8,-3,CONCRETE)
B(0,8,-2,CONCRETE)
B(0,8,-1,CONCRETE)
B(0,8,0,CONCRETE)
B(0,8,1,CONCRETE)
B(0,8,2,CONCRETE)
B(0,8,3,CONCRETE)
B(0,9,-4,CONCRETE)
B(0,9,-3,CONCRETE)
B(0,9,-2,CONCRETE)
B(0,9,-1,CONCRETE)
B(0,9,0,CONCRETE)
B(0,9,1,CONCRETE)
B(0,9,2,CONCRETE)
B(0,9,3,CONCRETE)
B(0,10,-4,CONCRETE:1)
B(0,10,-3,CONCRETE)
B(0,10,-2,CONCRETE)
B(0,10,-1,CONCRETE)
B(0,10,0,CONCRETE)
B(0,10,1,CONCRETE)
B(0,10,2,CONCRETE)
B(0,10,3,CONCRETE:1)
B(0,11,-4,CONCRETE)
B(0,11,-3,CONCRETE)
B(0,11,-2,CONCRETE)
B(0,11,-1,CONCRETE)
B(0,11,0,CONCRETE)
B(0,11,1,CONCRETE)
B(0,11,2,CONCRETE)
B(0,11,3,CONCRETE)
B(0,12,-4,CONCRETE)
B(0,12,-3,CONCRETE)
B(0,12,-2,CONCRETE)
B(0,12,-1,CONCRETE)
B(0,12,0,CONCRETE)
B(0,12,1,CONCRETE)
B(0,12,2,CONCRETE)
B(0,12,3,CONCRETE)
B(0,13,-3,CONCRETE:1)
B(0,13,-2,CONCRETE)
B(0,13,-1,CONCRETE)
B(0,13,0,CONCRETE)
B(0,13,1,CONCRETE)
B(0,13,2,CONCRETE)
B(0,13,3,CONCRETE:1)
B(0,14,-3,CONCRETE)
B(0,14,-2,CONCRETE)
B(0,14,-1,CONCRETE)
B(0,14,0,CONCRETE)
B(0,14,1,CONCRETE)
B(0,14,2,CONCRETE)
B(0,14,3,CONCRETE)
B(0,15,-3,CONCRETE)
B(0,15,-2,CONCRETE)
B(0,15,-1,CONCRETE)
B(0,15,0,CONCRETE)
B(0,15,1,CONCRETE)
B(0,15,2,CONCRETE)
B(0,15,3,CONCRETE)
B(0,16,-3,CONCRETE:14)
B(0,16,-2,CONCRETE)
B(0,16,-1,CONCRETE)
B(0,16,0,CONCRETE)
B(0,16,1,CONCRETE)
B(0,16,2,CONCRETE)
B(0,16,3,CONCRETE:14)
B(0,17,-3,CONCRETE:14)
B(0,17,-2,CONCRETE)
B(0,17,-1,CONCRETE)
B(0,17,0,CONCRETE)
B(0,17,1,CONCRETE)
B(0,17,2,CONCRETE)
B(0,17,3,CONCRETE:14)
B(0,18,-3,CONCRETE:12)
B(0,18,-2,CONCRETE)
B(0,18,-1,CONCRETE)
B(0,18,0,CONCRETE)
B(0,18,1,CONCRETE)
B(0,18,2,CONCRETE:12)
B(0,19,-3,CONCRETE:12)
B(0,19,-2,CONCRETE)
B(0,19,-1,CONCRETE)
B(0,19,0,CONCRETE)
B(0,19,1,CONCRETE)
B(0,19,2,CONCRETE:12)
B(0,20,-3,CONCRETE)
B(0,20,-2,CONCRETE)
B(0,20,-1,CONCRETE)
B(0,20,0,CONCRETE)
B(0,20,1,CONCRETE)
B(0,20,2,CONCRETE)
B(0,21,-2,CONCRETE)
B(0,21,-1,CONCRETE)
B(0,21,0,CONCRETE)
B(0,21,1,CONCRETE)
B(0,22,-2,CONCRETE)
B(0,22,-1,CONCRETE)
B(0,22,0,CONCRETE)
B(0,22,1,CONCRETE)
B(0,23,-2,CONCRETE:8)
B(0,23,-1,CONCRETE)
B(0,23,0,CONCRETE:8)
B(0,23,1,CONCRETE:8)
B(0,24,-2,CONCRETE)
B(0,24,-1,CONCRETE)
B(0,24,0,CONCRETE)
B(0,24,1,CONCRETE)
B(0,25,-2,CONCRETE:1)
B(0,25,-1,CONCRETE)
B(0,25,0,CONCRETE:1)
B(0,25,1,CONCRETE:1)
B(0,26,-2,CONCRETE)
B(0,26,-1,CONCRETE)
B(0,26,0,CONCRETE)
B(0,26,1,CONCRETE)
B(0,27,-2,CONCRETE)
B(0,27,-1,CONCRETE)
B(0,27,0,CONCRETE)
B(0,27,1,CONCRETE)
B(0,28,-2,CONCRETE)
B(0,28,-1,CONCRETE)
B(0,28,0,CONCRETE)
B(1,-3,-3,CONCRETE:1)
B(1,-3,-2,CONCRETE:1)
B(1,-3,-1,CONCRETE:1)
B(1,-3,0,CONCRETE:1)
B(1,-3,1,CONCRETE:1)
B(1,-3,2,CONCRETE:1)
B(1,-2,-5,CONCRETE:1)
B(1,-2,-4,CONCRETE:1)
B(1,-2,-3,CONCRETE:1)
B(1,-2,-2,CONCRETE:1)
B(1,-2,-1,CONCRETE:1)
B(1,-2,0,CONCRETE:1)
B(1,-2,1,CONCRETE:1)
B(1,-2,2,CONCRETE:1)
B(1,-2,3,CONCRETE:1)
B(1,-2,4,CONCRETE:1)
B(1,-1,-5,CONCRETE:1)
B(1,-1,-4,CONCRETE:1)
B(1,-1,-3,CONCRETE:1)
B(1,-1,-2,CONCRETE:1)
B(1,-1,-1,CONCRETE:1)
B(1,-1,0,CONCRETE:1)
B(1,-1,1,CONCRETE:1)
B(1,-1,2,CONCRETE:1)
B(1,-1,3,CONCRETE:1)
B(1,-1,4,CONCRETE:1)
B(1,-1,5,CONCRETE:1)
B(1,0,-6,CONCRETE:1)
B(1,0,-5,CONCRETE:1)
B(1,0,-4,CONCRETE:1)
B(1,0,-3,CONCRETE:1)
B(1,0,-2,CONCRETE:1)
B(1,0,-1,CONCRETE:1)
B(1,0,0,CONCRETE:1)
B(1,0,1,CONCRETE:1)
B(1,0,2,CONCRETE:1)
B(1,0,3,CONCRETE:1)
B(1,0,4,CONCRETE:1)
B(1,0,5,CONCRETE:1)
B(1,0,6,CONCRETE:1)
B(1,1,-7,CONCRETE:1)
B(1,1,-6,CONCRETE:1)
B(1,1,-5,CONCRETE:1)
B(1,1,-4,CONCRETE:1)
B(1,1,-3,CONCRETE:1)
B(1,1,-2,CONCRETE:1)
B(1,1,-1,CONCRETE:1)
B(1,1,0,CONCRETE:1)
B(1,1,1,CONCRETE:1)
B(1,1,2,CONCRETE:1)
B(1,1,3,CONCRETE:1)
B(1,1,4,CONCRETE:1)
B(1,1,5,CONCRETE:1)
B(1,1,6,CONCRETE:1)
B(1,1,7,CONCRETE:1)
B(1,2,-7,CONCRETE:1)
B(1,2,-6,CONCRETE:1)
B(1,2,-5,CONCRETE:1)
B(1,2,-4,CONCRETE:1)
B(1,2,-3,CONCRETE:1)
B(1,2,-2,CONCRETE:1)
B(1,2,-1,CONCRETE:1)
B(1,2,0,CONCRETE:1)
B(1,2,1,CONCRETE:1)
B(1,2,2,CONCRETE:1)
B(1,2,3,CONCRETE:1)
B(1,2,4,CONCRETE:1)
B(1,2,5,CONCRETE:1)
B(1,2,6,CONCRETE:1)
B(1,2,7,CONCRETE:1)
B(1,3,-7,CONCRETE:1)
B(1,3,-6,CONCRETE:1)
B(1,3,-5,CONCRETE:1)
B(1,3,-4,CONCRETE:1)
B(1,3,-3,CONCRETE:1)
B(1,3,-2,CONCRETE:1)
B(1,3,-1,CONCRETE:1)
B(1,3,0,CONCRETE:1)
B(1,3,1,CONCRETE:1)
B(1,3,2,CONCRETE:1)
B(1,3,3,CONCRETE:1)
B(1,3,4,CONCRETE:1)
B(1,3,5,CONCRETE:1)
B(1,3,6,CONCRETE:1)
B(1,3,7,CONCRETE:1)
B(1,4,-7,CONCRETE:1)
B(1,4,-6,CONCRETE:1)
B(1,4,-5,CONCRETE:1)
B(1,4,-4,CONCRETE:1)
B(1,4,-3,CONCRETE:1)
B(1,4,-2,CONCRETE:1)
B(1,4,-1,CONCRETE:1)
B(1,4,0,CONCRETE:1)
B(1,4,1,CONCRETE:1)
B(1,4,2,CONCRETE:1)
B(1,4,3,CONCRETE:1)
B(1,4,4,CONCRETE:1)
B(1,4,5,CONCRETE:1)
B(1,4,6,CONCRETE:1)
B(1,5,-6,CONCRETE:4)
B(1,5,-5,CONCRETE)
B(1,5,-4,CONCRETE)
B(1,5,-3,CONCRETE)
B(1,5,-2,CONCRETE)
B(1,5,-1,CONCRETE)
B(1,5,0,CONCRETE)
B(1,5,1,CONCRETE)
B(1,5,2,CONCRETE)
B(1,5,3,CONCRETE)
B(1,5,4,CONCRETE:1)
B(1,5,5,CONCRETE:4)
B(1,6,-6,CONCRETE:4)
B(1,6,-5,CONCRETE)
B(1,6,-4,CONCRETE)
B(1,6,-3,CONCRETE)
B(1,6,-2,CONCRETE)
B(1,6,-1,CONCRETE)
B(1,6,0,CONCRETE)
B(1,6,1,CONCRETE)
B(1,6,2,CONCRETE)
B(1,6,3,CONCRETE)
B(1,6,4,CONCRETE:1)
B(1,6,5,CONCRETE:4)
B(1,7,-4,CONCRETE)
B(1,7,-3,CONCRETE)
B(1,7,-2,CONCRETE)
B(1,7,-1,CONCRETE)
B(1,7,0,CONCRETE)
B(1,7,1,CONCRETE)
B(1,7,2,CONCRETE)
B(1,7,3,CONCRETE)
B(1,7,4,CONCRETE)
B(1,8,-4,CONCRETE)
B(1,8,-3,CONCRETE)
B(1,8,-2,CONCRETE)
B(1,8,-1,CONCRETE)
B(1,8,0,CONCRETE)
B(1,8,1,CONCRETE)
B(1,8,2,CONCRETE)
B(1,8,3,CONCRETE)
B(1,9,-4,CONCRETE)
B(1,9,-3,CONCRETE)
B(1,9,-2,CONCRETE)
B(1,9,-1,CONCRETE)
B(1,9,0,CONCRETE)
B(1,9,1,CONCRETE)
B(1,9,2,CONCRETE)
B(1,9,3,CONCRETE)
B(1,10,-4,CONCRETE:1)
B(1,10,-3,CONCRETE)
B(1,10,-2,CONCRETE)
B(1,10,-1,CONCRETE)
B(1,10,0,CONCRETE)
B(1,10,1,CONCRETE)
B(1,10,2,CONCRETE)
B(1,10,3,CONCRETE:1)
B(1,11,-4,CONCRETE)
B(1,11,-3,CONCRETE)
B(1,11,-2,CONCRETE)
B(1,11,-1,CONCRETE)
B(1,11,0,CONCRETE)
B(1,11,1,CONCRETE)
B(1,11,2,CONCRETE)
B(1,11,3,CONCRETE)
B(1,12,-4,CONCRETE)
B(1,12,-3,CONCRETE)
B(1,12,-2,CONCRETE)
B(1,12,-1,CONCRETE)
B(1,12,0,CONCRETE)
B(1,12,1,CONCRETE)
B(1,12,2,CONCRETE)
B(1,12,3,CONCRETE)
B(1,13,-4,CONCRETE:1)
B(1,13,-3,CONCRETE)
B(1,13,-2,CONCRETE)
B(1,13,-1,CONCRETE)
B(1,13,0,CONCRETE)
B(1,13,1,CONCRETE)
B(1,13,2,CONCRETE)
B(1,13,3,CONCRETE:1)
B(1,14,-3,CONCRETE)
B(1,14,-2,CONCRETE)
B(1,14,-1,CONCRETE)
B(1,14,0,CONCRETE)
B(1,14,1,CONCRETE)
B(1,14,2,CONCRETE)
B(1,14,3,CONCRETE)
B(1,15,-3,CONCRETE)
B(1,15,-2,CONCRETE)
B(1,15,-1,CONCRETE)
B(1,15,0,CONCRETE)
B(1,15,1,CONCRETE)
B(1,15,2,CONCRETE)
B(1,15,3,CONCRETE)
B(1,16,-3,CONCRETE:14)
B(1,16,-2,CONCRETE)
B(1,16,-1,CONCRETE)
B(1,16,0,CONCRETE)
B(1,16,1,CONCRETE)
B(1,16,2,CONCRETE)
B(1,16,3,CONCRETE:14)
B(1,17,-3,CONCRETE:14)
B(1,17,-2,CONCRETE)
B(1,17,-1,CONCRETE)
B(1,17,0,CONCRETE)
B(1,17,1,CONCRETE)
B(1,17,2,CONCRETE)
B(1,17,3,CONCRETE:14)
B(1,18,-3,CONCRETE:12)
B(1,18,-2,CONCRETE)
B(1,18,-1,CONCRETE)
B(1,18,0,CONCRETE)
B(1,18,1,CONCRETE)
B(1,18,2,CONCRETE)
B(1,18,3,CONCRETE:12)
B(1,19,-3,CONCRETE:12)
B(1,19,-2,CONCRETE)
B(1,19,-1,CONCRETE)
B(1,19,0,CONCRETE)
B(1,19,1,CONCRETE)
B(1,19,2,CONCRETE)
B(1,19,3,CONCRETE:12)
B(1,20,-3,CONCRETE)
B(1,20,-2,CONCRETE)
B(1,20,-1,CONCRETE)
B(1,20,0,CONCRETE)
B(1,20,1,CONCRETE)
B(1,20,2,CONCRETE)
B(1,20,3,CONCRETE)
B(1,21,-2,CONCRETE)
B(1,21,-1,CONCRETE)
B(1,21,0,CONCRETE)
B(1,21,1,CONCRETE)
B(1,21,2,CONCRETE)
B(1,22,-2,CONCRETE)
B(1,22,-1,CONCRETE)
B(1,22,0,CONCRETE)
B(1,22,1,CONCRETE)
B(1,22,2,CONCRETE)
B(1,23,-2,CONCRETE:8)
B(1,23,-1,CONCRETE:8)
B(1,23,0,CONCRETE)
B(1,23,1,CONCRETE)
B(1,23,2,CONCRETE:8)
B(1,24,-2,CONCRETE)
B(1,24,-1,CONCRETE)
B(1,24,0,CONCRETE)
B(1,24,1,CONCRETE)
B(1,25,-2,CONCRETE:1)
B(1,25,-1,CONCRETE:1)
B(1,25,0,CONCRETE)
B(1,25,1,CONCRETE:1)
B(1,26,-2,CONCRETE)
B(1,26,-1,CONCRETE)
B(1,26,0,CONCRETE)
B(1,26,1,CONCRETE)
B(1,27,-2,CONCRETE)
B(1,27,-1,CONCRETE)
B(1,27,0,CONCRETE)
B(1,27,1,CONCRETE)
B(1,28,-2,CONCRETE)
B(1,28,-1,CONCRETE)
B(1,28,0,CONCRETE)
B(1,28,1,CONCRETE)
B(2,-3,-2,CONCRETE:1)
B(2,-3,-1,CONCRETE:1)
B(2,-3,0,CONCRETE:1)
B(2,-3,1,CONCRETE:1)
B(2,-2,-4,CONCRETE:1)
B(2,-2,-3,CONCRETE:1)
B(2,-2,-2,CONCRETE:1)
B(2,-2,-1,CONCRETE:1)
B(2,-2,0,CONCRETE:1)
B(2,-2,1,CONCRETE:1)
B(2,-2,2,CONCRETE:1)
B(2,-1,-6,CONCRETE:1)
B(2,-1,-5,CONCRETE:1)
B(2,-1,-4,CONCRETE:1)
B(2,-1,-3,CONCRETE:1)
B(2,-1,-2,CONCRETE:1)
B(2,-1,-1,CONCRETE:1)
B(2,-1,0,CONCRETE:1)
B(2,-1,1,CONCRETE:1)
B(2,-1,2,CONCRETE:1)
B(2,-1,3,CONCRETE:1)
B(2,-1,4,CONCRETE:1)
B(2,0,-7,CONCRETE:1)
B(2,0,-6,CONCRETE:1)
B(2,0,-5,CONCRETE:1)
B(2,0,-4,CONCRETE:1)
B(2,0,-3,CONCRETE:1)
B(2,0,-2,CONCRETE:1)
B(2,0,-1,CONCRETE:1)
B(2,0,0,CONCRETE:1)
B(2,0,1,CONCRETE:1)
B(2,0,2,CONCRETE:1)
B(2,0,3,CONCRETE:1)
B(2,0,4,CONCRETE:1)
B(2,0,5,CONCRETE:1)
B(2,1,-7,CONCRETE:1)
B(2,1,-6,CONCRETE:1)
B(2,1,-5,CONCRETE:1)
B(2,1,-4,CONCRETE:1)
B(2,1,-3,CONCRETE:1)
B(2,1,-2,CONCRETE:1)
B(2,1,-1,CONCRETE:1)
B(2,1,0,CONCRETE:1)
B(2,1,1,CONCRETE:1)
B(2,1,2,CONCRETE:1)
B(2,1,3,CONCRETE:1)
B(2,1,4,CONCRETE:1)
B(2,1,5,CONCRETE:1)
B(2,1,6,CONCRETE:1)
B(2,1,7,CONCRETE:1)
B(2,2,-7,CONCRETE:1)
B(2,2,-6,CONCRETE:1)
B(2,2,-5,CONCRETE:1)
B(2,2,-4,CONCRETE:1)
B(2,2,-3,CONCRETE:1)
B(2,2,-2,CONCRETE:1)
B(2,2,-1,CONCRETE:1)
B(2,2,0,CONCRETE:1)
B(2,2,1,CONCRETE:1)
B(2,2,2,CONCRETE:1)
B(2,2,3,CONCRETE:1)
B(2,2,4,CONCRETE:1)
B(2,2,5,CONCRETE:1)
B(2,2,6,CONCRETE:1)
B(2,2,7,CONCRETE:1)
B(2,3,-7,CONCRETE:1)
B(2,3,-6,CONCRETE:1)
B(2,3,-5,CONCRETE:1)
B(2,3,-4,CONCRETE:1)
B(2,3,-3,CONCRETE:1)
B(2,3,-2,CONCRETE:1)
B(2,3,-1,CONCRETE:1)
B(2,3,0,CONCRETE:1)
B(2,3,1,CONCRETE:1)
B(2,3,2,CONCRETE:1)
B(2,3,3,CONCRETE:1)
B(2,3,4,CONCRETE:1)
B(2,3,5,CONCRETE:1)
B(2,3,6,CONCRETE:1)
B(2,3,7,CONCRETE:1)
B(2,4,-7,CONCRETE:1)
B(2,4,-6,CONCRETE:1)
B(2,4,-5,CONCRETE:1)
B(2,4,-4,CONCRETE:1)
B(2,4,-3,CONCRETE:1)
B(2,4,-2,CONCRETE:1)
B(2,4,-1,CONCRETE:1)
B(2,4,0,CONCRETE:1)
B(2,4,1,CONCRETE:1)
B(2,4,2,CONCRETE:1)
B(2,4,3,CONCRETE:1)
B(2,4,4,CONCRETE:1)
B(2,4,5,CONCRETE:1)
B(2,4,6,CONCRETE:1)
B(2,5,-6,CONCRETE:4)
B(2,5,-5,CONCRETE)
B(2,5,-4,CONCRETE)
B(2,5,-3,CONCRETE)
B(2,5,-2,CONCRETE)
B(2,5,-1,CONCRETE)
B(2,5,0,CONCRETE)
B(2,5,1,CONCRETE)
B(2,5,2,CONCRETE)
B(2,5,3,CONCRETE:1)
B(2,5,4,CONCRETE:1)
B(2,5,5,CONCRETE:4)
B(2,6,-5,CONCRETE:4)
B(2,6,-4,CONCRETE)
B(2,6,-3,CONCRETE)
B(2,6,-2,CONCRETE)
B(2,6,-1,CONCRETE)
B(2,6,0,CONCRETE)
B(2,6,1,CONCRETE)
B(2,6,2,CONCRETE:4)
B(2,6,3,CONCRETE:4)
B(2,6,4,CONCRETE:4)
B(2,6,5,CONCRETE:4)
B(2,7,-4,CONCRETE)
B(2,7,-3,CONCRETE)
B(2,7,-2,CONCRETE)
B(2,7,-1,CONCRETE)
B(2,7,0,CONCRETE)
B(2,7,1,CONCRETE)
B(2,7,2,CONCRETE)
B(2,7,3,CONCRETE:1)
B(2,7,4,CONCRETE)
B(2,8,-4,CONCRETE)
B(2,8,-3,CONCRETE)
B(2,8,-2,CONCRETE)
B(2,8,-1,CONCRETE)
B(2,8,0,CONCRETE)
B(2,8,1,CONCRETE)
B(2,8,2,CONCRETE)
B(2,8,3,CONCRETE:1)
B(2,9,-4,CONCRETE)
B(2,9,-3,CONCRETE)
B(2,9,-2,CONCRETE)
B(2,9,-1,CONCRETE)
B(2,9,0,CONCRETE)
B(2,9,1,CONCRETE)
B(2,9,2,CONCRETE)
B(2,9,3,CONCRETE:1)
B(2,10,-4,CONCRETE:1)
B(2,10,-3,CONCRETE)
B(2,10,-2,CONCRETE)
B(2,10,-1,CONCRETE)
B(2,10,0,CONCRETE)
B(2,10,1,CONCRETE)
B(2,10,2,CONCRETE)
B(2,10,3,CONCRETE:1)
B(2,11,-4,CONCRETE)
B(2,11,-3,CONCRETE)
B(2,11,-2,CONCRETE)
B(2,11,-1,CONCRETE)
B(2,11,0,CONCRETE)
B(2,11,1,CONCRETE)
B(2,11,2,CONCRETE)
B(2,12,-4,CONCRETE)
B(2,12,-3,CONCRETE)
B(2,12,-2,CONCRETE)
B(2,12,-1,CONCRETE)
B(2,12,0,CONCRETE)
B(2,12,1,CONCRETE)
B(2,12,2,CONCRETE)
B(2,13,-4,CONCRETE:1)
B(2,13,-3,CONCRETE:1)
B(2,13,-2,CONCRETE)
B(2,13,-1,CONCRETE)
B(2,13,0,CONCRETE)
B(2,13,1,CONCRETE)
B(2,13,2,CONCRETE:1)
B(2,14,-3,CONCRETE)
B(2,14,-2,CONCRETE)
B(2,14,-1,CONCRETE)
B(2,14,0,CONCRETE)
B(2,14,1,CONCRETE)
B(2,14,2,CONCRETE)
B(2,15,-3,CONCRETE)
B(2,15,-2,CONCRETE)
B(2,15,-1,CONCRETE)
B(2,15,0,CONCRETE)
B(2,15,1,CONCRETE)
B(2,15,2,CONCRETE)
B(2,16,-3,CONCRETE:14)
B(2,16,-2,CONCRETE)
B(2,16,-1,CONCRETE)
B(2,16,0,CONCRETE)
B(2,16,1,CONCRETE)
B(2,16,2,CONCRETE:14)
B(2,17,-3,CONCRETE:14)
B(2,17,-2,CONCRETE)
B(2,17,-1,CONCRETE)
B(2,17,0,CONCRETE)
B(2,17,1,CONCRETE)
B(2,17,2,CONCRETE:14)
B(2,18,-3,CONCRETE:12)
B(2,18,-2,CONCRETE)
B(2,18,-1,CONCRETE)
B(2,18,0,CONCRETE)
B(2,18,1,CONCRETE)
B(2,18,2,CONCRETE:12)
B(2,19,-2,CONCRETE:12)
B(2,19,-1,CONCRETE)
B(2,19,0,CONCRETE)
B(2,19,1,CONCRETE)
B(2,19,2,CONCRETE:12)
B(2,20,-2,CONCRETE)
B(2,20,-1,CONCRETE)
B(2,20,0,CONCRETE)
B(2,20,1,CONCRETE)
B(2,20,2,CONCRETE)
B(2,21,-1,CONCRETE)
B(2,21,0,CONCRETE)
B(2,21,1,CONCRETE)
B(2,22,-1,CONCRETE)
B(2,22,0,CONCRETE)
B(2,22,1,CONCRETE)
B(2,23,0,CONCRETE:8)
B(2,23,1,CONCRETE:8)
B(2,24,0,CONCRETE)
B(2,24,1,CONCRETE)
B(2,25,0,CONCRETE:1)
B(2,25,1,CONCRETE:1)
B(2,26,0,CONCRETE)
B(2,26,1,CONCRETE)
B(2,27,0,CONCRETE)
B(2,27,1,CONCRETE)
B(2,28,1,CONCRETE)
B(3,-3,-1,CONCRETE:1)
B(3,-3,0,CONCRETE:1)
B(3,-2,-3,CONCRETE:1)
B(3,-2,-2,CONCRETE:1)
B(3,-2,-1,CONCRETE:1)
B(3,-2,0,CONCRETE:1)
B(3,-2,1,CONCRETE:1)
B(3,-1,-5,CONCRETE:1)
B(3,-1,-4,CONCRETE:1)
B(3,-1,-3,CONCRETE:1)
B(3,-1,-2,CONCRETE:1)
B(3,-1,-1,CONCRETE:1)
B(3,-1,0,CONCRETE:1)
B(3,-1,1,CONCRETE:1)
B(3,-1,2,CONCRETE:1)
B(3,0,-6,CONCRETE:1)
B(3,0,-5,CONCRETE:1)
B(3,0,-4,CONCRETE:1)
B(3,0,-3,CONCRETE:1)
B(3,0,-2,CONCRETE:1)
B(3,0,-1,CONCRETE:1)
B(3,0,0,CONCRETE:1)
B(3,0,1,CONCRETE:1)
B(3,0,2,CONCRETE:1)
B(3,0,3,CONCRETE:1)
B(3,0,5,CONCRETE:1)
B(3,1,-6,CONCRETE:1)
B(3,1,-5,CONCRETE:1)
B(3,1,-4,CONCRETE:1)
B(3,1,-3,CONCRETE:1)
B(3,1,-2,CONCRETE:1)
B(3,1,-1,CONCRETE:1)
B(3,1,0,CONCRETE:1)
B(3,1,1,CONCRETE:1)
B(3,1,2,CONCRETE:1)
B(3,1,3,CONCRETE:1)
B(3,1,4,CONCRETE:1)
B(3,1,5,CONCRETE:1)
B(3,1,6,CONCRETE:1)
B(3,2,-7,CONCRETE:1)
B(3,2,-6,CONCRETE:1)
B(3,2,-5,CONCRETE:1)
B(3,2,-4,CONCRETE:1)
B(3,2,-3,CONCRETE:1)
B(3,2,-2,CONCRETE:1)
B(3,2,-1,CONCRETE:1)
B(3,2,0,CONCRETE:1)
B(3,2,1,CONCRETE:1)
B(3,2,2,CONCRETE:1)
B(3,2,3,CONCRETE:1)
B(3,2,4,CONCRETE:1)
B(3,2,5,CONCRETE:1)
B(3,2,6,CONCRETE:1)
B(3,2,7,CONCRETE:1)
B(3,3,-7,CONCRETE:1)
B(3,3,-6,CONCRETE:1)
B(3,3,-5,CONCRETE:1)
B(3,3,-4,CONCRETE:1)
B(3,3,-3,CONCRETE:1)
B(3,3,-2,CONCRETE:1)
B(3,3,-1,CONCRETE:1)
B(3,3,0,CONCRETE:1)
B(3,3,1,CONCRETE:1)
B(3,3,2,CONCRETE:1)
B(3,3,3,CONCRETE:1)
B(3,3,4,CONCRETE:1)
B(3,3,5,CONCRETE:1)
B(3,3,6,CONCRETE:1)
B(3,3,7,CONCRETE:1)
B(3,4,-6,CONCRETE:1)
B(3,4,-5,CONCRETE:1)
B(3,4,-4,CONCRETE:1)
B(3,4,-3,CONCRETE:1)
B(3,4,-2,CONCRETE:1)
B(3,4,-1,CONCRETE:1)
B(3,4,0,CONCRETE:1)
B(3,4,1,CONCRETE:1)
B(3,4,2,CONCRETE:1)
B(3,4,3,CONCRETE:1)
B(3,4,4,CONCRETE:1)
B(3,4,5,CONCRETE:1)
B(3,4,6,CONCRETE:1)
B(3,5,-5,CONCRETE:4)
B(3,5,-4,CONCRETE)
B(3,5,-3,CONCRETE)
B(3,5,-2,CONCRETE)
B(3,5,-1,CONCRETE)
B(3,5,0,CONCRETE)
B(3,5,1,CONCRETE)
B(3,5,2,CONCRETE)
B(3,5,3,CONCRETE:1)
B(3,5,4,CONCRETE:1)
B(3,5,5,CONCRETE:4)
B(3,6,-5,CONCRETE:4)
B(3,6,-4,CONCRETE)
B(3,6,-3,CONCRETE)
B(3,6,-2,CONCRETE)
B(3,6,-1,CONCRETE)
B(3,6,0,CONCRETE)
B(3,6,1,CONCRETE)
B(3,6,2,CONCRETE)
B(3,6,3,CONCRETE:4)
B(3,6,4,CONCRETE:4)
B(3,7,-4,CONCRETE)
B(3,7,-3,CONCRETE)
B(3,7,-2,CONCRETE)
B(3,7,-1,CONCRETE)
B(3,7,0,CONCRETE)
B(3,7,1,CONCRETE)
B(3,7,2,CONCRETE)
B(3,7,3,CONCRETE)
B(3,8,-4,CONCRETE)
B(3,8,-3,CONCRETE)
B(3,8,-2,CONCRETE)
B(3,8,-1,CONCRETE)
B(3,8,0,CONCRETE)
B(3,8,1,CONCRETE)
B(3,8,2,CONCRETE)
B(3,8,3,CONCRETE:1)
B(3,9,-4,CONCRETE)
B(3,9,-3,CONCRETE)
B(3,9,-2,CONCRETE)
B(3,9,-1,CONCRETE)
B(3,9,0,CONCRETE)
B(3,9,1,CONCRETE)
B(3,9,2,CONCRETE)
B(3,10,-4,CONCRETE:1)
B(3,10,-3,CONCRETE)
B(3,10,-2,CONCRETE)
B(3,10,-1,CONCRETE)
B(3,10,0,CONCRETE)
B(3,10,1,CONCRETE:1)
B(3,10,2,CONCRETE:1)
B(3,11,-4,CONCRETE)
B(3,11,-3,CONCRETE)
B(3,11,-2,CONCRETE)
B(3,11,-1,CONCRETE)
B(3,11,0,CONCRETE)
B(3,11,1,CONCRETE)
B(3,11,2,CONCRETE)
B(3,12,-4,CONCRETE)
B(3,12,-3,CONCRETE)
B(3,12,-2,CONCRETE)
B(3,12,-1,CONCRETE)
B(3,12,0,CONCRETE)
B(3,12,1,CONCRETE)
B(3,12,2,CONCRETE)
B(3,13,-2,CONCRETE:1)
B(3,13,-1,CONCRETE)
B(3,13,0,CONCRETE:1)
B(3,13,1,CONCRETE:1)
B(3,13,2,CONCRETE:1)
B(3,14,-2,CONCRETE)
B(3,14,-1,CONCRETE)
B(3,14,0,CONCRETE)
B(3,14,1,CONCRETE)
B(3,14,2,CONCRETE)
B(3,15,-2,CONCRETE)
B(3,15,-1,CONCRETE)
B(3,15,0,CONCRETE)
B(3,15,1,CONCRETE)
B(3,15,2,CONCRETE)
B(3,16,-2,CONCRETE:14)
B(3,16,-1,CONCRETE)
B(3,16,0,CONCRETE:14)
B(3,16,1,CONCRETE:14)
B(3,16,2,CONCRETE:14)
B(3,17,-2,CONCRETE:14)
B(3,17,-1,CONCRETE)
B(3,17,0,CONCRETE:14)
B(3,17,1,CONCRETE:14)
B(3,17,2,CONCRETE:14)
B(3,18,-2,CONCRETE:12)
B(3,18,-1,CONCRETE)
B(3,18,0,CONCRETE:12)
B(3,18,1,CONCRETE:12)
B(3,18,2,CONCRETE:12)
B(3,19,-2,CONCRETE:12)
B(3,19,-1,CONCRETE:12)
B(3,19,0,CONCRETE:12)
B(3,19,1,CONCRETE:12)
B(3,19,2,CONCRETE:12)
B(3,20,-2,CONCRETE)
B(3,20,-1,CONCRETE)
B(3,20,0,CONCRETE)
B(3,20,1,CONCRETE)
B(3,20,2,CONCRETE)
B(4,-2,-4,CONCRETE:1)
B(4,-2,-3,CONCRETE:1)
B(4,-2,-2,CONCRETE:1)
B(4,-2,-1,CONCRETE:1)
B(4,-2,0,CONCRETE:1)
B(4,-1,-4,CONCRETE:1)
B(4,-1,-3,CONCRETE:1)
B(4,-1,-2,CONCRETE:1)
B(4,-1,-1,CONCRETE:1)
B(4,-1,0,CONCRETE:1)
B(4,-1,1,CONCRETE:1)
B(4,0,-4,CONCRETE:1)
B(4,0,-3,CONCRETE:1)
B(4,0,-2,CONCRETE:1)
B(4,0,-1,CONCRETE:1)
B(4,0,0,CONCRETE:1)
B(4,0,1,CONCRETE:1)
B(4,0,2,CONCRETE:1)
B(4,0,3,CONCRETE:1)
B(4,0,4,CONCRETE:1)
B(4,1,-6,CONCRETE:1)
B(4,1,-5,CONCRETE:1)
B(4,1,-4,CONCRETE:1)
B(4,1,-3,CONCRETE:1)
B(4,1,-2,CONCRETE:1)
B(4,1,-1,CONCRETE:1)
B(4,1,0,CONCRETE:1)
B(4,1,1,CONCRETE:1)
B(4,1,2,CONCRETE:1)
B(4,1,3,CONCRETE:1)
B(4,1,4,CONCRETE:1)
B(4,1,5,CONCRETE:1)
B(4,2,-7,CONCRETE:1)
B(4,2,-6,CONCRETE:1)
B(4,2,-5,CONCRETE:1)
B(4,2,-4,CONCRETE:1)
B(4,2,-3,CONCRETE:1)
B(4,2,-2,CONCRETE:1)
B(4,2,-1,CONCRETE:1)
B(4,2,0,CONCRETE:1)
B(4,2,1,CONCRETE:1)
B(4,2,2,CONCRETE:1)
B(4,2,3,CONCRETE:1)
B(4,2,4,CONCRETE:1)
B(4,2,5,CONCRETE:1)
B(4,2,6,CONCRETE:1)
B(4,3,-7,CONCRETE:1)
B(4,3,-6,CONCRETE:1)
B(4,3,-5,CONCRETE:1)
B(4,3,-4,CONCRETE:1)
B(4,3,-3,CONCRETE:1)
B(4,3,-2,CONCRETE:1)
B(4,3,-1,CONCRETE:1)
B(4,3,0,CONCRETE:1)
B(4,3,1,CONCRETE:1)
B(4,3,2,CONCRETE:1)
B(4,3,3,CONCRETE:1)
B(4,3,4,CONCRETE:1)
B(4,3,5,CONCRETE:1)
B(4,3,6,CONCRETE:1)
B(4,4,-6,CONCRETE:1)
B(4,4,-5,CONCRETE:1)
B(4,4,-4,CONCRETE:1)
B(4,4,-3,CONCRETE:1)
B(4,4,-2,CONCRETE:1)
B(4,4,-1,CONCRETE:1)
B(4,4,0,CONCRETE:1)
B(4,4,1,CONCRETE:1)
B(4,4,2,CONCRETE:1)
B(4,4,3,CONCRETE:1)
B(4,4,4,CONCRETE:1)
B(4,4,5,CONCRETE:1)
B(4,5,-5,CONCRETE:4)
B(4,5,-4,CONCRETE)
B(4,5,-3,CONCRETE)
B(4,5,-2,CONCRETE)
B(4,5,-1,CONCRETE)
B(4,5,0,CONCRETE)
B(4,5,1,CONCRETE)
B(4,5,2,CONCRETE)
B(4,5,3,CONCRETE:4)
B(4,5,4,CONCRETE:4)
B(4,6,-4,CONCRETE:4)
B(4,6,-3,CONCRETE)
B(4,6,-2,CONCRETE)
B(4,6,-1,CONCRETE)
B(4,6,0,CONCRETE)
B(4,6,1,CONCRETE)
B(4,6,2,CONCRETE)
B(4,6,3,CONCRETE:4)
B(4,7,-4,CONCRETE)
B(4,7,-3,CONCRETE)
B(4,7,-2,CONCRETE)
B(4,7,-1,CONCRETE)
B(4,7,0,CONCRETE)
B(4,7,1,CONCRETE)
B(4,7,2,CONCRETE)
B(4,8,-3,CONCRETE)
B(4,8,-2,CONCRETE)
B(4,8,-1,CONCRETE)
B(4,8,0,CONCRETE)
B(4,8,1,CONCRETE)
B(4,8,2,CONCRETE)
B(4,9,-3,CONCRETE)
B(4,9,-2,CONCRETE)
B(4,9,-1,CONCRETE)
B(4,9,0,CONCRETE)
B(4,9,1,CONCRETE)
B(4,10,-3,CONCRETE)
B(4,10,-2,CONCRETE)
B(4,10,-1,CONCRETE:1)
B(4,10,0,CONCRETE:1)
B(4,11,-3,CONCRETE)
B(4,11,-2,CONCRETE)
B(4,11,-1,CONCRETE)
B(4,11,0,CONCRETE)
B(4,12,-3,CONCRETE)
B(4,12,-2,CONCRETE)
B(4,12,-1,CONCRETE)
B(4,12,0,CONCRETE)
B(4,13,-2,CONCRETE:1)
B(4,13,-1,CONCRETE:1)
B(4,14,-2,CONCRETE)
B(4,14,-1,CONCRETE)
B(4,15,-2,CONCRETE)
B(4,15,-1,CONCRETE)
B(4,16,-2,CONCRETE:14)
B(4,16,-1,CONCRETE:14)
B(4,17,-2,CONCRETE:14)
B(4,17,-1,CONCRETE:14)
B(4,18,-1,CONCRETE:12)
B(4,19,-1,CONCRETE:12)
B(4,20,-1,CONCRETE)
B(5,-2,-2,CONCRETE:1)
B(5,-2,-1,CONCRETE:1)
B(5,-1,-4,CONCRETE:1)
B(5,-1,-3,CONCRETE:1)
B(5,-1,-2,CONCRETE:1)
B(5,-1,-1,CONCRETE:1)
B(5,-1,0,CONCRETE:1)
B(5,-1,1,CONCRETE:1)
B(5,0,-5,CONCRETE:1)
B(5,0,-4,CONCRETE:1)
B(5,0,-3,CONCRETE:1)
B(5,0,-2,CONCRETE:1)
B(5,0,-1,CONCRETE:1)
B(5,0,0,CONCRETE:1)
B(5,0,1,CONCRETE:1)
B(5,0,2,CONCRETE:1)
B(5,0,3,CONCRETE:1)
B(5,1,-5,CONCRETE:1)
B(5,1,-4,CONCRETE:1)
B(5,1,-3,CONCRETE:1)
B(5,1,-2,CONCRETE:1)
B(5,1,-1,CONCRETE:1)
B(5,1,0,CONCRETE:1)
B(5,1,1,CONCRETE:1)
B(5,1,2,CONCRETE:1)
B(5,1,3,CONCRETE:1)
B(5,1,4,CONCRETE:1)
B(5,2,-6,CONCRETE:1)
B(5,2,-5,CONCRETE:1)
B(5,2,-4,CONCRETE:1)
B(5,2,-3,CONCRETE:1)
B(5,2,-2,CONCRETE:1)
B(5,2,-1,CONCRETE:1)
B(5,2,0,CONCRETE:1)
B(5,2,1,CONCRETE:1)
B(5,2,2,CONCRETE:1)
B(5,2,3,CONCRETE:1)
B(5,2,4,CONCRETE:1)
B(5,2,5,CONCRETE:1)
B(5,3,-6,CONCRETE:1)
B(5,3,-5,CONCRETE:1)
B(5,3,-4,CONCRETE:1)
B(5,3,-3,CONCRETE:1)
B(5,3,-2,CONCRETE:1)
B(5,3,-1,CONCRETE:1)
B(5,3,0,CONCRETE:1)
B(5,3,1,CONCRETE:1)
B(5,3,2,CONCRETE:1)
B(5,3,3,CONCRETE:1)
B(5,3,4,CONCRETE:1)
B(5,3,5,CONCRETE:1)
B(5,4,-5,CONCRETE:1)
B(5,4,-4,CONCRETE:1)
B(5,4,-3,CONCRETE:1)
B(5,4,-2,CONCRETE:1)
B(5,4,-1,CONCRETE:1)
B(5,4,0,CONCRETE:1)
B(5,4,1,CONCRETE:1)
B(5,4,2,CONCRETE:1)
B(5,4,3,CONCRETE:1)
B(5,4,4,CONCRETE:1)
B(5,5,-4,CONCRETE:4)
B(5,5,-3,CONCRETE:4)
B(5,5,-2,CONCRETE)
B(5,5,-1,CONCRETE)
B(5,5,0,CONCRETE)
B(5,5,1,CONCRETE)
B(5,5,2,CONCRETE:1)
B(5,5,3,CONCRETE:4)
B(5,6,-3,CONCRETE:4)
B(5,6,-2,CONCRETE)
B(5,6,-1,CONCRETE:4)
B(5,6,0,CONCRETE:4)
B(5,6,1,CONCRETE:4)
B(5,6,2,CONCRETE:4)
B(5,7,-2,CONCRETE)
B(5,7,-1,CONCRETE)
B(5,8,-2,CONCRETE)
B(5,8,-1,CONCRETE)
B(5,9,-2,CONCRETE)
B(5,10,-2,CONCRETE:1)
B(5,11,-2,CONCRETE)
B(6,-1,-3,CONCRETE:1)
B(6,-1,-2,CONCRETE:1)
B(6,-1,-1,CONCRETE:1)
B(6,-1,0,CONCRETE:1)
B(6,-1,1,CONCRETE:1)
B(6,0,-4,CONCRETE:1)
B(6,0,-3,CONCRETE:1)
B(6,0,-2,CONCRETE:1)
B(6,0,-1,CONCRETE:1)
B(6,0,0,CONCRETE:1)
B(6,0,1,CONCRETE:1)
B(6,0,2,CONCRETE:1)
B(6,1,-5,CONCRETE:1)
B(6,1,-4,CONCRETE:1)
B(6,1,-3,CONCRETE:1)
B(6,1,-2,CONCRETE:1)
B(6,1,-1,CONCRETE:1)
B(6,1,0,CONCRETE:1)
B(6,1,1,CONCRETE:1)
B(6,1,2,CONCRETE:1)
B(6,1,3,CONCRETE:1)
B(6,1,4,CONCRETE:1)
B(6,2,-5,CONCRETE:1)
B(6,2,-4,CONCRETE:1)
B(6,2,-3,CONCRETE:1)
B(6,2,-2,CONCRETE:1)
B(6,2,-1,CONCRETE:1)
B(6,2,0,CONCRETE:1)
B(6,2,1,CONCRETE:1)
B(6,2,2,CONCRETE:1)
B(6,2,3,CONCRETE:1)
B(6,2,4,CONCRETE:1)
B(6,3,-5,CONCRETE:1)
B(6,3,-4,CONCRETE:1)
B(6,3,-3,CONCRETE:1)
B(6,3,-2,CONCRETE:1)
B(6,3,-1,CONCRETE:1)
B(6,3,0,CONCRETE:1)
B(6,3,1,CONCRETE:1)
B(6,3,2,CONCRETE:1)
B(6,3,3,CONCRETE:1)
B(6,3,4,CONCRETE:1)
B(6,4,-4,CONCRETE:1)
B(6,4,-3,CONCRETE:1)
B(6,4,-2,CONCRETE:1)
B(6,4,-1,CONCRETE:1)
B(6,4,0,CONCRETE:1)
B(6,4,1,CONCRETE:1)
B(6,4,2,CONCRETE:1)
B(6,4,3,CONCRETE:1)
B(6,5,-2,CONCRETE:4)
B(6,5,-1,CONCRETE:4)
B(6,5,0,CONCRETE:4)
B(6,5,1,CONCRETE:4)
B(6,5,2,CONCRETE:4)
B(6,6,-2,CONCRETE:4)
B(7,0,-3,CONCRETE:1)
B(7,0,-2,CONCRETE:1)
B(7,0,-1,CONCRETE:1)
B(7,0,0,CONCRETE:1)
B(7,0,1,CONCRETE:1)
B(7,1,-4,CONCRETE:1)
B(7,1,-3,CONCRETE:1)
B(7,1,-2,CONCRETE:1)
B(7,1,-1,CONCRETE:1)
B(7,1,0,CONCRETE:1)
B(7,1,1,CONCRETE:1)
B(7,1,2,CONCRETE:1)
B(7,1,3,CONCRETE:1)
B(7,2,-4,CONCRETE:1)
B(7,2,-3,CONCRETE:1)
B(7,2,-2,CONCRETE:1)
B(7,2,-1,CONCRETE:1)
B(7,2,0,CONCRETE:1)
B(7,2,1,CONCRETE:1)
B(7,2,2,CONCRETE:1)
B(7,2,3,CONCRETE:1)
B(7,3,-4,CONCRETE:1)
B(7,3,-3,CONCRETE:1)
B(7,3,-2,CONCRETE:1)
B(7,3,-1,CONCRETE:1)
B(7,3,0,CONCRETE:1)
B(7,3,1,CONCRETE:1)
B(7,3,2,CONCRETE:1)
B(7,4,-2,CONCRETE:1)
B(7,4,-1,CONCRETE:1)
B(7,4,0,CONCRETE:1)
B(7,4,1,CONCRETE:1)
B(8,0,-1,CONCRETE:1)
B(8,1,-1,CONCRETE:1)
B(8,1,0,CONCRETE:1)
B(8,1,1,CONCRETE:1)
B(8,2,-1,CONCRETE:1)
B(8,2,0,CONCRETE:1)
B(8,2,1,CONCRETE:1)
B(8,2,2,CONCRETE:1)
B(8,3,-1,CONCRETE:1)
B(8,3,0,CONCRETE:1)
B(8,3,1,CONCRETE:1)

#######################################################################
# +-----------------------------------------------------------------+ #
# |                            BO3 checks                           | #
# +-----------------------------------------------------------------+ #
#######################################################################


#######################################################################
# +-----------------------------------------------------------------+ #
# |                             Branches                            | #
# +-----------------------------------------------------------------+ #
#######################################################################


#######################################################################
# +-----------------------------------------------------------------+ #
# |                         EntityFunctions                         | #
# +-----------------------------------------------------------------+ #
#######################################################################

