
#######################################################################
# +-----------------------------------------------------------------+ #
# |                            BO3 object                           | #
# +-----------------------------------------------------------------+ #
#######################################################################

Author: LordSmellyPants

Description: No description given

Version: 3

SettingsMode: WriteWithoutComments


#######################################################################
# +-----------------------------------------------------------------+ #
# |                          Main settings                          | #
# +-----------------------------------------------------------------+ #
#######################################################################

Tree: false

Frequency: 1

Rarity: 3.0

RotateRandomly: true

SpawnHeight: randomY

SpawnHeightOffset: 0

SpawnHeightVariance: 0

##############################
# Height Limits for the BO3. #
##############################

MinHeight: 55

MaxHeight: 65

######################
# Extrusion settings #
######################

ExtrudeMode: None

ExtrudeThroughBlocks: AIR

MaxBranchDepth: 10

ExcludedBiomes: All


#######################################################################
# +-----------------------------------------------------------------+ #
# |                      Source block settings                      | #
# +-----------------------------------------------------------------+ #
#######################################################################

SourceBlocks: GRASS,DIRT,GRAVEL,SAND,SAND:1,SANDSTONE,STONE,STONE:1,STONE:3,STONE:5,DIRT:1,CLAY,CONCRETE,RED_ROSE,RED_ROSE:1,RED_ROSE:2,RED_ROSE:3,RED_ROSE:4,RED_ROSE:5,RED_ROSE:6,RED_ROSE:7,RED_ROSE:8,BROWN_MUSHROOM,RED_MUSHROOM,DOUBLE_PLANT,DOUBLE_PLANT:1,DOUBLE_PLANT:2,DOUBLE_PLANT:3,DOUBLE_PLANT:4,DOUBLE_PLANT:5,LONG_GRASS,LONG_GRASS:1,LONG_GRASS:2,DEAD_BUSH,COAL_ORE,IRON_ORE,GOLD_ORE,REDSTONE_ORE,DIAMOND_ORE,LAPIS_ORE,EMERALD_ORE,VINE,AIR,STATIONARY_WATER

MaxPercentageOutsideSourceBlock: 20

OutsideSourceBlock: placeAnyway

DoReplaceBlocks: true

IsOTGPlus: false


#######################################################################
# +-----------------------------------------------------------------+ #
# |                              Blocks                             | #
# +-----------------------------------------------------------------+ #
#######################################################################

Block(-6,0,-1,CONCRETE:1)
Block(-6,0,0,CONCRETE:1)
Block(-6,1,-1,CONCRETE:1)
Block(-6,1,0,CONCRETE:1)
Block(-5,-1,-1,CONCRETE:1)
Block(-5,-1,0,CONCRETE:1)
Block(-5,0,-2,CONCRETE:1)
Block(-5,0,-1,CONCRETE:1)
Block(-5,0,0,CONCRETE:1)
Block(-5,0,1,CONCRETE:1)
Block(-5,1,-2,CONCRETE:1)
Block(-5,1,-1,CONCRETE:1)
Block(-5,1,0,CONCRETE:1)
Block(-5,1,1,CONCRETE:1)
Block(-5,2,-1,CONCRETE:1)
Block(-5,2,0,CONCRETE:1)
Block(-4,-2,-1,CONCRETE:1)
Block(-4,-2,0,CONCRETE:1)
Block(-4,-1,-2,CONCRETE:1)
Block(-4,-1,-1,CONCRETE:1)
Block(-4,-1,0,CONCRETE:1)
Block(-4,-1,1,CONCRETE:1)
Block(-4,0,-3,CONCRETE:1)
Block(-4,0,-2,CONCRETE:1)
Block(-4,0,-1,CONCRETE:1)
Block(-4,0,0,CONCRETE:1)
Block(-4,0,1,CONCRETE:1)
Block(-4,0,2,CONCRETE:1)
Block(-4,0,3,CONCRETE:1)
Block(-4,1,-3,CONCRETE:1)
Block(-4,1,-2,CONCRETE:1)
Block(-4,1,-1,CONCRETE:1)
Block(-4,1,0,CONCRETE:1)
Block(-4,1,1,CONCRETE:1)
Block(-4,1,2,CONCRETE:1)
Block(-4,1,3,CONCRETE:1)
Block(-4,2,-2,CONCRETE:1)
Block(-4,2,-1,CONCRETE:1)
Block(-4,2,0,CONCRETE:1)
Block(-4,2,1,CONCRETE:1)
Block(-4,3,-2,CONCRETE:4)
Block(-4,3,-1,CONCRETE:4)
Block(-4,3,0,CONCRETE:4)
Block(-4,4,0,CONCRETE:4)
Block(-3,-3,0,CONCRETE:1)
Block(-3,-2,-1,CONCRETE:1)
Block(-3,-2,0,CONCRETE:1)
Block(-3,-2,1,CONCRETE:1)
Block(-3,-1,-3,CONCRETE:1)
Block(-3,-1,-2,CONCRETE:1)
Block(-3,-1,-1,CONCRETE:1)
Block(-3,-1,0,CONCRETE:1)
Block(-3,-1,1,CONCRETE:1)
Block(-3,-1,2,CONCRETE:1)
Block(-3,-1,3,CONCRETE:1)
Block(-3,0,-4,CONCRETE:1)
Block(-3,0,-3,CONCRETE:1)
Block(-3,0,-2,CONCRETE:1)
Block(-3,0,-1,CONCRETE:1)
Block(-3,0,0,CONCRETE:1)
Block(-3,0,1,CONCRETE:1)
Block(-3,0,2,CONCRETE:1)
Block(-3,0,3,CONCRETE:1)
Block(-3,0,4,CONCRETE:1)
Block(-3,1,-4,CONCRETE:1)
Block(-3,1,-3,CONCRETE:1)
Block(-3,1,-2,CONCRETE:1)
Block(-3,1,-1,CONCRETE:1)
Block(-3,1,0,CONCRETE:1)
Block(-3,1,1,CONCRETE:1)
Block(-3,1,2,CONCRETE:1)
Block(-3,1,3,CONCRETE:1)
Block(-3,1,4,CONCRETE:1)
Block(-3,2,-3,CONCRETE:1)
Block(-3,2,-2,CONCRETE:1)
Block(-3,2,-1,CONCRETE:1)
Block(-3,2,0,CONCRETE:1)
Block(-3,2,1,CONCRETE:1)
Block(-3,2,2,CONCRETE:1)
Block(-3,2,3,CONCRETE:1)
Block(-3,3,-3,CONCRETE:4)
Block(-3,3,-2,CONCRETE:4)
Block(-3,3,-1,CONCRETE:4)
Block(-3,3,0,CONCRETE:4)
Block(-3,3,1,CONCRETE:4)
Block(-3,3,2,CONCRETE:1)
Block(-3,4,-2,CONCRETE:4)
Block(-3,4,-1,CONCRETE:4)
Block(-3,4,0,CONCRETE:4)
Block(-3,4,1,CONCRETE:4)
Block(-3,5,0,CONCRETE:4)
Block(-2,-4,0,CONCRETE:1)
Block(-2,-3,-1,CONCRETE:1)
Block(-2,-3,0,CONCRETE:1)
Block(-2,-3,1,CONCRETE:1)
Block(-2,-2,-2,CONCRETE:1)
Block(-2,-2,-1,CONCRETE:1)
Block(-2,-2,0,CONCRETE:1)
Block(-2,-2,1,CONCRETE:1)
Block(-2,-2,2,CONCRETE:1)
Block(-2,-2,3,CONCRETE:1)
Block(-2,-1,-4,CONCRETE:1)
Block(-2,-1,-3,CONCRETE:1)
Block(-2,-1,-2,CONCRETE:1)
Block(-2,-1,-1,CONCRETE:1)
Block(-2,-1,0,CONCRETE:1)
Block(-2,-1,1,CONCRETE:1)
Block(-2,-1,2,CONCRETE:1)
Block(-2,-1,3,CONCRETE:1)
Block(-2,-1,4,CONCRETE:1)
Block(-2,0,-4,CONCRETE:1)
Block(-2,0,-3,CONCRETE:1)
Block(-2,0,-2,CONCRETE:1)
Block(-2,0,-1,CONCRETE:1)
Block(-2,0,0,CONCRETE:1)
Block(-2,0,1,CONCRETE:1)
Block(-2,0,2,CONCRETE:1)
Block(-2,0,3,CONCRETE:1)
Block(-2,0,4,CONCRETE:1)
Block(-2,0,5,CONCRETE:1)
Block(-2,1,-4,CONCRETE:1)
Block(-2,1,-3,CONCRETE:1)
Block(-2,1,-2,CONCRETE:1)
Block(-2,1,-1,CONCRETE:1)
Block(-2,1,0,CONCRETE:1)
Block(-2,1,1,CONCRETE:1)
Block(-2,1,2,CONCRETE:1)
Block(-2,1,3,CONCRETE:1)
Block(-2,1,4,CONCRETE:1)
Block(-2,1,5,CONCRETE:1)
Block(-2,2,-4,CONCRETE:1)
Block(-2,2,-3,CONCRETE:1)
Block(-2,2,-2,CONCRETE:1)
Block(-2,2,-1,CONCRETE:1)
Block(-2,2,0,CONCRETE:1)
Block(-2,2,1,CONCRETE:1)
Block(-2,2,2,CONCRETE:1)
Block(-2,2,3,CONCRETE:1)
Block(-2,2,4,CONCRETE:1)
Block(-2,3,-3,CONCRETE:1)
Block(-2,3,-2,CONCRETE:1)
Block(-2,3,-1,CONCRETE:1)
Block(-2,3,0,CONCRETE:1)
Block(-2,3,1,CONCRETE:1)
Block(-2,3,2,CONCRETE:1)
Block(-2,3,3,CONCRETE:1)
Block(-2,3,4,CONCRETE:1)
Block(-2,4,-3,CONCRETE:4)
Block(-2,4,-2,CONCRETE:1)
Block(-2,4,-1,CONCRETE:4)
Block(-2,4,0,CONCRETE:1)
Block(-2,4,1,CONCRETE:4)
Block(-2,4,2,CONCRETE:4)
Block(-2,5,-2,CONCRETE:1)
Block(-2,5,-1,CONCRETE:1)
Block(-2,5,0,CONCRETE:1)
Block(-2,5,1,CONCRETE:4)
Block(-2,6,-1,CONCRETE:1)
Block(-2,6,0,CONCRETE:1)
Block(-1,-5,1,CONCRETE:1)
Block(-1,-4,0,CONCRETE:1)
Block(-1,-4,1,CONCRETE:1)
Block(-1,-4,2,CONCRETE:1)
Block(-1,-3,-2,CONCRETE:1)
Block(-1,-3,-1,CONCRETE:1)
Block(-1,-3,0,CONCRETE:1)
Block(-1,-3,1,CONCRETE:1)
Block(-1,-3,2,CONCRETE:1)
Block(-1,-3,3,CONCRETE:1)
Block(-1,-2,-3,CONCRETE:1)
Block(-1,-2,-2,CONCRETE:1)
Block(-1,-2,-1,CONCRETE:1)
Block(-1,-2,0,CONCRETE:1)
Block(-1,-2,1,CONCRETE:1)
Block(-1,-2,2,CONCRETE:1)
Block(-1,-2,3,CONCRETE:1)
Block(-1,-2,4,CONCRETE:1)
Block(-1,-1,-4,CONCRETE:1)
Block(-1,-1,-3,CONCRETE:1)
Block(-1,-1,-2,CONCRETE:1)
Block(-1,-1,-1,CONCRETE:1)
Block(-1,-1,0,CONCRETE:1)
Block(-1,-1,1,CONCRETE:1)
Block(-1,-1,2,CONCRETE:1)
Block(-1,-1,3,CONCRETE:1)
Block(-1,-1,4,CONCRETE:1)
Block(-1,-1,5,CONCRETE:1)
Block(-1,0,-4,CONCRETE:1)
Block(-1,0,-3,CONCRETE:1)
Block(-1,0,-2,CONCRETE:1)
Block(-1,0,-1,CONCRETE:1)
Block(-1,0,0,CONCRETE:1)
Block(-1,0,1,CONCRETE:1)
Block(-1,0,2,CONCRETE:1)
Block(-1,0,3,CONCRETE:1)
Block(-1,0,4,CONCRETE:1)
Block(-1,0,5,CONCRETE:1)
Block(-1,0,6,CONCRETE:1)
Block(-1,1,-4,CONCRETE:1)
Block(-1,1,-3,CONCRETE:1)
Block(-1,1,-2,CONCRETE:1)
Block(-1,1,-1,CONCRETE:1)
Block(-1,1,0,CONCRETE:1)
Block(-1,1,1,CONCRETE:1)
Block(-1,1,2,CONCRETE:1)
Block(-1,1,3,CONCRETE:1)
Block(-1,1,4,CONCRETE:1)
Block(-1,1,5,CONCRETE:1)
Block(-1,1,6,CONCRETE:1)
Block(-1,2,-4,CONCRETE:1)
Block(-1,2,-3,CONCRETE:1)
Block(-1,2,-2,CONCRETE:1)
Block(-1,2,-1,CONCRETE:1)
Block(-1,2,0,CONCRETE:1)
Block(-1,2,1,CONCRETE:1)
Block(-1,2,2,CONCRETE:1)
Block(-1,2,3,CONCRETE:1)
Block(-1,2,4,CONCRETE:1)
Block(-1,2,5,CONCRETE:1)
Block(-1,3,-4,CONCRETE:1)
Block(-1,3,-3,CONCRETE:1)
Block(-1,3,-2,CONCRETE:1)
Block(-1,3,-1,CONCRETE:1)
Block(-1,3,0,CONCRETE:1)
Block(-1,3,1,CONCRETE:1)
Block(-1,3,2,CONCRETE:1)
Block(-1,3,3,CONCRETE:1)
Block(-1,3,4,CONCRETE:1)
Block(-1,4,-4,CONCRETE:4)
Block(-1,4,-3,CONCRETE:1)
Block(-1,4,-2,CONCRETE:1)
Block(-1,4,-1,CONCRETE:1)
Block(-1,4,0,CONCRETE:1)
Block(-1,4,1,CONCRETE:1)
Block(-1,4,2,CONCRETE:1)
Block(-1,4,3,CONCRETE:4)
Block(-1,4,4,CONCRETE:4)
Block(-1,5,-3,CONCRETE:1)
Block(-1,5,-2,CONCRETE:1)
Block(-1,5,-1,CONCRETE:1)
Block(-1,5,0,CONCRETE:1)
Block(-1,5,1,CONCRETE:1)
Block(-1,5,2,CONCRETE:4)
Block(-1,5,3,CONCRETE:4)
Block(-1,5,4,CONCRETE:4)
Block(-1,6,-3,CONCRETE:1)
Block(-1,6,-2,CONCRETE:1)
Block(-1,6,-1,CONCRETE:1)
Block(-1,6,0,CONCRETE:1)
Block(-1,6,1,CONCRETE:1)
Block(-1,6,2,CONCRETE:1)
Block(-1,6,3,CONCRETE:1)
Block(-1,7,-2,CONCRETE:1)
Block(-1,7,-1,CONCRETE:1)
Block(-1,7,0,CONCRETE:1)
Block(-1,7,1,CONCRETE:1)
Block(-1,7,2,CONCRETE:1)
Block(-1,8,-2,CONCRETE:1)
Block(-1,8,-1,CONCRETE:1)
Block(-1,8,0,CONCRETE:1)
Block(-1,8,1,CONCRETE:1)
Block(-1,9,-2,CONCRETE:1)
Block(-1,9,-1,CONCRETE:1)
Block(-1,9,0,CONCRETE:1)
Block(-1,9,1,CONCRETE:1)
Block(-1,10,0,CONCRETE:1)
Block(-1,10,1,CONCRETE:1)
Block(-1,11,1,CONCRETE:1)
Block(-1,12,1,CONCRETE:1)
Block(-1,13,1,CONCRETE:14)
Block(-1,14,1,CONCRETE:12)
Block(-1,15,1,CONCRETE:12)
Block(-1,16,1,CONCRETE:1)
Block(0,-5,0,CONCRETE:1)
Block(0,-5,1,CONCRETE:1)
Block(0,-4,-1,CONCRETE:1)
Block(0,-4,0,CONCRETE:1)
Block(0,-4,1,CONCRETE:1)
Block(0,-4,2,CONCRETE:1)
Block(0,-3,-2,CONCRETE:1)
Block(0,-3,-1,CONCRETE:1)
Block(0,-3,0,CONCRETE:1)
Block(0,-3,1,CONCRETE:1)
Block(0,-3,2,CONCRETE:1)
Block(0,-3,3,CONCRETE:1)
Block(0,-2,-3,CONCRETE:1)
Block(0,-2,-2,CONCRETE:1)
Block(0,-2,-1,CONCRETE:1)
Block(0,-2,0,CONCRETE:1)
Block(0,-2,1,CONCRETE:1)
Block(0,-2,2,CONCRETE:1)
Block(0,-2,3,CONCRETE:1)
Block(0,-2,4,CONCRETE:1)
Block(0,-1,-4,CONCRETE:1)
Block(0,-1,-3,CONCRETE:1)
Block(0,-1,-2,CONCRETE:1)
Block(0,-1,-1,CONCRETE:1)
Block(0,-1,0,CONCRETE:1)
Block(0,-1,1,CONCRETE:1)
Block(0,-1,2,CONCRETE:1)
Block(0,-1,3,CONCRETE:1)
Block(0,-1,4,CONCRETE:1)
Block(0,-1,5,CONCRETE:1)
Block(0,-1,6,CONCRETE:1)
Block(0,0,-4,CONCRETE:1)
Block(0,0,-3,CONCRETE:1)
Block(0,0,-2,CONCRETE:1)
Block(0,0,-1,CONCRETE:1)
Block(0,0,0,CONCRETE:1)
Block(0,0,1,CONCRETE:1)
Block(0,0,2,CONCRETE:1)
Block(0,0,3,CONCRETE:1)
Block(0,0,4,CONCRETE:1)
Block(0,0,5,CONCRETE:1)
Block(0,0,6,CONCRETE:1)
Block(0,1,-4,CONCRETE:1)
Block(0,1,-3,CONCRETE:1)
Block(0,1,-2,CONCRETE:1)
Block(0,1,-1,CONCRETE:1)
Block(0,1,0,CONCRETE:1)
Block(0,1,1,CONCRETE:1)
Block(0,1,2,CONCRETE:1)
Block(0,1,3,CONCRETE:1)
Block(0,1,4,CONCRETE:1)
Block(0,1,5,CONCRETE:1)
Block(0,1,6,CONCRETE:1)
Block(0,2,-4,CONCRETE:1)
Block(0,2,-3,CONCRETE:1)
Block(0,2,-2,CONCRETE:1)
Block(0,2,-1,CONCRETE:1)
Block(0,2,0,CONCRETE:1)
Block(0,2,1,CONCRETE:1)
Block(0,2,2,CONCRETE:1)
Block(0,2,3,CONCRETE:1)
Block(0,2,4,CONCRETE:1)
Block(0,2,5,CONCRETE:1)
Block(0,3,-3,CONCRETE:4)
Block(0,3,-2,CONCRETE:1)
Block(0,3,-1,CONCRETE:1)
Block(0,3,0,CONCRETE:1)
Block(0,3,1,CONCRETE:1)
Block(0,3,2,CONCRETE:1)
Block(0,3,3,CONCRETE:1)
Block(0,3,4,CONCRETE:1)
Block(0,3,5,CONCRETE:1)
Block(0,4,-3,CONCRETE:4)
Block(0,4,-2,CONCRETE:1)
Block(0,4,-1,CONCRETE:1)
Block(0,4,0,CONCRETE:1)
Block(0,4,1,CONCRETE:1)
Block(0,4,2,CONCRETE:1)
Block(0,4,3,CONCRETE:1)
Block(0,4,4,CONCRETE:4)
Block(0,5,-3,CONCRETE:4)
Block(0,5,-2,CONCRETE:1)
Block(0,5,-1,CONCRETE:1)
Block(0,5,0,CONCRETE:1)
Block(0,5,1,CONCRETE:1)
Block(0,5,2,CONCRETE:1)
Block(0,5,3,CONCRETE:1)
Block(0,5,4,CONCRETE:4)
Block(0,6,-2,CONCRETE:1)
Block(0,6,-1,CONCRETE:1)
Block(0,6,0,CONCRETE:1)
Block(0,6,1,CONCRETE:1)
Block(0,6,2,CONCRETE:1)
Block(0,6,3,CONCRETE:1)
Block(0,6,4,CONCRETE:1)
Block(0,7,-2,CONCRETE:1)
Block(0,7,-1,CONCRETE:1)
Block(0,7,0,CONCRETE:1)
Block(0,7,1,CONCRETE:1)
Block(0,7,2,CONCRETE:1)
Block(0,7,3,CONCRETE:1)
Block(0,8,-2,CONCRETE:1)
Block(0,8,-1,CONCRETE:1)
Block(0,8,0,CONCRETE:1)
Block(0,8,1,CONCRETE:1)
Block(0,8,2,CONCRETE:1)
Block(0,9,-2,CONCRETE:1)
Block(0,9,-1,CONCRETE:1)
Block(0,9,0,CONCRETE:1)
Block(0,9,1,CONCRETE:1)
Block(0,9,2,CONCRETE:1)
Block(0,10,-2,CONCRETE:1)
Block(0,10,-1,CONCRETE:1)
Block(0,10,0,CONCRETE:1)
Block(0,10,1,CONCRETE:1)
Block(0,10,2,CONCRETE:1)
Block(0,11,-2,CONCRETE:1)
Block(0,11,-1,CONCRETE:1)
Block(0,11,0,CONCRETE:1)
Block(0,11,1,CONCRETE:1)
Block(0,11,2,CONCRETE:1)
Block(0,12,-2,CONCRETE:1)
Block(0,12,-1,CONCRETE:1)
Block(0,12,0,CONCRETE:1)
Block(0,12,1,CONCRETE:1)
Block(0,12,2,CONCRETE:1)
Block(0,13,-2,CONCRETE:14)
Block(0,13,-1,CONCRETE:14)
Block(0,13,0,CONCRETE:14)
Block(0,13,1,CONCRETE:14)
Block(0,13,2,CONCRETE:14)
Block(0,14,-2,CONCRETE:12)
Block(0,14,-1,CONCRETE:12)
Block(0,14,0,CONCRETE:12)
Block(0,14,1,CONCRETE:12)
Block(0,14,2,CONCRETE:12)
Block(0,15,-2,CONCRETE:12)
Block(0,15,-1,CONCRETE:12)
Block(0,15,0,CONCRETE:12)
Block(0,15,1,CONCRETE:12)
Block(0,15,2,CONCRETE:12)
Block(0,16,-2,CONCRETE:1)
Block(0,16,-1,CONCRETE:1)
Block(0,16,0,CONCRETE:1)
Block(0,16,1,CONCRETE:1)
Block(0,16,2,CONCRETE:1)
Block(1,-5,0,CONCRETE:1)
Block(1,-5,1,CONCRETE:1)
Block(1,-5,2,CONCRETE:1)
Block(1,-4,-1,CONCRETE:1)
Block(1,-4,0,CONCRETE:1)
Block(1,-4,1,CONCRETE:1)
Block(1,-4,2,CONCRETE:1)
Block(1,-4,3,CONCRETE:1)
Block(1,-3,-1,CONCRETE:1)
Block(1,-3,0,CONCRETE:1)
Block(1,-3,1,CONCRETE:1)
Block(1,-3,2,CONCRETE:1)
Block(1,-3,3,CONCRETE:1)
Block(1,-2,-2,CONCRETE:1)
Block(1,-2,-1,CONCRETE:1)
Block(1,-2,0,CONCRETE:1)
Block(1,-2,1,CONCRETE:1)
Block(1,-2,2,CONCRETE:1)
Block(1,-2,3,CONCRETE:1)
Block(1,-2,4,CONCRETE:1)
Block(1,-1,-3,CONCRETE:1)
Block(1,-1,-2,CONCRETE:1)
Block(1,-1,-1,CONCRETE:1)
Block(1,-1,0,CONCRETE:1)
Block(1,-1,1,CONCRETE:1)
Block(1,-1,2,CONCRETE:1)
Block(1,-1,3,CONCRETE:1)
Block(1,-1,4,CONCRETE:1)
Block(1,-1,5,CONCRETE:1)
Block(1,0,-3,CONCRETE:1)
Block(1,0,-2,CONCRETE:1)
Block(1,0,-1,CONCRETE:1)
Block(1,0,0,CONCRETE:1)
Block(1,0,1,CONCRETE:1)
Block(1,0,2,CONCRETE:1)
Block(1,0,3,CONCRETE:1)
Block(1,0,4,CONCRETE:1)
Block(1,0,5,CONCRETE:1)
Block(1,0,6,CONCRETE:1)
Block(1,1,-3,CONCRETE:1)
Block(1,1,-2,CONCRETE:1)
Block(1,1,-1,CONCRETE:1)
Block(1,1,0,CONCRETE:1)
Block(1,1,1,CONCRETE:1)
Block(1,1,2,CONCRETE:1)
Block(1,1,3,CONCRETE:1)
Block(1,1,4,CONCRETE:1)
Block(1,1,5,CONCRETE:1)
Block(1,1,6,CONCRETE:1)
Block(1,2,-3,CONCRETE:1)
Block(1,2,-2,CONCRETE:1)
Block(1,2,-1,CONCRETE:1)
Block(1,2,0,CONCRETE:1)
Block(1,2,1,CONCRETE:1)
Block(1,2,2,CONCRETE:1)
Block(1,2,3,CONCRETE:1)
Block(1,2,4,CONCRETE:1)
Block(1,2,5,CONCRETE:1)
Block(1,2,6,CONCRETE:1)
Block(1,3,-3,CONCRETE:4)
Block(1,3,-2,CONCRETE:1)
Block(1,3,-1,CONCRETE:1)
Block(1,3,0,CONCRETE:1)
Block(1,3,1,CONCRETE:1)
Block(1,3,2,CONCRETE:1)
Block(1,3,3,CONCRETE:1)
Block(1,3,4,CONCRETE:1)
Block(1,3,5,CONCRETE:1)
Block(1,4,-2,CONCRETE:4)
Block(1,4,-1,CONCRETE:1)
Block(1,4,0,CONCRETE:1)
Block(1,4,1,CONCRETE:1)
Block(1,4,2,CONCRETE:1)
Block(1,4,3,CONCRETE:1)
Block(1,4,4,CONCRETE:1)
Block(1,4,5,CONCRETE:4)
Block(1,5,-2,CONCRETE:4)
Block(1,5,-1,CONCRETE:1)
Block(1,5,0,CONCRETE:1)
Block(1,5,1,CONCRETE:1)
Block(1,5,2,CONCRETE:1)
Block(1,5,3,CONCRETE:1)
Block(1,5,4,CONCRETE:4)
Block(1,6,-2,CONCRETE:1)
Block(1,6,-1,CONCRETE:1)
Block(1,6,0,CONCRETE:1)
Block(1,6,1,CONCRETE:1)
Block(1,6,2,CONCRETE:1)
Block(1,6,3,CONCRETE:1)
Block(1,6,4,CONCRETE:1)
Block(1,7,-2,CONCRETE:1)
Block(1,7,-1,CONCRETE:1)
Block(1,7,0,CONCRETE:1)
Block(1,7,1,CONCRETE:1)
Block(1,7,2,CONCRETE:1)
Block(1,7,3,CONCRETE:1)
Block(1,7,4,CONCRETE:1)
Block(1,8,-2,CONCRETE:1)
Block(1,8,-1,CONCRETE:1)
Block(1,8,0,CONCRETE:1)
Block(1,8,1,CONCRETE:1)
Block(1,8,2,CONCRETE:1)
Block(1,8,3,CONCRETE:1)
Block(1,9,-2,CONCRETE:1)
Block(1,9,-1,CONCRETE:1)
Block(1,9,0,CONCRETE:1)
Block(1,9,1,CONCRETE:1)
Block(1,9,2,CONCRETE:1)
Block(1,9,3,CONCRETE:1)
Block(1,10,-2,CONCRETE:1)
Block(1,10,-1,CONCRETE:1)
Block(1,10,0,CONCRETE:1)
Block(1,10,1,CONCRETE:1)
Block(1,10,2,CONCRETE:1)
Block(1,10,3,CONCRETE:1)
Block(1,11,-2,CONCRETE:1)
Block(1,11,-1,CONCRETE:1)
Block(1,11,0,CONCRETE:1)
Block(1,11,1,CONCRETE:1)
Block(1,11,2,CONCRETE:1)
Block(1,11,3,CONCRETE:1)
Block(1,12,-2,CONCRETE:1)
Block(1,12,-1,CONCRETE:1)
Block(1,12,0,CONCRETE:1)
Block(1,12,1,CONCRETE:1)
Block(1,12,2,CONCRETE:1)
Block(1,12,3,CONCRETE:1)
Block(1,13,-2,CONCRETE:14)
Block(1,13,-1,CONCRETE:14)
Block(1,13,0,CONCRETE:14)
Block(1,13,1,CONCRETE:14)
Block(1,13,2,CONCRETE:14)
Block(1,13,3,CONCRETE:14)
Block(1,14,-2,CONCRETE:12)
Block(1,14,-1,CONCRETE:12)
Block(1,14,0,CONCRETE:12)
Block(1,14,1,CONCRETE:12)
Block(1,14,2,CONCRETE:12)
Block(1,15,-2,CONCRETE:12)
Block(1,15,-1,CONCRETE:12)
Block(1,15,0,CONCRETE:12)
Block(1,15,1,CONCRETE:12)
Block(1,15,2,CONCRETE:12)
Block(1,16,-2,CONCRETE:1)
Block(1,16,-1,CONCRETE:1)
Block(1,16,0,CONCRETE:1)
Block(1,16,1,CONCRETE:1)
Block(1,16,2,CONCRETE:1)
Block(2,-5,1,CONCRETE:1)
Block(2,-5,2,CONCRETE:1)
Block(2,-4,0,CONCRETE:1)
Block(2,-4,1,CONCRETE:1)
Block(2,-4,2,CONCRETE:1)
Block(2,-3,-1,CONCRETE:1)
Block(2,-3,0,CONCRETE:1)
Block(2,-3,1,CONCRETE:1)
Block(2,-3,2,CONCRETE:1)
Block(2,-3,3,CONCRETE:1)
Block(2,-2,-2,CONCRETE:1)
Block(2,-2,-1,CONCRETE:1)
Block(2,-2,0,CONCRETE:1)
Block(2,-2,1,CONCRETE:1)
Block(2,-2,2,CONCRETE:1)
Block(2,-2,3,CONCRETE:1)
Block(2,-2,4,CONCRETE:1)
Block(2,-1,-3,CONCRETE:1)
Block(2,-1,-2,CONCRETE:1)
Block(2,-1,-1,CONCRETE:1)
Block(2,-1,0,CONCRETE:1)
Block(2,-1,1,CONCRETE:1)
Block(2,-1,2,CONCRETE:1)
Block(2,-1,3,CONCRETE:1)
Block(2,-1,4,CONCRETE:1)
Block(2,-1,5,CONCRETE:1)
Block(2,0,-3,CONCRETE:1)
Block(2,0,-2,CONCRETE:1)
Block(2,0,-1,CONCRETE:1)
Block(2,0,0,CONCRETE:1)
Block(2,0,1,CONCRETE:1)
Block(2,0,2,CONCRETE:1)
Block(2,0,3,CONCRETE:1)
Block(2,0,4,CONCRETE:1)
Block(2,0,5,CONCRETE:1)
Block(2,0,6,CONCRETE:1)
Block(2,1,-3,CONCRETE:1)
Block(2,1,-2,CONCRETE:1)
Block(2,1,-1,CONCRETE:1)
Block(2,1,0,CONCRETE:1)
Block(2,1,1,CONCRETE:1)
Block(2,1,2,CONCRETE:1)
Block(2,1,3,CONCRETE:1)
Block(2,1,4,CONCRETE:1)
Block(2,1,5,CONCRETE:1)
Block(2,1,6,CONCRETE:1)
Block(2,2,-3,CONCRETE:1)
Block(2,2,-2,CONCRETE:1)
Block(2,2,-1,CONCRETE:1)
Block(2,2,0,CONCRETE:1)
Block(2,2,1,CONCRETE:1)
Block(2,2,2,CONCRETE:1)
Block(2,2,3,CONCRETE:1)
Block(2,2,4,CONCRETE:1)
Block(2,2,5,CONCRETE:1)
Block(2,2,6,CONCRETE:1)
Block(2,3,-3,CONCRETE:4)
Block(2,3,-2,CONCRETE:1)
Block(2,3,-1,CONCRETE:1)
Block(2,3,0,CONCRETE:1)
Block(2,3,1,CONCRETE:1)
Block(2,3,2,CONCRETE:1)
Block(2,3,3,CONCRETE:1)
Block(2,3,4,CONCRETE:1)
Block(2,3,5,CONCRETE:1)
Block(2,3,6,CONCRETE:1)
Block(2,4,-2,CONCRETE:4)
Block(2,4,-1,CONCRETE:1)
Block(2,4,0,CONCRETE:1)
Block(2,4,1,CONCRETE:1)
Block(2,4,2,CONCRETE:1)
Block(2,4,3,CONCRETE:1)
Block(2,4,4,CONCRETE:1)
Block(2,4,5,CONCRETE:4)
Block(2,4,6,CONCRETE:4)
Block(2,5,-1,CONCRETE:1)
Block(2,5,0,CONCRETE:1)
Block(2,5,1,CONCRETE:1)
Block(2,5,2,CONCRETE:1)
Block(2,5,3,CONCRETE:1)
Block(2,5,4,CONCRETE:1)
Block(2,5,5,CONCRETE:4)
Block(2,6,-1,CONCRETE:1)
Block(2,6,0,CONCRETE:1)
Block(2,6,1,CONCRETE:1)
Block(2,6,2,CONCRETE:1)
Block(2,6,3,CONCRETE:1)
Block(2,6,4,CONCRETE:1)
Block(2,7,-1,CONCRETE:1)
Block(2,7,0,CONCRETE:1)
Block(2,7,1,CONCRETE:1)
Block(2,7,2,CONCRETE:1)
Block(2,7,3,CONCRETE:1)
Block(2,7,4,CONCRETE:1)
Block(2,8,-1,CONCRETE:1)
Block(2,8,0,CONCRETE:1)
Block(2,8,1,CONCRETE:1)
Block(2,8,2,CONCRETE:1)
Block(2,8,3,CONCRETE:1)
Block(2,8,4,CONCRETE:1)
Block(2,9,-1,CONCRETE:1)
Block(2,9,0,CONCRETE:1)
Block(2,9,1,CONCRETE:1)
Block(2,9,2,CONCRETE:1)
Block(2,9,3,CONCRETE:1)
Block(2,9,4,CONCRETE:1)
Block(2,10,-1,CONCRETE:1)
Block(2,10,0,CONCRETE:1)
Block(2,10,1,CONCRETE:1)
Block(2,10,2,CONCRETE:1)
Block(2,10,3,CONCRETE:1)
Block(2,10,4,CONCRETE:1)
Block(2,11,-1,CONCRETE:1)
Block(2,11,0,CONCRETE:1)
Block(2,11,1,CONCRETE:1)
Block(2,11,2,CONCRETE:1)
Block(2,11,3,CONCRETE:1)
Block(2,11,4,CONCRETE:1)
Block(2,12,-1,CONCRETE:1)
Block(2,12,0,CONCRETE:1)
Block(2,12,1,CONCRETE:1)
Block(2,12,2,CONCRETE:1)
Block(2,12,3,CONCRETE:1)
Block(2,12,4,CONCRETE:1)
Block(2,13,-1,CONCRETE:1)
Block(2,13,0,CONCRETE:14)
Block(2,13,1,CONCRETE:14)
Block(2,13,2,CONCRETE:14)
Block(2,13,3,CONCRETE:14)
Block(2,13,4,CONCRETE:14)
Block(2,14,-1,CONCRETE:1)
Block(2,14,0,CONCRETE:1)
Block(2,14,1,CONCRETE:12)
Block(2,14,2,CONCRETE:12)
Block(2,14,3,CONCRETE:12)
Block(2,14,4,CONCRETE:12)
Block(2,15,-1,CONCRETE:1)
Block(2,15,0,CONCRETE:12)
Block(2,15,1,CONCRETE:12)
Block(2,15,2,CONCRETE:12)
Block(2,15,3,CONCRETE:12)
Block(2,16,-1,CONCRETE:1)
Block(2,16,0,CONCRETE:1)
Block(2,16,1,CONCRETE:1)
Block(2,16,2,CONCRETE:1)
Block(2,16,3,CONCRETE:1)
Block(3,-4,1,CONCRETE:1)
Block(3,-4,2,CONCRETE:1)
Block(3,-3,-1,CONCRETE:1)
Block(3,-3,0,CONCRETE:1)
Block(3,-3,1,CONCRETE:1)
Block(3,-3,2,CONCRETE:1)
Block(3,-3,3,CONCRETE:1)
Block(3,-2,-2,CONCRETE:1)
Block(3,-2,-1,CONCRETE:1)
Block(3,-2,0,CONCRETE:1)
Block(3,-2,1,CONCRETE:1)
Block(3,-2,2,CONCRETE:1)
Block(3,-2,3,CONCRETE:1)
Block(3,-2,4,CONCRETE:1)
Block(3,-1,-3,CONCRETE:1)
Block(3,-1,-2,CONCRETE:1)
Block(3,-1,-1,CONCRETE:1)
Block(3,-1,0,CONCRETE:1)
Block(3,-1,1,CONCRETE:1)
Block(3,-1,2,CONCRETE:1)
Block(3,-1,3,CONCRETE:1)
Block(3,-1,4,CONCRETE:1)
Block(3,-1,5,CONCRETE:1)
Block(3,-1,6,CONCRETE:1)
Block(3,0,-3,CONCRETE:1)
Block(3,0,-2,CONCRETE:1)
Block(3,0,-1,CONCRETE:1)
Block(3,0,0,CONCRETE:1)
Block(3,0,1,CONCRETE:1)
Block(3,0,2,CONCRETE:1)
Block(3,0,3,CONCRETE:1)
Block(3,0,4,CONCRETE:1)
Block(3,0,5,CONCRETE:1)
Block(3,0,6,CONCRETE:1)
Block(3,1,-3,CONCRETE:1)
Block(3,1,-2,CONCRETE:1)
Block(3,1,-1,CONCRETE:1)
Block(3,1,0,CONCRETE:1)
Block(3,1,1,CONCRETE:1)
Block(3,1,2,CONCRETE:1)
Block(3,1,3,CONCRETE:1)
Block(3,1,4,CONCRETE:1)
Block(3,1,5,CONCRETE:1)
Block(3,1,6,CONCRETE:1)
Block(3,2,-3,CONCRETE:1)
Block(3,2,-2,CONCRETE:1)
Block(3,2,-1,CONCRETE:1)
Block(3,2,0,CONCRETE:1)
Block(3,2,1,CONCRETE:1)
Block(3,2,2,CONCRETE:1)
Block(3,2,3,CONCRETE:1)
Block(3,2,4,CONCRETE:1)
Block(3,2,5,CONCRETE:1)
Block(3,2,6,CONCRETE:1)
Block(3,3,-2,CONCRETE:4)
Block(3,3,-1,CONCRETE:1)
Block(3,3,0,CONCRETE:1)
Block(3,3,1,CONCRETE:1)
Block(3,3,2,CONCRETE:1)
Block(3,3,3,CONCRETE:1)
Block(3,3,4,CONCRETE:1)
Block(3,3,5,CONCRETE:1)
Block(3,3,6,CONCRETE:1)
Block(3,4,-1,CONCRETE:4)
Block(3,4,0,CONCRETE:1)
Block(3,4,1,CONCRETE:1)
Block(3,4,2,CONCRETE:1)
Block(3,4,3,CONCRETE:1)
Block(3,4,4,CONCRETE:1)
Block(3,4,5,CONCRETE:1)
Block(3,4,6,CONCRETE:4)
Block(3,5,-1,CONCRETE:4)
Block(3,5,0,CONCRETE:1)
Block(3,5,1,CONCRETE:1)
Block(3,5,2,CONCRETE:1)
Block(3,5,3,CONCRETE:1)
Block(3,5,4,CONCRETE:1)
Block(3,5,5,CONCRETE:4)
Block(3,6,-1,CONCRETE:1)
Block(3,6,0,CONCRETE:1)
Block(3,6,1,CONCRETE:1)
Block(3,6,2,CONCRETE:1)
Block(3,6,3,CONCRETE:1)
Block(3,6,4,CONCRETE:1)
Block(3,7,-1,CONCRETE:1)
Block(3,7,0,CONCRETE:1)
Block(3,7,1,CONCRETE:1)
Block(3,7,2,CONCRETE:1)
Block(3,7,3,CONCRETE:1)
Block(3,7,4,CONCRETE:1)
Block(3,8,-1,CONCRETE:1)
Block(3,8,0,CONCRETE:1)
Block(3,8,1,CONCRETE:1)
Block(3,8,2,CONCRETE:1)
Block(3,8,3,CONCRETE:1)
Block(3,9,-1,CONCRETE:1)
Block(3,9,0,CONCRETE:1)
Block(3,9,1,CONCRETE:1)
Block(3,9,2,CONCRETE:1)
Block(3,9,3,CONCRETE:1)
Block(3,10,-1,CONCRETE:1)
Block(3,10,0,CONCRETE:1)
Block(3,10,1,CONCRETE:1)
Block(3,10,2,CONCRETE:1)
Block(3,10,3,CONCRETE:1)
Block(3,11,-1,CONCRETE:1)
Block(3,11,0,CONCRETE:1)
Block(3,11,1,CONCRETE:1)
Block(3,11,2,CONCRETE:1)
Block(3,11,3,CONCRETE:1)
Block(3,12,-1,CONCRETE:1)
Block(3,12,0,CONCRETE:1)
Block(3,12,1,CONCRETE:1)
Block(3,12,2,CONCRETE:1)
Block(3,13,-1,CONCRETE:14)
Block(3,13,0,CONCRETE:14)
Block(3,13,1,CONCRETE:14)
Block(3,13,2,CONCRETE:14)
Block(3,14,0,CONCRETE:12)
Block(3,14,1,CONCRETE:12)
Block(3,14,2,CONCRETE:12)
Block(3,15,1,CONCRETE:12)
Block(3,15,2,CONCRETE:12)
Block(3,16,1,CONCRETE:1)
Block(3,16,2,CONCRETE:1)
Block(4,-4,2,CONCRETE:1)
Block(4,-3,1,CONCRETE:1)
Block(4,-3,2,CONCRETE:1)
Block(4,-3,3,CONCRETE:1)
Block(4,-2,-1,CONCRETE:1)
Block(4,-2,0,CONCRETE:1)
Block(4,-2,1,CONCRETE:1)
Block(4,-2,2,CONCRETE:1)
Block(4,-2,3,CONCRETE:1)
Block(4,-2,4,CONCRETE:1)
Block(4,-1,-2,CONCRETE:1)
Block(4,-1,-1,CONCRETE:1)
Block(4,-1,0,CONCRETE:1)
Block(4,-1,1,CONCRETE:1)
Block(4,-1,2,CONCRETE:1)
Block(4,-1,3,CONCRETE:1)
Block(4,-1,4,CONCRETE:1)
Block(4,-1,5,CONCRETE:1)
Block(4,0,-2,CONCRETE:1)
Block(4,0,-1,CONCRETE:1)
Block(4,0,0,CONCRETE:1)
Block(4,0,1,CONCRETE:1)
Block(4,0,2,CONCRETE:1)
Block(4,0,3,CONCRETE:1)
Block(4,0,4,CONCRETE:1)
Block(4,0,5,CONCRETE:1)
Block(4,0,6,CONCRETE:1)
Block(4,1,-2,CONCRETE:1)
Block(4,1,-1,CONCRETE:1)
Block(4,1,0,CONCRETE:1)
Block(4,1,1,CONCRETE:1)
Block(4,1,2,CONCRETE:1)
Block(4,1,3,CONCRETE:1)
Block(4,1,4,CONCRETE:1)
Block(4,1,5,CONCRETE:1)
Block(4,1,6,CONCRETE:1)
Block(4,2,-2,CONCRETE:1)
Block(4,2,-1,CONCRETE:1)
Block(4,2,0,CONCRETE:1)
Block(4,2,1,CONCRETE:1)
Block(4,2,2,CONCRETE:1)
Block(4,2,3,CONCRETE:1)
Block(4,2,4,CONCRETE:1)
Block(4,2,5,CONCRETE:1)
Block(4,2,6,CONCRETE:1)
Block(4,3,-1,CONCRETE:4)
Block(4,3,0,CONCRETE:1)
Block(4,3,1,CONCRETE:1)
Block(4,3,2,CONCRETE:1)
Block(4,3,3,CONCRETE:1)
Block(4,3,4,CONCRETE:1)
Block(4,3,5,CONCRETE:1)
Block(4,3,6,CONCRETE:4)
Block(4,4,0,CONCRETE:4)
Block(4,4,1,CONCRETE:1)
Block(4,4,2,CONCRETE:1)
Block(4,4,3,CONCRETE:1)
Block(4,4,4,CONCRETE:1)
Block(4,4,5,CONCRETE:4)
Block(4,5,0,CONCRETE:4)
Block(4,5,1,CONCRETE:4)
Block(4,5,2,CONCRETE:1)
Block(4,5,3,CONCRETE:1)
Block(4,5,4,CONCRETE:4)
Block(4,6,1,CONCRETE:1)
Block(4,6,2,CONCRETE:1)
Block(4,6,3,CONCRETE:1)
Block(4,6,4,CONCRETE:1)
Block(4,7,2,CONCRETE:1)
Block(4,7,3,CONCRETE:1)
Block(4,7,4,CONCRETE:1)
Block(4,8,2,CONCRETE:1)
Block(4,8,3,CONCRETE:1)
Block(4,9,2,CONCRETE:1)
Block(4,10,2,CONCRETE:1)
Block(5,-3,2,CONCRETE:1)
Block(5,-3,3,CONCRETE:1)
Block(5,-2,1,CONCRETE:1)
Block(5,-2,2,CONCRETE:1)
Block(5,-2,3,CONCRETE:1)
Block(5,-2,4,CONCRETE:1)
Block(5,-1,0,CONCRETE:1)
Block(5,-1,1,CONCRETE:1)
Block(5,-1,2,CONCRETE:1)
Block(5,-1,3,CONCRETE:1)
Block(5,-1,4,CONCRETE:1)
Block(5,-1,5,CONCRETE:1)
Block(5,0,0,CONCRETE:1)
Block(5,0,1,CONCRETE:1)
Block(5,0,2,CONCRETE:1)
Block(5,0,3,CONCRETE:1)
Block(5,0,4,CONCRETE:1)
Block(5,0,5,CONCRETE:1)
Block(5,0,6,CONCRETE:1)
Block(5,1,0,CONCRETE:1)
Block(5,1,1,CONCRETE:1)
Block(5,1,2,CONCRETE:1)
Block(5,1,3,CONCRETE:1)
Block(5,1,4,CONCRETE:1)
Block(5,1,5,CONCRETE:1)
Block(5,1,6,CONCRETE:1)
Block(5,2,0,CONCRETE:1)
Block(5,2,1,CONCRETE:1)
Block(5,2,2,CONCRETE:1)
Block(5,2,3,CONCRETE:1)
Block(5,2,4,CONCRETE:1)
Block(5,2,5,CONCRETE:1)
Block(5,2,6,CONCRETE:1)
Block(5,3,1,CONCRETE:1)
Block(5,3,2,CONCRETE:1)
Block(5,3,3,CONCRETE:1)
Block(5,3,4,CONCRETE:1)
Block(5,3,5,CONCRETE:4)
Block(5,4,1,CONCRETE:4)
Block(5,4,2,CONCRETE:1)
Block(5,4,3,CONCRETE:4)
Block(5,4,4,CONCRETE:4)
Block(5,5,2,CONCRETE:4)
Block(5,5,3,CONCRETE:4)
Block(5,6,2,CONCRETE:1)
Block(5,6,3,CONCRETE:1)
Block(6,-3,3,CONCRETE:1)
Block(6,-2,2,CONCRETE:1)
Block(6,-2,3,CONCRETE:1)
Block(6,-2,4,CONCRETE:1)
Block(6,-1,2,CONCRETE:1)
Block(6,-1,3,CONCRETE:1)
Block(6,-1,4,CONCRETE:1)
Block(6,0,0,CONCRETE:1)
Block(6,0,1,CONCRETE:1)
Block(6,0,2,CONCRETE:1)
Block(6,0,3,CONCRETE:1)
Block(6,0,4,CONCRETE:1)
Block(6,0,5,CONCRETE:1)
Block(6,1,0,CONCRETE:1)
Block(6,1,1,CONCRETE:1)
Block(6,1,2,CONCRETE:1)
Block(6,1,3,CONCRETE:1)
Block(6,1,4,CONCRETE:1)
Block(6,1,5,CONCRETE:1)
Block(6,1,6,CONCRETE:1)
Block(6,2,1,CONCRETE:1)
Block(6,2,2,CONCRETE:1)
Block(6,2,3,CONCRETE:1)
Block(6,2,4,CONCRETE:1)
Block(6,2,5,CONCRETE:1)
Block(6,3,1,CONCRETE:1)
Block(6,3,2,CONCRETE:1)
Block(6,3,3,CONCRETE:4)
Block(6,3,4,CONCRETE:1)
Block(6,4,2,CONCRETE:4)
Block(7,-2,3,CONCRETE:1)
Block(7,-1,2,CONCRETE:1)
Block(7,-1,3,CONCRETE:1)
Block(7,-1,4,CONCRETE:1)
Block(7,0,1,CONCRETE:1)
Block(7,0,2,CONCRETE:1)
Block(7,0,3,CONCRETE:1)
Block(7,0,4,CONCRETE:1)
Block(7,1,1,CONCRETE:1)
Block(7,1,2,CONCRETE:1)
Block(7,1,3,CONCRETE:1)
Block(7,1,4,CONCRETE:1)
Block(7,2,1,CONCRETE:1)
Block(7,2,2,CONCRETE:1)
Block(7,2,3,CONCRETE:1)
Block(7,2,4,CONCRETE:1)
Block(7,3,2,CONCRETE:1)

#######################################################################
# +-----------------------------------------------------------------+ #
# |                            BO3 checks                           | #
# +-----------------------------------------------------------------+ #
#######################################################################


#######################################################################
# +-----------------------------------------------------------------+ #
# |                             Branches                            | #
# +-----------------------------------------------------------------+ #
#######################################################################


#######################################################################
# +-----------------------------------------------------------------+ #
# |                             Entities                            | #
# +-----------------------------------------------------------------+ #
#######################################################################


#######################################################################
# +-----------------------------------------------------------------+ #
# |                            Particles                            | #
# +-----------------------------------------------------------------+ #
#######################################################################


#######################################################################
# +-----------------------------------------------------------------+ #
# |                             Spawners                            | #
# +-----------------------------------------------------------------+ #
#######################################################################


#######################################################################
# +-----------------------------------------------------------------+ #
# |                             ModData                             | #
# +-----------------------------------------------------------------+ #
#######################################################################

