
#######################################################################
# +-----------------------------------------------------------------+ #
# |                            BO3 object                           | #
# +-----------------------------------------------------------------+ #
#######################################################################

Author: Piginabag

Description: No description given

Version: 3

SettingsMode: WriteWithoutComments


#######################################################################
# +-----------------------------------------------------------------+ #
# |                          Main settings                          | #
# +-----------------------------------------------------------------+ #
#######################################################################

Tree: false

Frequency: 15

Rarity: 100.0

RotateRandomly: true

SpawnHeight: randomY

SpawnHeightOffset: 0

SpawnHeightVariance: 0

##############################
# Height Limits for the BO3. #
##############################

MinHeight: 21

MaxHeight: 21

######################
# Extrusion settings #
######################

ExtrudeMode: None

ExtrudeThroughBlocks: AIR

MaxBranchDepth: 10

ExcludedBiomes: All


#######################################################################
# +-----------------------------------------------------------------+ #
# |                      Source block settings                      | #
# +-----------------------------------------------------------------+ #
#######################################################################

SourceBlocks: STONE:1,STONE:3,STONE:5,DIRT:1,STONE,DIRT,GRAVEL,CLAY,OBSIDIAN,COAL_ORE,IRON_ORE,GOLD_ORE,REDSTONE_ORE,DIAMOND_ORE,LAPIS_ORE,EMERALD_ORE,CONCRETE,CONCRETE

MaxPercentageOutsideSourceBlock: 100

OutsideSourceBlock: dontPlace

DoReplaceBlocks: true

IsOTGPlus: false


#######################################################################
# +-----------------------------------------------------------------+ #
# |                              Blocks                             | #
# +-----------------------------------------------------------------+ #
#######################################################################

Block(-11,13,6,CONCRETE:14)
Block(-11,13,7,CONCRETE:14)
Block(-11,14,6,CONCRETE)
Block(-11,14,7,CONCRETE)
Block(-11,15,6,CONCRETE)
Block(-11,15,7,CONCRETE)
Block(-11,15,8,CONCRETE)
Block(-11,16,6,CONCRETE:12)
Block(-11,16,7,CONCRETE:12)
Block(-11,16,8,CONCRETE:12)
Block(-11,17,6,CONCRETE:15)
Block(-11,17,7,CONCRETE:15)
Block(-11,18,6,CONCRETE:12)
Block(-11,18,7,CONCRETE:12)
Block(-11,19,5,CONCRETE:1)
Block(-11,19,6,CONCRETE:1)
Block(-11,20,4,CONCRETE:1)
Block(-11,20,5,CONCRETE:1)
Block(-11,20,6,CONCRETE:1)
Block(-11,21,3,CONCRETE:1)
Block(-11,21,4,CONCRETE:1)
Block(-11,21,5,CONCRETE:1)
Block(-11,22,-2,CONCRETE:14)
Block(-11,22,-1,CONCRETE:14)
Block(-11,22,0,CONCRETE:14)
Block(-11,22,1,CONCRETE:14)
Block(-11,22,2,CONCRETE:14)
Block(-11,22,3,CONCRETE:14)
Block(-11,22,4,CONCRETE:14)
Block(-11,22,5,CONCRETE:14)
Block(-11,23,-2,CONCRETE)
Block(-11,23,-1,CONCRETE)
Block(-11,23,0,CONCRETE)
Block(-11,23,1,CONCRETE)
Block(-11,23,2,CONCRETE)
Block(-11,23,3,CONCRETE)
Block(-11,24,0,CONCRETE:4)
Block(-11,24,1,CONCRETE:4)
Block(-11,24,2,CONCRETE:4)
Block(-10,6,-1,CONCRETE)
Block(-10,6,0,CONCRETE)
Block(-10,6,1,CONCRETE)
Block(-10,7,-1,CONCRETE:8)
Block(-10,7,1,CONCRETE:8)
Block(-10,7,2,CONCRETE:8)
Block(-10,7,3,CONCRETE:8)
Block(-10,7,4,CONCRETE:8)
Block(-10,7,5,CONCRETE:8)
Block(-10,8,3,CONCRETE)
Block(-10,8,4,CONCRETE)
Block(-10,8,5,CONCRETE)
Block(-10,8,6,CONCRETE)
Block(-10,9,4,CONCRETE)
Block(-10,9,5,CONCRETE)
Block(-10,9,6,CONCRETE)
Block(-10,9,7,CONCRETE)
Block(-10,10,5,CONCRETE:15)
Block(-10,10,6,CONCRETE:15)
Block(-10,10,7,CONCRETE:15)
Block(-10,11,5,CONCRETE:4)
Block(-10,11,6,CONCRETE:4)
Block(-10,11,7,CONCRETE:4)
Block(-10,11,8,CONCRETE:4)
Block(-10,12,5,CONCRETE:1)
Block(-10,12,6,CONCRETE:1)
Block(-10,12,7,CONCRETE:1)
Block(-10,12,8,CONCRETE:1)
Block(-10,13,5,CONCRETE:14)
Block(-10,13,6,CONCRETE:14)
Block(-10,13,7,CONCRETE:14)
Block(-10,13,8,CONCRETE:14)
Block(-10,13,9,CONCRETE:14)
Block(-10,14,5,CONCRETE)
Block(-10,14,6,CONCRETE)
Block(-10,14,7,CONCRETE)
Block(-10,14,8,CONCRETE)
Block(-10,14,9,CONCRETE)
Block(-10,15,5,CONCRETE)
Block(-10,15,6,CONCRETE)
Block(-10,15,7,CONCRETE)
Block(-10,15,8,CONCRETE)
Block(-10,15,9,CONCRETE)
Block(-10,16,5,CONCRETE:12)
Block(-10,16,6,CONCRETE:12)
Block(-10,16,7,CONCRETE:12)
Block(-10,16,8,CONCRETE:12)
Block(-10,16,9,CONCRETE:12)
Block(-10,17,5,CONCRETE:15)
Block(-10,17,6,CONCRETE:15)
Block(-10,17,7,CONCRETE:15)
Block(-10,17,8,CONCRETE:15)
Block(-10,18,-9,CONCRETE:12)
Block(-10,18,4,CONCRETE:12)
Block(-10,18,5,CONCRETE:12)
Block(-10,18,6,CONCRETE:12)
Block(-10,18,7,CONCRETE:12)
Block(-10,18,8,CONCRETE:12)
Block(-10,19,-9,CONCRETE:1)
Block(-10,19,-8,CONCRETE:1)
Block(-10,19,3,CONCRETE:1)
Block(-10,19,4,CONCRETE:1)
Block(-10,19,5,CONCRETE:1)
Block(-10,19,6,CONCRETE:1)
Block(-10,19,7,CONCRETE:1)
Block(-10,19,8,CONCRETE:1)
Block(-10,20,-9,CONCRETE:1)
Block(-10,20,-8,CONCRETE:1)
Block(-10,20,-7,CONCRETE:1)
Block(-10,20,2,CONCRETE:1)
Block(-10,20,3,CONCRETE:1)
Block(-10,20,4,CONCRETE:1)
Block(-10,20,5,CONCRETE:1)
Block(-10,20,6,CONCRETE:1)
Block(-10,20,7,CONCRETE:1)
Block(-10,21,-8,CONCRETE:1)
Block(-10,21,-7,CONCRETE:1)
Block(-10,21,-6,CONCRETE:1)
Block(-10,21,-5,CONCRETE:1)
Block(-10,21,-4,CONCRETE:1)
Block(-10,21,-3,CONCRETE:1)
Block(-10,21,-2,CONCRETE:1)
Block(-10,21,-1,CONCRETE:1)
Block(-10,21,0,CONCRETE:1)
Block(-10,21,1,CONCRETE:1)
Block(-10,21,2,CONCRETE:1)
Block(-10,21,3,CONCRETE:1)
Block(-10,21,4,CONCRETE:1)
Block(-10,21,5,CONCRETE:1)
Block(-10,21,6,CONCRETE:1)
Block(-10,21,7,CONCRETE:1)
Block(-10,22,-8,CONCRETE:14)
Block(-10,22,-7,CONCRETE:14)
Block(-10,22,-6,CONCRETE:14)
Block(-10,22,-5,CONCRETE:14)
Block(-10,22,-4,CONCRETE:14)
Block(-10,22,-3,CONCRETE:14)
Block(-10,22,-2,CONCRETE:14)
Block(-10,22,-1,CONCRETE:14)
Block(-10,22,0,CONCRETE:14)
Block(-10,22,1,CONCRETE:14)
Block(-10,22,2,CONCRETE:14)
Block(-10,22,3,CONCRETE:14)
Block(-10,22,4,CONCRETE:14)
Block(-10,22,5,CONCRETE:14)
Block(-10,22,6,CONCRETE:14)
Block(-10,23,-6,CONCRETE)
Block(-10,23,-5,CONCRETE)
Block(-10,23,-4,CONCRETE)
Block(-10,23,-3,CONCRETE)
Block(-10,23,-2,CONCRETE)
Block(-10,23,-1,CONCRETE)
Block(-10,23,0,CONCRETE)
Block(-10,23,1,CONCRETE)
Block(-10,23,2,CONCRETE)
Block(-10,23,3,CONCRETE)
Block(-10,23,4,CONCRETE)
Block(-10,23,5,CONCRETE)
Block(-10,24,-4,CONCRETE:4)
Block(-10,24,-3,CONCRETE:4)
Block(-10,24,-2,CONCRETE:4)
Block(-10,24,-1,CONCRETE:4)
Block(-10,24,0,CONCRETE:4)
Block(-10,24,1,CONCRETE:4)
Block(-10,24,2,CONCRETE:4)
Block(-10,24,3,CONCRETE:4)
Block(-10,24,4,CONCRETE:4)
Block(-10,25,-2,CONCRETE:12)
Block(-10,25,-1,CONCRETE:12)
Block(-10,25,0,CONCRETE:12)
Block(-10,25,1,CONCRETE:12)
Block(-10,25,2,CONCRETE:12)
Block(-9,4,-2,CONCRETE:14)
Block(-9,4,-1,CONCRETE:14)
Block(-9,4,0,CONCRETE:14)
Block(-9,4,1,CONCRETE:14)
Block(-9,4,2,CONCRETE:14)
Block(-9,5,-4,CONCRETE)
Block(-9,5,-3,CONCRETE)
Block(-9,5,-2,CONCRETE)
Block(-9,5,-1,CONCRETE)
Block(-9,5,0,CONCRETE)
Block(-9,5,1,CONCRETE)
Block(-9,5,2,CONCRETE)
Block(-9,5,3,CONCRETE)
Block(-9,5,4,CONCRETE)
Block(-9,6,-6,CONCRETE)
Block(-9,6,-5,CONCRETE)
Block(-9,6,-4,CONCRETE)
Block(-9,6,-3,CONCRETE)
Block(-9,6,-2,CONCRETE)
Block(-9,6,-1,CONCRETE)
Block(-9,6,0,CONCRETE)
Block(-9,6,1,CONCRETE)
Block(-9,6,2,CONCRETE)
Block(-9,6,3,CONCRETE)
Block(-9,6,4,CONCRETE)
Block(-9,6,5,CONCRETE)
Block(-9,7,-7,CONCRETE:8)
Block(-9,7,-6,CONCRETE:8)
Block(-9,7,-5,CONCRETE:8)
Block(-9,7,-4,CONCRETE:8)
Block(-9,7,-3,CONCRETE:8)
Block(-9,7,-2,CONCRETE:8)
Block(-9,7,-1,CONCRETE:8)
Block(-9,7,0,CONCRETE:8)
Block(-9,7,1,CONCRETE:8)
Block(-9,7,2,CONCRETE:8)
Block(-9,7,3,CONCRETE:8)
Block(-9,7,4,CONCRETE:8)
Block(-9,7,5,CONCRETE:8)
Block(-9,7,6,CONCRETE:8)
Block(-9,7,7,CONCRETE:8)
Block(-9,8,-8,CONCRETE)
Block(-9,8,-7,CONCRETE)
Block(-9,8,-6,CONCRETE)
Block(-9,8,-5,CONCRETE)
Block(-9,8,-4,CONCRETE)
Block(-9,8,-3,CONCRETE)
Block(-9,8,-2,CONCRETE)
Block(-9,8,-1,CONCRETE)
Block(-9,8,0,CONCRETE)
Block(-9,8,1,CONCRETE)
Block(-9,8,2,CONCRETE)
Block(-9,8,3,CONCRETE)
Block(-9,8,4,CONCRETE)
Block(-9,8,5,CONCRETE)
Block(-9,8,6,CONCRETE)
Block(-9,8,7,CONCRETE)
Block(-9,9,-9,CONCRETE)
Block(-9,9,-8,CONCRETE)
Block(-9,9,-7,CONCRETE)
Block(-9,9,2,CONCRETE)
Block(-9,9,3,CONCRETE)
Block(-9,9,4,CONCRETE)
Block(-9,9,5,CONCRETE)
Block(-9,9,6,CONCRETE)
Block(-9,9,7,CONCRETE)
Block(-9,9,8,CONCRETE)
Block(-9,10,-9,CONCRETE:15)
Block(-9,10,-8,CONCRETE:15)
Block(-9,10,3,CONCRETE:15)
Block(-9,10,4,CONCRETE:15)
Block(-9,10,5,CONCRETE:15)
Block(-9,10,6,CONCRETE:15)
Block(-9,10,7,CONCRETE:15)
Block(-9,10,8,CONCRETE:15)
Block(-9,10,9,CONCRETE:15)
Block(-9,11,-10,CONCRETE:4)
Block(-9,11,-9,CONCRETE:4)
Block(-9,11,-8,CONCRETE:4)
Block(-9,11,4,CONCRETE:4)
Block(-9,11,5,CONCRETE:4)
Block(-9,11,6,CONCRETE:4)
Block(-9,11,7,CONCRETE:4)
Block(-9,11,8,CONCRETE:4)
Block(-9,11,9,CONCRETE:4)
Block(-9,12,-10,CONCRETE:1)
Block(-9,12,-9,CONCRETE:1)
Block(-9,12,-8,CONCRETE:1)
Block(-9,12,4,CONCRETE:1)
Block(-9,12,5,CONCRETE:1)
Block(-9,12,6,CONCRETE:1)
Block(-9,12,7,CONCRETE:1)
Block(-9,12,8,CONCRETE:1)
Block(-9,12,9,CONCRETE:1)
Block(-9,13,-10,CONCRETE:14)
Block(-9,13,-9,CONCRETE:14)
Block(-9,13,-8,CONCRETE:14)
Block(-9,13,4,CONCRETE:14)
Block(-9,13,5,CONCRETE:14)
Block(-9,13,6,CONCRETE:14)
Block(-9,13,7,CONCRETE:14)
Block(-9,13,8,CONCRETE:14)
Block(-9,13,9,CONCRETE:14)
Block(-9,13,10,CONCRETE:14)
Block(-9,14,-11,CONCRETE)
Block(-9,14,-10,CONCRETE)
Block(-9,14,-9,CONCRETE)
Block(-9,14,-8,CONCRETE)
Block(-9,14,4,CONCRETE)
Block(-9,14,5,CONCRETE)
Block(-9,14,6,CONCRETE)
Block(-9,14,7,CONCRETE)
Block(-9,14,8,CONCRETE)
Block(-9,14,9,CONCRETE)
Block(-9,14,10,CONCRETE)
Block(-9,15,-11,CONCRETE)
Block(-9,15,-10,CONCRETE)
Block(-9,15,-9,CONCRETE)
Block(-9,15,-8,CONCRETE)
Block(-9,15,4,CONCRETE)
Block(-9,15,5,CONCRETE)
Block(-9,15,6,CONCRETE)
Block(-9,15,7,CONCRETE)
Block(-9,15,8,CONCRETE)
Block(-9,15,9,CONCRETE)
Block(-9,15,10,CONCRETE)
Block(-9,16,-11,CONCRETE:12)
Block(-9,16,-10,CONCRETE:12)
Block(-9,16,-9,CONCRETE:12)
Block(-9,16,-8,CONCRETE:12)
Block(-9,16,4,CONCRETE:12)
Block(-9,16,5,CONCRETE:12)
Block(-9,16,6,CONCRETE:12)
Block(-9,16,7,CONCRETE:12)
Block(-9,16,8,CONCRETE:12)
Block(-9,16,9,CONCRETE:12)
Block(-9,17,-11,CONCRETE:15)
Block(-9,17,-10,CONCRETE:15)
Block(-9,17,-9,CONCRETE:15)
Block(-9,17,-8,CONCRETE:15)
Block(-9,17,4,CONCRETE:15)
Block(-9,17,5,CONCRETE:15)
Block(-9,17,6,CONCRETE:15)
Block(-9,17,7,CONCRETE:15)
Block(-9,17,8,CONCRETE:15)
Block(-9,17,9,CONCRETE:15)
Block(-9,18,-11,CONCRETE:12)
Block(-9,18,-10,CONCRETE:12)
Block(-9,18,-9,CONCRETE:12)
Block(-9,18,-8,CONCRETE:12)
Block(-9,18,-7,CONCRETE:12)
Block(-9,18,3,CONCRETE:12)
Block(-9,18,4,CONCRETE:12)
Block(-9,18,5,CONCRETE:12)
Block(-9,18,6,CONCRETE:12)
Block(-9,18,7,CONCRETE:12)
Block(-9,18,8,CONCRETE:12)
Block(-9,18,9,CONCRETE:12)
Block(-9,19,-11,CONCRETE:1)
Block(-9,19,-10,CONCRETE:1)
Block(-9,19,-9,CONCRETE:1)
Block(-9,19,-8,CONCRETE:1)
Block(-9,19,-7,CONCRETE:1)
Block(-9,19,-6,CONCRETE:1)
Block(-9,19,2,CONCRETE:1)
Block(-9,19,3,CONCRETE:1)
Block(-9,19,4,CONCRETE:1)
Block(-9,19,5,CONCRETE:1)
Block(-9,19,6,CONCRETE:1)
Block(-9,19,7,CONCRETE:1)
Block(-9,19,8,CONCRETE:1)
Block(-9,20,-10,CONCRETE:1)
Block(-9,20,-9,CONCRETE:1)
Block(-9,20,-8,CONCRETE:1)
Block(-9,20,-7,CONCRETE:1)
Block(-9,20,-6,CONCRETE:1)
Block(-9,20,-5,CONCRETE:1)
Block(-9,20,-4,CONCRETE:1)
Block(-9,20,-3,CONCRETE:1)
Block(-9,20,-2,CONCRETE:1)
Block(-9,20,-1,CONCRETE:1)
Block(-9,20,0,CONCRETE:1)
Block(-9,20,1,CONCRETE:1)
Block(-9,20,2,CONCRETE:1)
Block(-9,20,3,CONCRETE:1)
Block(-9,20,4,CONCRETE:1)
Block(-9,20,5,CONCRETE:1)
Block(-9,20,6,CONCRETE:1)
Block(-9,20,7,CONCRETE:1)
Block(-9,20,8,CONCRETE:1)
Block(-9,21,-10,CONCRETE:1)
Block(-9,21,-9,CONCRETE:1)
Block(-9,21,-8,CONCRETE:1)
Block(-9,21,-7,CONCRETE:1)
Block(-9,21,-6,CONCRETE:1)
Block(-9,21,-5,CONCRETE:1)
Block(-9,21,-4,CONCRETE:1)
Block(-9,21,-3,CONCRETE:1)
Block(-9,21,-2,CONCRETE:1)
Block(-9,21,-1,CONCRETE:1)
Block(-9,21,0,CONCRETE:1)
Block(-9,21,1,CONCRETE:1)
Block(-9,21,2,CONCRETE:1)
Block(-9,21,3,CONCRETE:1)
Block(-9,21,4,CONCRETE:1)
Block(-9,21,5,CONCRETE:1)
Block(-9,21,6,CONCRETE:1)
Block(-9,21,7,CONCRETE:1)
Block(-9,21,8,CONCRETE:1)
Block(-9,22,-9,CONCRETE:14)
Block(-9,22,-8,CONCRETE:14)
Block(-9,22,-7,CONCRETE:14)
Block(-9,22,-6,CONCRETE:14)
Block(-9,22,-5,CONCRETE:14)
Block(-9,22,-4,CONCRETE:14)
Block(-9,22,-3,CONCRETE:14)
Block(-9,22,-2,CONCRETE:14)
Block(-9,22,-1,CONCRETE:14)
Block(-9,22,0,CONCRETE:14)
Block(-9,22,1,CONCRETE:14)
Block(-9,22,2,CONCRETE:14)
Block(-9,22,3,CONCRETE:14)
Block(-9,22,4,CONCRETE:14)
Block(-9,22,5,CONCRETE:14)
Block(-9,22,6,CONCRETE:14)
Block(-9,22,7,CONCRETE:14)
Block(-9,23,-9,CONCRETE)
Block(-9,23,-8,CONCRETE)
Block(-9,23,-7,CONCRETE)
Block(-9,23,-6,CONCRETE)
Block(-9,23,-5,CONCRETE)
Block(-9,23,-4,CONCRETE)
Block(-9,23,-3,CONCRETE)
Block(-9,23,-2,CONCRETE)
Block(-9,23,-1,CONCRETE)
Block(-9,23,0,CONCRETE)
Block(-9,23,1,CONCRETE)
Block(-9,23,2,CONCRETE)
Block(-9,23,3,CONCRETE)
Block(-9,23,4,CONCRETE)
Block(-9,23,5,CONCRETE)
Block(-9,23,6,CONCRETE)
Block(-9,24,-7,CONCRETE:4)
Block(-9,24,-6,CONCRETE:4)
Block(-9,24,-5,CONCRETE:4)
Block(-9,24,-4,CONCRETE:4)
Block(-9,24,-3,CONCRETE:4)
Block(-9,24,-2,CONCRETE:4)
Block(-9,24,-1,CONCRETE:4)
Block(-9,24,0,CONCRETE:4)
Block(-9,24,1,CONCRETE:4)
Block(-9,24,2,CONCRETE:4)
Block(-9,24,3,CONCRETE:4)
Block(-9,24,4,CONCRETE:4)
Block(-9,24,5,CONCRETE:4)
Block(-9,25,-5,CONCRETE:12)
Block(-9,25,-4,CONCRETE:12)
Block(-9,25,-3,CONCRETE:12)
Block(-9,25,-2,CONCRETE:12)
Block(-9,25,-1,CONCRETE:12)
Block(-9,25,0,CONCRETE:12)
Block(-9,25,1,CONCRETE:12)
Block(-9,25,2,CONCRETE:12)
Block(-9,25,3,CONCRETE:12)
Block(-9,25,4,CONCRETE:12)
Block(-9,26,-3,CONCRETE:12)
Block(-9,26,-2,CONCRETE:12)
Block(-9,26,-1,CONCRETE:12)
Block(-9,26,0,CONCRETE:12)
Block(-9,26,1,CONCRETE:12)
Block(-9,26,2,CONCRETE:12)
Block(-8,3,-1,CONCRETE:1)
Block(-8,3,0,CONCRETE:1)
Block(-8,3,1,CONCRETE:1)
Block(-8,4,-4,CONCRETE:14)
Block(-8,4,-3,CONCRETE:14)
Block(-8,4,-2,CONCRETE:14)
Block(-8,4,-1,CONCRETE:14)
Block(-8,4,0,CONCRETE:14)
Block(-8,4,1,CONCRETE:14)
Block(-8,4,2,CONCRETE:14)
Block(-8,4,3,CONCRETE:14)
Block(-8,4,4,CONCRETE:14)
Block(-8,5,-6,CONCRETE)
Block(-8,5,-5,CONCRETE)
Block(-8,5,-4,CONCRETE)
Block(-8,5,-3,CONCRETE)
Block(-8,5,-2,CONCRETE)
Block(-8,5,-1,CONCRETE)
Block(-8,5,0,CONCRETE)
Block(-8,5,1,CONCRETE)
Block(-8,5,2,CONCRETE)
Block(-8,5,3,CONCRETE)
Block(-8,5,4,CONCRETE)
Block(-8,5,5,CONCRETE)
Block(-8,6,-8,CONCRETE)
Block(-8,6,-7,CONCRETE)
Block(-8,6,-6,CONCRETE)
Block(-8,6,-5,CONCRETE)
Block(-8,6,-4,CONCRETE)
Block(-8,6,-3,CONCRETE)
Block(-8,6,-2,CONCRETE)
Block(-8,6,-1,CONCRETE)
Block(-8,6,0,CONCRETE)
Block(-8,6,1,CONCRETE)
Block(-8,6,2,CONCRETE)
Block(-8,6,3,CONCRETE)
Block(-8,6,4,CONCRETE)
Block(-8,6,5,CONCRETE)
Block(-8,6,6,CONCRETE)
Block(-8,6,7,CONCRETE)
Block(-8,7,-9,CONCRETE:8)
Block(-8,7,-8,CONCRETE:8)
Block(-8,7,-7,CONCRETE:8)
Block(-8,7,-6,CONCRETE:8)
Block(-8,7,-5,CONCRETE:8)
Block(-8,7,-4,CONCRETE:8)
Block(-8,7,-3,CONCRETE:8)
Block(-8,7,-2,CONCRETE:8)
Block(-8,7,-1,CONCRETE:8)
Block(-8,7,0,CONCRETE:8)
Block(-8,7,1,CONCRETE:8)
Block(-8,7,2,CONCRETE:8)
Block(-8,7,3,CONCRETE:8)
Block(-8,7,4,CONCRETE:8)
Block(-8,7,5,CONCRETE:8)
Block(-8,7,6,CONCRETE:8)
Block(-8,7,7,CONCRETE:8)
Block(-8,7,8,CONCRETE:8)
Block(-8,8,-9,CONCRETE)
Block(-8,8,-8,CONCRETE)
Block(-8,8,-7,CONCRETE)
Block(-8,8,-6,CONCRETE)
Block(-8,8,-5,CONCRETE)
Block(-8,8,-4,CONCRETE)
Block(-8,8,-3,CONCRETE)
Block(-8,8,-2,CONCRETE)
Block(-8,8,-1,CONCRETE)
Block(-8,8,0,CONCRETE)
Block(-8,8,1,CONCRETE)
Block(-8,8,2,CONCRETE)
Block(-8,8,3,CONCRETE)
Block(-8,8,4,CONCRETE)
Block(-8,8,5,CONCRETE)
Block(-8,8,6,CONCRETE)
Block(-8,8,7,CONCRETE)
Block(-8,8,8,CONCRETE)
Block(-8,9,-10,CONCRETE)
Block(-8,9,-9,CONCRETE)
Block(-8,9,-8,CONCRETE)
Block(-8,9,-7,CONCRETE)
Block(-8,9,-6,CONCRETE)
Block(-8,9,-5,CONCRETE)
Block(-8,9,-4,CONCRETE)
Block(-8,9,-3,CONCRETE)
Block(-8,9,-2,CONCRETE)
Block(-8,9,-1,CONCRETE)
Block(-8,9,0,CONCRETE)
Block(-8,9,1,CONCRETE)
Block(-8,9,2,CONCRETE)
Block(-8,9,3,CONCRETE)
Block(-8,9,4,CONCRETE)
Block(-8,9,5,CONCRETE)
Block(-8,9,6,CONCRETE)
Block(-8,9,7,CONCRETE)
Block(-8,9,8,CONCRETE)
Block(-8,9,9,CONCRETE)
Block(-8,10,-11,CONCRETE:15)
Block(-8,10,-10,CONCRETE:15)
Block(-8,10,-9,CONCRETE:15)
Block(-8,10,-8,CONCRETE:15)
Block(-8,10,-7,CONCRETE:15)
Block(-8,10,-6,CONCRETE:15)
Block(-8,10,2,CONCRETE:15)
Block(-8,10,3,CONCRETE:15)
Block(-8,10,4,CONCRETE:15)
Block(-8,10,5,CONCRETE:15)
Block(-8,10,6,CONCRETE:15)
Block(-8,10,7,CONCRETE:15)
Block(-8,10,8,CONCRETE:15)
Block(-8,10,9,CONCRETE:15)
Block(-8,11,-11,CONCRETE:4)
Block(-8,11,-10,CONCRETE:4)
Block(-8,11,-9,CONCRETE:4)
Block(-8,11,-8,CONCRETE:4)
Block(-8,11,-7,CONCRETE:4)
Block(-8,11,3,CONCRETE:4)
Block(-8,11,4,CONCRETE:4)
Block(-8,11,5,CONCRETE:4)
Block(-8,11,6,CONCRETE:4)
Block(-8,11,7,CONCRETE:4)
Block(-8,11,8,CONCRETE:4)
Block(-8,11,9,CONCRETE:4)
Block(-8,11,10,CONCRETE:4)
Block(-8,12,-11,CONCRETE:1)
Block(-8,12,-10,CONCRETE:1)
Block(-8,12,-9,CONCRETE:1)
Block(-8,12,-8,CONCRETE:1)
Block(-8,12,-7,CONCRETE:1)
Block(-8,12,3,CONCRETE:1)
Block(-8,12,4,CONCRETE:1)
Block(-8,12,5,CONCRETE:1)
Block(-8,12,6,CONCRETE:1)
Block(-8,12,7,CONCRETE:1)
Block(-8,12,8,CONCRETE:1)
Block(-8,12,9,CONCRETE:1)
Block(-8,12,10,CONCRETE:1)
Block(-8,13,-12,CONCRETE:14)
Block(-8,13,-11,CONCRETE:14)
Block(-8,13,-10,CONCRETE:14)
Block(-8,13,-9,CONCRETE:14)
Block(-8,13,-8,CONCRETE:14)
Block(-8,13,-7,CONCRETE:14)
Block(-8,13,3,CONCRETE:14)
Block(-8,13,4,CONCRETE:14)
Block(-8,13,5,CONCRETE:14)
Block(-8,13,6,CONCRETE:14)
Block(-8,13,7,CONCRETE:14)
Block(-8,13,8,CONCRETE:14)
Block(-8,13,9,CONCRETE:14)
Block(-8,13,10,CONCRETE:14)
Block(-8,14,-12,CONCRETE)
Block(-8,14,-11,CONCRETE)
Block(-8,14,-10,CONCRETE)
Block(-8,14,-9,CONCRETE)
Block(-8,14,-8,CONCRETE)
Block(-8,14,-7,CONCRETE)
Block(-8,14,3,CONCRETE)
Block(-8,14,4,CONCRETE)
Block(-8,14,5,CONCRETE)
Block(-8,14,6,CONCRETE)
Block(-8,14,7,CONCRETE)
Block(-8,14,8,CONCRETE)
Block(-8,14,9,CONCRETE)
Block(-8,14,10,CONCRETE)
Block(-8,15,-12,CONCRETE)
Block(-8,15,-11,CONCRETE)
Block(-8,15,-10,CONCRETE)
Block(-8,15,-9,CONCRETE)
Block(-8,15,-8,CONCRETE)
Block(-8,15,-7,CONCRETE)
Block(-8,15,3,CONCRETE)
Block(-8,15,4,CONCRETE)
Block(-8,15,5,CONCRETE)
Block(-8,15,6,CONCRETE)
Block(-8,15,7,CONCRETE)
Block(-8,15,8,CONCRETE)
Block(-8,15,9,CONCRETE)
Block(-8,15,10,CONCRETE)
Block(-8,16,-12,CONCRETE:12)
Block(-8,16,-11,CONCRETE:12)
Block(-8,16,-10,CONCRETE:12)
Block(-8,16,-9,CONCRETE:12)
Block(-8,16,-8,CONCRETE:12)
Block(-8,16,-7,CONCRETE:12)
Block(-8,16,3,CONCRETE:12)
Block(-8,16,4,CONCRETE:12)
Block(-8,16,5,CONCRETE:12)
Block(-8,16,6,CONCRETE:12)
Block(-8,16,7,CONCRETE:12)
Block(-8,16,8,CONCRETE:12)
Block(-8,16,9,CONCRETE:12)
Block(-8,16,10,CONCRETE:12)
Block(-8,17,-12,CONCRETE:15)
Block(-8,17,-11,CONCRETE:15)
Block(-8,17,-10,CONCRETE:15)
Block(-8,17,-9,CONCRETE:15)
Block(-8,17,-8,CONCRETE:15)
Block(-8,17,-7,CONCRETE:15)
Block(-8,17,3,CONCRETE:15)
Block(-8,17,4,CONCRETE:15)
Block(-8,17,5,CONCRETE:15)
Block(-8,17,6,CONCRETE:15)
Block(-8,17,7,CONCRETE:15)
Block(-8,17,8,CONCRETE:15)
Block(-8,17,9,CONCRETE:15)
Block(-8,17,10,CONCRETE:15)
Block(-8,18,-12,CONCRETE:12)
Block(-8,18,-11,CONCRETE:12)
Block(-8,18,-10,CONCRETE:12)
Block(-8,18,-9,CONCRETE:12)
Block(-8,18,-8,CONCRETE:12)
Block(-8,18,-7,CONCRETE:12)
Block(-8,18,-6,CONCRETE:12)
Block(-8,18,2,CONCRETE:12)
Block(-8,18,3,CONCRETE:12)
Block(-8,18,4,CONCRETE:12)
Block(-8,18,5,CONCRETE:12)
Block(-8,18,6,CONCRETE:12)
Block(-8,18,7,CONCRETE:12)
Block(-8,18,8,CONCRETE:12)
Block(-8,18,9,CONCRETE:12)
Block(-8,19,-12,CONCRETE:1)
Block(-8,19,-11,CONCRETE:1)
Block(-8,19,-10,CONCRETE:1)
Block(-8,19,-9,CONCRETE:1)
Block(-8,19,-8,CONCRETE:1)
Block(-8,19,-7,CONCRETE:1)
Block(-8,19,-6,CONCRETE:1)
Block(-8,19,-5,CONCRETE:1)
Block(-8,19,-4,CONCRETE:1)
Block(-8,19,-3,CONCRETE:1)
Block(-8,19,-2,CONCRETE:1)
Block(-8,19,-1,CONCRETE:1)
Block(-8,19,0,CONCRETE:1)
Block(-8,19,1,CONCRETE:1)
Block(-8,19,2,CONCRETE:1)
Block(-8,19,3,CONCRETE:1)
Block(-8,19,4,CONCRETE:1)
Block(-8,19,5,CONCRETE:1)
Block(-8,19,6,CONCRETE:1)
Block(-8,19,7,CONCRETE:1)
Block(-8,19,8,CONCRETE:1)
Block(-8,19,9,CONCRETE:1)
Block(-8,20,-11,CONCRETE:1)
Block(-8,20,-10,CONCRETE:1)
Block(-8,20,-9,CONCRETE:1)
Block(-8,20,-8,CONCRETE:1)
Block(-8,20,-7,CONCRETE:1)
Block(-8,20,-6,CONCRETE:1)
Block(-8,20,-5,CONCRETE:1)
Block(-8,20,-4,CONCRETE:1)
Block(-8,20,-3,CONCRETE:1)
Block(-8,20,-2,CONCRETE:1)
Block(-8,20,-1,CONCRETE:1)
Block(-8,20,0,CONCRETE:1)
Block(-8,20,1,CONCRETE:1)
Block(-8,20,2,CONCRETE:1)
Block(-8,20,3,CONCRETE:1)
Block(-8,20,4,CONCRETE:1)
Block(-8,20,5,CONCRETE:1)
Block(-8,20,6,CONCRETE:1)
Block(-8,20,7,CONCRETE:1)
Block(-8,20,8,CONCRETE:1)
Block(-8,20,9,CONCRETE:1)
Block(-8,21,-11,CONCRETE:1)
Block(-8,21,-10,CONCRETE:1)
Block(-8,21,-9,CONCRETE:1)
Block(-8,21,-8,CONCRETE:1)
Block(-8,21,-7,CONCRETE:1)
Block(-8,21,-6,CONCRETE:1)
Block(-8,21,-5,CONCRETE:1)
Block(-8,21,-4,CONCRETE:1)
Block(-8,21,-3,CONCRETE:1)
Block(-8,21,-2,CONCRETE:1)
Block(-8,21,-1,CONCRETE:1)
Block(-8,21,0,CONCRETE:1)
Block(-8,21,1,CONCRETE:1)
Block(-8,21,2,CONCRETE:1)
Block(-8,21,3,CONCRETE:1)
Block(-8,21,4,CONCRETE:1)
Block(-8,21,5,CONCRETE:1)
Block(-8,21,6,CONCRETE:1)
Block(-8,21,7,CONCRETE:1)
Block(-8,21,8,CONCRETE:1)
Block(-8,22,-10,CONCRETE:14)
Block(-8,22,-9,CONCRETE:14)
Block(-8,22,-8,CONCRETE:14)
Block(-8,22,-7,CONCRETE:14)
Block(-8,22,-6,CONCRETE:14)
Block(-8,22,-5,CONCRETE:14)
Block(-8,22,-4,CONCRETE:14)
Block(-8,22,-3,CONCRETE:14)
Block(-8,22,-2,CONCRETE:14)
Block(-8,22,-1,CONCRETE:14)
Block(-8,22,0,CONCRETE:14)
Block(-8,22,1,CONCRETE:14)
Block(-8,22,2,CONCRETE:14)
Block(-8,22,3,CONCRETE:14)
Block(-8,22,4,CONCRETE:14)
Block(-8,22,5,CONCRETE:14)
Block(-8,22,6,CONCRETE:14)
Block(-8,22,7,CONCRETE:14)
Block(-8,22,8,CONCRETE:14)
Block(-8,23,-10,CONCRETE)
Block(-8,23,-9,CONCRETE)
Block(-8,23,-8,CONCRETE)
Block(-8,23,-7,CONCRETE)
Block(-8,23,-6,CONCRETE)
Block(-8,23,-5,CONCRETE)
Block(-8,23,-4,CONCRETE)
Block(-8,23,-3,CONCRETE)
Block(-8,23,-2,CONCRETE)
Block(-8,23,-1,CONCRETE)
Block(-8,23,0,CONCRETE)
Block(-8,23,1,CONCRETE)
Block(-8,23,2,CONCRETE)
Block(-8,23,3,CONCRETE)
Block(-8,23,4,CONCRETE)
Block(-8,23,5,CONCRETE)
Block(-8,23,6,CONCRETE)
Block(-8,23,7,CONCRETE)
Block(-8,24,-9,CONCRETE:4)
Block(-8,24,-8,CONCRETE:4)
Block(-8,24,-7,CONCRETE:4)
Block(-8,24,-6,CONCRETE:4)
Block(-8,24,-5,CONCRETE:4)
Block(-8,24,-4,CONCRETE:4)
Block(-8,24,-3,CONCRETE:4)
Block(-8,24,-2,CONCRETE:4)
Block(-8,24,-1,CONCRETE:4)
Block(-8,24,0,CONCRETE:4)
Block(-8,24,1,CONCRETE:4)
Block(-8,24,2,CONCRETE:4)
Block(-8,24,3,CONCRETE:4)
Block(-8,24,4,CONCRETE:4)
Block(-8,24,5,CONCRETE:4)
Block(-8,24,6,CONCRETE:4)
Block(-8,25,-7,CONCRETE:12)
Block(-8,25,-6,CONCRETE:12)
Block(-8,25,-5,CONCRETE:12)
Block(-8,25,-4,CONCRETE:12)
Block(-8,25,-3,CONCRETE:12)
Block(-8,25,-2,CONCRETE:12)
Block(-8,25,-1,CONCRETE:12)
Block(-8,25,0,CONCRETE:12)
Block(-8,25,1,CONCRETE:12)
Block(-8,25,2,CONCRETE:12)
Block(-8,25,3,CONCRETE:12)
Block(-8,25,4,CONCRETE:12)
Block(-8,25,5,CONCRETE:12)
Block(-8,26,-6,CONCRETE:12)
Block(-8,26,-5,CONCRETE:12)
Block(-8,26,-4,CONCRETE:12)
Block(-8,26,-3,CONCRETE:12)
Block(-8,26,-2,CONCRETE:12)
Block(-8,26,-1,CONCRETE:12)
Block(-8,26,0,CONCRETE:12)
Block(-8,26,1,CONCRETE:12)
Block(-8,26,2,CONCRETE:12)
Block(-8,26,3,CONCRETE:12)
Block(-8,27,-3,CONCRETE)
Block(-8,27,-2,CONCRETE)
Block(-8,27,-1,CONCRETE)
Block(-8,27,0,CONCRETE)
Block(-8,27,1,CONCRETE)
Block(-7,3,-3,CONCRETE:1)
Block(-7,3,-2,CONCRETE:1)
Block(-7,3,-1,CONCRETE:1)
Block(-7,3,0,CONCRETE:1)
Block(-7,3,1,CONCRETE:1)
Block(-7,3,2,CONCRETE:1)
Block(-7,3,3,CONCRETE:1)
Block(-7,4,-6,CONCRETE:14)
Block(-7,4,-5,CONCRETE:14)
Block(-7,4,-4,CONCRETE:14)
Block(-7,4,-3,CONCRETE:14)
Block(-7,4,-2,CONCRETE:14)
Block(-7,4,-1,CONCRETE:14)
Block(-7,4,0,CONCRETE:14)
Block(-7,4,1,CONCRETE:14)
Block(-7,4,2,CONCRETE:14)
Block(-7,4,3,CONCRETE:14)
Block(-7,4,4,CONCRETE:14)
Block(-7,4,5,CONCRETE:14)
Block(-7,5,-7,CONCRETE)
Block(-7,5,-6,CONCRETE)
Block(-7,5,-5,CONCRETE)
Block(-7,5,-4,CONCRETE)
Block(-7,5,-3,CONCRETE)
Block(-7,5,-2,CONCRETE)
Block(-7,5,-1,CONCRETE)
Block(-7,5,0,CONCRETE)
Block(-7,5,1,CONCRETE)
Block(-7,5,2,CONCRETE)
Block(-7,5,3,CONCRETE)
Block(-7,5,4,CONCRETE)
Block(-7,5,5,CONCRETE)
Block(-7,5,6,CONCRETE)
Block(-7,5,7,CONCRETE)
Block(-7,6,-9,CONCRETE)
Block(-7,6,-8,CONCRETE)
Block(-7,6,-7,CONCRETE)
Block(-7,6,-6,CONCRETE)
Block(-7,6,-5,CONCRETE)
Block(-7,6,-4,CONCRETE)
Block(-7,6,-3,CONCRETE)
Block(-7,6,-2,CONCRETE)
Block(-7,6,-1,CONCRETE)
Block(-7,6,0,CONCRETE)
Block(-7,6,1,CONCRETE)
Block(-7,6,2,CONCRETE)
Block(-7,6,3,CONCRETE)
Block(-7,6,4,CONCRETE)
Block(-7,6,5,CONCRETE)
Block(-7,6,6,CONCRETE)
Block(-7,6,7,CONCRETE)
Block(-7,6,8,CONCRETE)
Block(-7,7,-9,CONCRETE:8)
Block(-7,7,-8,CONCRETE:8)
Block(-7,7,-7,CONCRETE:8)
Block(-7,7,-6,CONCRETE:8)
Block(-7,7,-5,CONCRETE:8)
Block(-7,7,-4,CONCRETE:8)
Block(-7,7,-3,CONCRETE:8)
Block(-7,7,-2,CONCRETE:8)
Block(-7,7,-1,CONCRETE:8)
Block(-7,7,0,CONCRETE:8)
Block(-7,7,1,CONCRETE:8)
Block(-7,7,2,CONCRETE:8)
Block(-7,7,3,CONCRETE:8)
Block(-7,7,4,CONCRETE:8)
Block(-7,7,5,CONCRETE:8)
Block(-7,7,6,CONCRETE:8)
Block(-7,7,7,CONCRETE:8)
Block(-7,7,8,CONCRETE:8)
Block(-7,7,9,CONCRETE:8)
Block(-7,8,-10,CONCRETE)
Block(-7,8,-9,CONCRETE)
Block(-7,8,-8,CONCRETE)
Block(-7,8,-7,CONCRETE)
Block(-7,8,-6,CONCRETE)
Block(-7,8,-5,CONCRETE)
Block(-7,8,-4,CONCRETE)
Block(-7,8,-3,CONCRETE)
Block(-7,8,-2,CONCRETE)
Block(-7,8,-1,CONCRETE)
Block(-7,8,0,CONCRETE)
Block(-7,8,1,CONCRETE)
Block(-7,8,2,CONCRETE)
Block(-7,8,3,CONCRETE)
Block(-7,8,4,CONCRETE)
Block(-7,8,5,CONCRETE)
Block(-7,8,6,CONCRETE)
Block(-7,8,7,CONCRETE)
Block(-7,8,8,CONCRETE)
Block(-7,8,9,CONCRETE)
Block(-7,9,-11,CONCRETE)
Block(-7,9,-10,CONCRETE)
Block(-7,9,-9,CONCRETE)
Block(-7,9,-8,CONCRETE)
Block(-7,9,-7,CONCRETE)
Block(-7,9,-6,CONCRETE)
Block(-7,9,-5,CONCRETE)
Block(-7,9,-4,CONCRETE)
Block(-7,9,-3,CONCRETE)
Block(-7,9,-2,CONCRETE)
Block(-7,9,-1,CONCRETE)
Block(-7,9,0,CONCRETE)
Block(-7,9,1,CONCRETE)
Block(-7,9,2,CONCRETE)
Block(-7,9,3,CONCRETE)
Block(-7,9,4,CONCRETE)
Block(-7,9,5,CONCRETE)
Block(-7,9,6,CONCRETE)
Block(-7,9,7,CONCRETE)
Block(-7,9,8,CONCRETE)
Block(-7,9,9,CONCRETE)
Block(-7,9,10,CONCRETE)
Block(-7,10,-11,CONCRETE:15)
Block(-7,10,-10,CONCRETE:15)
Block(-7,10,-9,CONCRETE:15)
Block(-7,10,-8,CONCRETE:15)
Block(-7,10,-7,CONCRETE:15)
Block(-7,10,-6,CONCRETE:15)
Block(-7,10,-5,CONCRETE:15)
Block(-7,10,-4,CONCRETE:15)
Block(-7,10,-3,CONCRETE:15)
Block(-7,10,-2,CONCRETE:15)
Block(-7,10,-1,CONCRETE:15)
Block(-7,10,0,CONCRETE:15)
Block(-7,10,1,CONCRETE:15)
Block(-7,10,2,CONCRETE:15)
Block(-7,10,3,CONCRETE:15)
Block(-7,10,4,CONCRETE:15)
Block(-7,10,5,CONCRETE:15)
Block(-7,10,6,CONCRETE:15)
Block(-7,10,7,CONCRETE:15)
Block(-7,10,8,CONCRETE:15)
Block(-7,10,9,CONCRETE:15)
Block(-7,10,10,CONCRETE:15)
Block(-7,11,-12,CONCRETE:4)
Block(-7,11,-11,CONCRETE:4)
Block(-7,11,-10,CONCRETE:4)
Block(-7,11,-9,CONCRETE:4)
Block(-7,11,-8,CONCRETE:4)
Block(-7,11,-7,CONCRETE:4)
Block(-7,11,-6,CONCRETE:4)
Block(-7,11,-5,CONCRETE:4)
Block(-7,11,1,CONCRETE:4)
Block(-7,11,2,CONCRETE:4)
Block(-7,11,3,CONCRETE:4)
Block(-7,11,4,CONCRETE:4)
Block(-7,11,5,CONCRETE:4)
Block(-7,11,6,CONCRETE:4)
Block(-7,11,7,CONCRETE:4)
Block(-7,11,8,CONCRETE:4)
Block(-7,11,9,CONCRETE:4)
Block(-7,11,10,CONCRETE:4)
Block(-7,12,-12,CONCRETE:1)
Block(-7,12,-11,CONCRETE:1)
Block(-7,12,-10,CONCRETE:1)
Block(-7,12,-9,CONCRETE:1)
Block(-7,12,-8,CONCRETE:1)
Block(-7,12,-7,CONCRETE:1)
Block(-7,12,-6,CONCRETE:1)
Block(-7,12,2,CONCRETE:1)
Block(-7,12,3,CONCRETE:1)
Block(-7,12,4,CONCRETE:1)
Block(-7,12,5,CONCRETE:1)
Block(-7,12,6,CONCRETE:1)
Block(-7,12,7,CONCRETE:1)
Block(-7,12,8,CONCRETE:1)
Block(-7,12,9,CONCRETE:1)
Block(-7,12,10,CONCRETE:1)
Block(-7,12,11,CONCRETE:1)
Block(-7,13,-12,CONCRETE:14)
Block(-7,13,-11,CONCRETE:14)
Block(-7,13,-10,CONCRETE:14)
Block(-7,13,-9,CONCRETE:14)
Block(-7,13,-8,CONCRETE:14)
Block(-7,13,-7,CONCRETE:14)
Block(-7,13,-6,CONCRETE:14)
Block(-7,13,2,CONCRETE:14)
Block(-7,13,3,CONCRETE:14)
Block(-7,13,4,CONCRETE:14)
Block(-7,13,5,CONCRETE:14)
Block(-7,13,6,CONCRETE:14)
Block(-7,13,7,CONCRETE:14)
Block(-7,13,8,CONCRETE:14)
Block(-7,13,9,CONCRETE:14)
Block(-7,13,10,CONCRETE:14)
Block(-7,13,11,CONCRETE:14)
Block(-7,14,-12,CONCRETE)
Block(-7,14,-11,CONCRETE)
Block(-7,14,-10,CONCRETE)
Block(-7,14,-9,CONCRETE)
Block(-7,14,-8,CONCRETE)
Block(-7,14,-7,CONCRETE)
Block(-7,14,-6,CONCRETE)
Block(-7,14,2,CONCRETE)
Block(-7,14,3,CONCRETE)
Block(-7,14,4,CONCRETE)
Block(-7,14,5,CONCRETE)
Block(-7,14,6,CONCRETE)
Block(-7,14,7,CONCRETE)
Block(-7,14,8,CONCRETE)
Block(-7,14,9,CONCRETE)
Block(-7,14,10,CONCRETE)
Block(-7,14,11,CONCRETE)
Block(-7,15,-13,CONCRETE)
Block(-7,15,-12,CONCRETE)
Block(-7,15,-11,CONCRETE)
Block(-7,15,-10,CONCRETE)
Block(-7,15,-9,CONCRETE)
Block(-7,15,-8,CONCRETE)
Block(-7,15,-7,CONCRETE)
Block(-7,15,-6,CONCRETE)
Block(-7,15,2,CONCRETE)
Block(-7,15,3,CONCRETE)
Block(-7,15,4,CONCRETE)
Block(-7,15,5,CONCRETE)
Block(-7,15,6,CONCRETE)
Block(-7,15,7,CONCRETE)
Block(-7,15,8,CONCRETE)
Block(-7,15,9,CONCRETE)
Block(-7,15,10,CONCRETE)
Block(-7,15,11,CONCRETE)
Block(-7,16,-13,CONCRETE:12)
Block(-7,16,-12,CONCRETE:12)
Block(-7,16,-11,CONCRETE:12)
Block(-7,16,-10,CONCRETE:12)
Block(-7,16,-9,CONCRETE:12)
Block(-7,16,-8,CONCRETE:12)
Block(-7,16,-7,CONCRETE:12)
Block(-7,16,-6,CONCRETE:12)
Block(-7,16,2,CONCRETE:12)
Block(-7,16,3,CONCRETE:12)
Block(-7,16,4,CONCRETE:12)
Block(-7,16,5,CONCRETE:12)
Block(-7,16,6,CONCRETE:12)
Block(-7,16,7,CONCRETE:12)
Block(-7,16,8,CONCRETE:12)
Block(-7,16,9,CONCRETE:12)
Block(-7,16,10,CONCRETE:12)
Block(-7,17,-13,CONCRETE:15)
Block(-7,17,-12,CONCRETE:15)
Block(-7,17,-11,CONCRETE:15)
Block(-7,17,-10,CONCRETE:15)
Block(-7,17,-9,CONCRETE:15)
Block(-7,17,-8,CONCRETE:15)
Block(-7,17,-7,CONCRETE:15)
Block(-7,17,-6,CONCRETE:15)
Block(-7,17,-5,CONCRETE:15)
Block(-7,17,1,CONCRETE:15)
Block(-7,17,2,CONCRETE:15)
Block(-7,17,3,CONCRETE:15)
Block(-7,17,4,CONCRETE:15)
Block(-7,17,5,CONCRETE:15)
Block(-7,17,6,CONCRETE:15)
Block(-7,17,7,CONCRETE:15)
Block(-7,17,8,CONCRETE:15)
Block(-7,17,9,CONCRETE:15)
Block(-7,17,10,CONCRETE:15)
Block(-7,18,-13,CONCRETE:12)
Block(-7,18,-12,CONCRETE:12)
Block(-7,18,-11,CONCRETE:12)
Block(-7,18,-10,CONCRETE:12)
Block(-7,18,-9,CONCRETE:12)
Block(-7,18,-8,CONCRETE:12)
Block(-7,18,-7,CONCRETE:12)
Block(-7,18,-6,CONCRETE:12)
Block(-7,18,-5,CONCRETE:12)
Block(-7,18,-4,CONCRETE:12)
Block(-7,18,-3,CONCRETE:12)
Block(-7,18,-2,CONCRETE:12)
Block(-7,18,-1,CONCRETE:12)
Block(-7,18,0,CONCRETE:12)
Block(-7,18,1,CONCRETE:12)
Block(-7,18,2,CONCRETE:12)
Block(-7,18,3,CONCRETE:12)
Block(-7,18,4,CONCRETE:12)
Block(-7,18,5,CONCRETE:12)
Block(-7,18,6,CONCRETE:12)
Block(-7,18,7,CONCRETE:12)
Block(-7,18,8,CONCRETE:12)
Block(-7,18,9,CONCRETE:12)
Block(-7,18,10,CONCRETE:12)
Block(-7,19,-12,CONCRETE:1)
Block(-7,19,-11,CONCRETE:1)
Block(-7,19,-10,CONCRETE:1)
Block(-7,19,-9,CONCRETE:1)
Block(-7,19,-8,CONCRETE:1)
Block(-7,19,-7,CONCRETE:1)
Block(-7,19,-6,CONCRETE:1)
Block(-7,19,-5,CONCRETE:1)
Block(-7,19,-4,CONCRETE:1)
Block(-7,19,-3,CONCRETE:1)
Block(-7,19,-2,CONCRETE:1)
Block(-7,19,-1,CONCRETE:1)
Block(-7,19,0,CONCRETE:1)
Block(-7,19,1,CONCRETE:1)
Block(-7,19,2,CONCRETE:1)
Block(-7,19,3,CONCRETE:1)
Block(-7,19,4,CONCRETE:1)
Block(-7,19,5,CONCRETE:1)
Block(-7,19,6,CONCRETE:1)
Block(-7,19,7,CONCRETE:1)
Block(-7,19,8,CONCRETE:1)
Block(-7,19,9,CONCRETE:1)
Block(-7,19,10,CONCRETE:1)
Block(-7,20,-12,CONCRETE:1)
Block(-7,20,-11,CONCRETE:1)
Block(-7,20,-10,CONCRETE:1)
Block(-7,20,-9,CONCRETE:1)
Block(-7,20,-8,CONCRETE:1)
Block(-7,20,-7,CONCRETE:1)
Block(-7,20,-6,CONCRETE:1)
Block(-7,20,-5,CONCRETE:1)
Block(-7,20,-4,CONCRETE:1)
Block(-7,20,-3,CONCRETE:1)
Block(-7,20,-2,CONCRETE:1)
Block(-7,20,-1,CONCRETE:1)
Block(-7,20,0,CONCRETE:1)
Block(-7,20,1,CONCRETE:1)
Block(-7,20,2,CONCRETE:1)
Block(-7,20,3,CONCRETE:1)
Block(-7,20,4,CONCRETE:1)
Block(-7,20,5,CONCRETE:1)
Block(-7,20,6,CONCRETE:1)
Block(-7,20,7,CONCRETE:1)
Block(-7,20,8,CONCRETE:1)
Block(-7,20,9,CONCRETE:1)
Block(-7,21,-12,CONCRETE:1)
Block(-7,21,-11,CONCRETE:1)
Block(-7,21,-10,CONCRETE:1)
Block(-7,21,-9,CONCRETE:1)
Block(-7,21,-8,CONCRETE:1)
Block(-7,21,-7,CONCRETE:1)
Block(-7,21,-6,CONCRETE:1)
Block(-7,21,-5,CONCRETE:1)
Block(-7,21,-4,CONCRETE:1)
Block(-7,21,-3,CONCRETE:1)
Block(-7,21,-2,CONCRETE:1)
Block(-7,21,-1,CONCRETE:1)
Block(-7,21,0,CONCRETE:1)
Block(-7,21,1,CONCRETE:1)
Block(-7,21,2,CONCRETE:1)
Block(-7,21,3,CONCRETE:1)
Block(-7,21,4,CONCRETE:1)
Block(-7,21,5,CONCRETE:1)
Block(-7,21,6,CONCRETE:1)
Block(-7,21,7,CONCRETE:1)
Block(-7,21,8,CONCRETE:1)
Block(-7,21,9,CONCRETE:1)
Block(-7,22,-11,CONCRETE:14)
Block(-7,22,-10,CONCRETE:14)
Block(-7,22,-9,CONCRETE:14)
Block(-7,22,-8,CONCRETE:14)
Block(-7,22,-7,CONCRETE:14)
Block(-7,22,-6,CONCRETE:14)
Block(-7,22,-5,CONCRETE:14)
Block(-7,22,-4,CONCRETE:14)
Block(-7,22,-3,CONCRETE:14)
Block(-7,22,-2,CONCRETE:14)
Block(-7,22,-1,CONCRETE:14)
Block(-7,22,0,CONCRETE:14)
Block(-7,22,1,CONCRETE:14)
Block(-7,22,2,CONCRETE:14)
Block(-7,22,3,CONCRETE:14)
Block(-7,22,4,CONCRETE:14)
Block(-7,22,5,CONCRETE:14)
Block(-7,22,6,CONCRETE:14)
Block(-7,22,7,CONCRETE:14)
Block(-7,22,8,CONCRETE:14)
Block(-7,23,-11,CONCRETE)
Block(-7,23,-10,CONCRETE)
Block(-7,23,-9,CONCRETE)
Block(-7,23,-8,CONCRETE)
Block(-7,23,-7,CONCRETE)
Block(-7,23,-6,CONCRETE)
Block(-7,23,-5,CONCRETE)
Block(-7,23,-4,CONCRETE)
Block(-7,23,-3,CONCRETE)
Block(-7,23,-2,CONCRETE)
Block(-7,23,-1,CONCRETE)
Block(-7,23,0,CONCRETE)
Block(-7,23,1,CONCRETE)
Block(-7,23,2,CONCRETE)
Block(-7,23,3,CONCRETE)
Block(-7,23,4,CONCRETE)
Block(-7,23,5,CONCRETE)
Block(-7,23,6,CONCRETE)
Block(-7,23,7,CONCRETE)
Block(-7,23,8,CONCRETE)
Block(-7,24,-10,CONCRETE:4)
Block(-7,24,-9,CONCRETE:4)
Block(-7,24,-8,CONCRETE:4)
Block(-7,24,-7,CONCRETE:4)
Block(-7,24,-6,CONCRETE:4)
Block(-7,24,-5,CONCRETE:4)
Block(-7,24,-4,CONCRETE:4)
Block(-7,24,-3,CONCRETE:4)
Block(-7,24,-2,CONCRETE:4)
Block(-7,24,-1,CONCRETE:4)
Block(-7,24,0,CONCRETE:4)
Block(-7,24,1,CONCRETE:4)
Block(-7,24,2,CONCRETE:4)
Block(-7,24,3,CONCRETE:4)
Block(-7,24,4,CONCRETE:4)
Block(-7,24,5,CONCRETE:4)
Block(-7,24,6,CONCRETE:4)
Block(-7,24,7,CONCRETE:4)
Block(-7,25,-9,CONCRETE:12)
Block(-7,25,-8,CONCRETE:12)
Block(-7,25,-7,CONCRETE:12)
Block(-7,25,-6,CONCRETE:12)
Block(-7,25,-5,CONCRETE:12)
Block(-7,25,-4,CONCRETE:12)
Block(-7,25,-3,CONCRETE:12)
Block(-7,25,-2,CONCRETE:12)
Block(-7,25,-1,CONCRETE:12)
Block(-7,25,0,CONCRETE:12)
Block(-7,25,1,CONCRETE:12)
Block(-7,25,2,CONCRETE:12)
Block(-7,25,3,CONCRETE:12)
Block(-7,25,4,CONCRETE:12)
Block(-7,25,5,CONCRETE:12)
Block(-7,26,-7,CONCRETE:12)
Block(-7,26,-6,CONCRETE:12)
Block(-7,26,-5,CONCRETE:12)
Block(-7,26,-4,CONCRETE:12)
Block(-7,26,-3,CONCRETE:12)
Block(-7,26,-2,CONCRETE:12)
Block(-7,26,-1,CONCRETE:12)
Block(-7,26,0,CONCRETE:12)
Block(-7,26,1,CONCRETE:12)
Block(-7,26,2,CONCRETE:12)
Block(-7,26,3,CONCRETE:12)
Block(-7,26,4,CONCRETE:12)
Block(-7,27,-5,CONCRETE)
Block(-7,27,-4,CONCRETE)
Block(-7,27,-3,CONCRETE)
Block(-7,27,-2,CONCRETE)
Block(-7,27,-1,CONCRETE)
Block(-7,27,0,CONCRETE)
Block(-7,27,1,CONCRETE)
Block(-7,27,2,CONCRETE)
Block(-7,28,-1,CONCRETE:14)
Block(-6,2,-1,CONCRETE:1)
Block(-6,2,0,CONCRETE:1)
Block(-6,2,1,CONCRETE:1)
Block(-6,3,-5,CONCRETE:1)
Block(-6,3,-4,CONCRETE:1)
Block(-6,3,-3,CONCRETE:1)
Block(-6,3,-2,CONCRETE:1)
Block(-6,3,-1,CONCRETE:1)
Block(-6,3,0,CONCRETE:1)
Block(-6,3,1,CONCRETE:1)
Block(-6,3,2,CONCRETE:1)
Block(-6,3,3,CONCRETE:1)
Block(-6,3,4,CONCRETE:1)
Block(-6,3,5,CONCRETE:1)
Block(-6,4,-7,CONCRETE:14)
Block(-6,4,-6,CONCRETE:14)
Block(-6,4,-5,CONCRETE:14)
Block(-6,4,-4,CONCRETE:14)
Block(-6,4,-3,CONCRETE:14)
Block(-6,4,-2,CONCRETE:14)
Block(-6,4,-1,CONCRETE:14)
Block(-6,4,0,CONCRETE:14)
Block(-6,4,1,CONCRETE:14)
Block(-6,4,2,CONCRETE:14)
Block(-6,4,3,CONCRETE:14)
Block(-6,4,4,CONCRETE:14)
Block(-6,4,5,CONCRETE:14)
Block(-6,4,6,CONCRETE:14)
Block(-6,4,7,CONCRETE:14)
Block(-6,5,-8,CONCRETE)
Block(-6,5,-7,CONCRETE)
Block(-6,5,-6,CONCRETE)
Block(-6,5,-5,CONCRETE)
Block(-6,5,-4,CONCRETE)
Block(-6,5,-3,CONCRETE)
Block(-6,5,-2,CONCRETE)
Block(-6,5,-1,CONCRETE)
Block(-6,5,0,CONCRETE)
Block(-6,5,1,CONCRETE)
Block(-6,5,2,CONCRETE)
Block(-6,5,3,CONCRETE)
Block(-6,5,4,CONCRETE)
Block(-6,5,5,CONCRETE)
Block(-6,5,6,CONCRETE)
Block(-6,5,7,CONCRETE)
Block(-6,5,8,CONCRETE)
Block(-6,6,-9,CONCRETE)
Block(-6,6,-8,CONCRETE)
Block(-6,6,-7,CONCRETE)
Block(-6,6,-6,CONCRETE)
Block(-6,6,-5,CONCRETE)
Block(-6,6,-4,CONCRETE)
Block(-6,6,-3,CONCRETE)
Block(-6,6,-2,CONCRETE)
Block(-6,6,-1,CONCRETE)
Block(-6,6,0,CONCRETE)
Block(-6,6,1,CONCRETE)
Block(-6,6,2,CONCRETE)
Block(-6,6,3,CONCRETE)
Block(-6,6,4,CONCRETE)
Block(-6,6,5,CONCRETE)
Block(-6,6,6,CONCRETE)
Block(-6,6,7,CONCRETE)
Block(-6,6,8,CONCRETE)
Block(-6,6,9,CONCRETE)
Block(-6,7,-10,CONCRETE:8)
Block(-6,7,-9,CONCRETE:8)
Block(-6,7,-8,CONCRETE:8)
Block(-6,7,-7,CONCRETE:8)
Block(-6,7,-6,CONCRETE:8)
Block(-6,7,-5,CONCRETE:8)
Block(-6,7,-4,CONCRETE:8)
Block(-6,7,-3,CONCRETE:8)
Block(-6,7,-2,CONCRETE:8)
Block(-6,7,-1,CONCRETE:8)
Block(-6,7,0,CONCRETE:8)
Block(-6,7,1,CONCRETE:8)
Block(-6,7,2,CONCRETE:8)
Block(-6,7,3,CONCRETE:8)
Block(-6,7,4,CONCRETE:8)
Block(-6,7,5,CONCRETE:8)
Block(-6,7,6,CONCRETE:8)
Block(-6,7,7,CONCRETE:8)
Block(-6,7,8,CONCRETE:8)
Block(-6,7,9,CONCRETE:8)
Block(-6,8,-11,CONCRETE)
Block(-6,8,-10,CONCRETE)
Block(-6,8,-9,CONCRETE)
Block(-6,8,-8,CONCRETE)
Block(-6,8,-7,CONCRETE)
Block(-6,8,-6,CONCRETE)
Block(-6,8,-5,CONCRETE)
Block(-6,8,-4,CONCRETE)
Block(-6,8,-3,CONCRETE)
Block(-6,8,-2,CONCRETE)
Block(-6,8,-1,CONCRETE)
Block(-6,8,0,CONCRETE)
Block(-6,8,1,CONCRETE)
Block(-6,8,2,CONCRETE)
Block(-6,8,3,CONCRETE)
Block(-6,8,4,CONCRETE)
Block(-6,8,5,CONCRETE)
Block(-6,8,6,CONCRETE)
Block(-6,8,7,CONCRETE)
Block(-6,8,8,CONCRETE)
Block(-6,8,9,CONCRETE)
Block(-6,8,10,CONCRETE)
Block(-6,9,-11,CONCRETE)
Block(-6,9,-10,CONCRETE)
Block(-6,9,-9,CONCRETE)
Block(-6,9,-8,CONCRETE)
Block(-6,9,-7,CONCRETE)
Block(-6,9,-6,CONCRETE)
Block(-6,9,-5,CONCRETE)
Block(-6,9,-4,CONCRETE)
Block(-6,9,-3,CONCRETE)
Block(-6,9,-2,CONCRETE)
Block(-6,9,-1,CONCRETE)
Block(-6,9,0,CONCRETE)
Block(-6,9,1,CONCRETE)
Block(-6,9,2,CONCRETE)
Block(-6,9,3,CONCRETE)
Block(-6,9,4,CONCRETE)
Block(-6,9,5,CONCRETE)
Block(-6,9,6,CONCRETE)
Block(-6,9,7,CONCRETE)
Block(-6,9,8,CONCRETE)
Block(-6,9,9,CONCRETE)
Block(-6,9,10,CONCRETE)
Block(-6,9,11,CONCRETE)
Block(-6,10,-12,CONCRETE:15)
Block(-6,10,-11,CONCRETE:15)
Block(-6,10,-10,CONCRETE:15)
Block(-6,10,-9,CONCRETE:15)
Block(-6,10,-8,CONCRETE:15)
Block(-6,10,-7,CONCRETE:15)
Block(-6,10,-6,CONCRETE:15)
Block(-6,10,-5,CONCRETE:15)
Block(-6,10,-4,CONCRETE:15)
Block(-6,10,-3,CONCRETE:15)
Block(-6,10,-2,CONCRETE:15)
Block(-6,10,-1,CONCRETE:15)
Block(-6,10,0,CONCRETE:15)
Block(-6,10,1,CONCRETE:15)
Block(-6,10,2,CONCRETE:15)
Block(-6,10,3,CONCRETE:15)
Block(-6,10,4,CONCRETE:15)
Block(-6,10,5,CONCRETE:15)
Block(-6,10,6,CONCRETE:15)
Block(-6,10,7,CONCRETE:15)
Block(-6,10,8,CONCRETE:15)
Block(-6,10,9,CONCRETE:15)
Block(-6,10,10,CONCRETE:15)
Block(-6,10,11,CONCRETE:15)
Block(-6,11,-12,CONCRETE:4)
Block(-6,11,-11,CONCRETE:4)
Block(-6,11,-10,CONCRETE:4)
Block(-6,11,-9,CONCRETE:4)
Block(-6,11,-8,CONCRETE:4)
Block(-6,11,-7,CONCRETE:4)
Block(-6,11,-6,CONCRETE:4)
Block(-6,11,-5,CONCRETE:4)
Block(-6,11,-4,CONCRETE:4)
Block(-6,11,-3,CONCRETE:4)
Block(-6,11,-2,CONCRETE:4)
Block(-6,11,-1,CONCRETE:4)
Block(-6,11,0,CONCRETE:4)
Block(-6,11,1,CONCRETE:4)
Block(-6,11,2,CONCRETE:4)
Block(-6,11,3,CONCRETE:4)
Block(-6,11,4,CONCRETE:4)
Block(-6,11,5,CONCRETE:4)
Block(-6,11,6,CONCRETE:4)
Block(-6,11,7,CONCRETE:4)
Block(-6,11,8,CONCRETE:4)
Block(-6,11,9,CONCRETE:4)
Block(-6,11,10,CONCRETE:4)
Block(-6,11,11,CONCRETE:4)
Block(-6,12,-13,CONCRETE:1)
Block(-6,12,-12,CONCRETE:1)
Block(-6,12,-11,CONCRETE:1)
Block(-6,12,-10,CONCRETE:1)
Block(-6,12,-9,CONCRETE:1)
Block(-6,12,-8,CONCRETE:1)
Block(-6,12,-7,CONCRETE:1)
Block(-6,12,-6,CONCRETE:1)
Block(-6,12,-5,CONCRETE:1)
Block(-6,12,-4,CONCRETE:1)
Block(-6,12,-3,CONCRETE:1)
Block(-6,12,-2,CONCRETE:1)
Block(-6,12,-1,CONCRETE:1)
Block(-6,12,0,CONCRETE:1)
Block(-6,12,1,CONCRETE:1)
Block(-6,12,2,CONCRETE:1)
Block(-6,12,3,CONCRETE:1)
Block(-6,12,4,CONCRETE:1)
Block(-6,12,5,CONCRETE:1)
Block(-6,12,6,CONCRETE:1)
Block(-6,12,7,CONCRETE:1)
Block(-6,12,8,CONCRETE:1)
Block(-6,12,9,CONCRETE:1)
Block(-6,12,10,CONCRETE:1)
Block(-6,12,11,CONCRETE:1)
Block(-6,13,-13,CONCRETE:14)
Block(-6,13,-12,CONCRETE:14)
Block(-6,13,-11,CONCRETE:14)
Block(-6,13,-10,CONCRETE:14)
Block(-6,13,-9,CONCRETE:14)
Block(-6,13,-8,CONCRETE:14)
Block(-6,13,-7,CONCRETE:14)
Block(-6,13,-6,CONCRETE:14)
Block(-6,13,-5,CONCRETE:14)
Block(-6,13,-4,CONCRETE:14)
Block(-6,13,-3,CONCRETE:14)
Block(-6,13,-2,CONCRETE:14)
Block(-6,13,-1,CONCRETE:14)
Block(-6,13,0,CONCRETE:14)
Block(-6,13,1,CONCRETE:14)
Block(-6,13,2,CONCRETE:14)
Block(-6,13,3,CONCRETE:14)
Block(-6,13,4,CONCRETE:14)
Block(-6,13,5,CONCRETE:14)
Block(-6,13,6,CONCRETE:14)
Block(-6,13,7,CONCRETE:14)
Block(-6,13,8,CONCRETE:14)
Block(-6,13,9,CONCRETE:14)
Block(-6,13,10,CONCRETE:14)
Block(-6,13,11,CONCRETE:14)
Block(-6,14,-13,CONCRETE)
Block(-6,14,-12,CONCRETE)
Block(-6,14,-11,CONCRETE)
Block(-6,14,-10,CONCRETE)
Block(-6,14,-9,CONCRETE)
Block(-6,14,-8,CONCRETE)
Block(-6,14,-7,CONCRETE)
Block(-6,14,-6,CONCRETE)
Block(-6,14,-5,CONCRETE)
Block(-6,14,-4,CONCRETE)
Block(-6,14,-3,CONCRETE)
Block(-6,14,-2,CONCRETE)
Block(-6,14,-1,CONCRETE)
Block(-6,14,0,CONCRETE)
Block(-6,14,1,CONCRETE)
Block(-6,14,2,CONCRETE)
Block(-6,14,3,CONCRETE)
Block(-6,14,4,CONCRETE)
Block(-6,14,5,CONCRETE)
Block(-6,14,6,CONCRETE)
Block(-6,14,7,CONCRETE)
Block(-6,14,8,CONCRETE)
Block(-6,14,9,CONCRETE)
Block(-6,14,10,CONCRETE)
Block(-6,14,11,CONCRETE)
Block(-6,15,-13,CONCRETE)
Block(-6,15,-12,CONCRETE)
Block(-6,15,-11,CONCRETE)
Block(-6,15,-10,CONCRETE)
Block(-6,15,-9,CONCRETE)
Block(-6,15,-8,CONCRETE)
Block(-6,15,-7,CONCRETE)
Block(-6,15,-6,CONCRETE)
Block(-6,15,-5,CONCRETE)
Block(-6,15,-4,CONCRETE)
Block(-6,15,-3,CONCRETE)
Block(-6,15,-2,CONCRETE)
Block(-6,15,-1,CONCRETE)
Block(-6,15,0,CONCRETE)
Block(-6,15,1,CONCRETE)
Block(-6,15,2,CONCRETE)
Block(-6,15,3,CONCRETE)
Block(-6,15,4,CONCRETE)
Block(-6,15,5,CONCRETE)
Block(-6,15,6,CONCRETE)
Block(-6,15,7,CONCRETE)
Block(-6,15,8,CONCRETE)
Block(-6,15,9,CONCRETE)
Block(-6,15,10,CONCRETE)
Block(-6,15,11,CONCRETE)
Block(-6,16,-14,CONCRETE:12)
Block(-6,16,-13,CONCRETE:12)
Block(-6,16,-12,CONCRETE:12)
Block(-6,16,-11,CONCRETE:12)
Block(-6,16,-10,CONCRETE:12)
Block(-6,16,-9,CONCRETE:12)
Block(-6,16,-8,CONCRETE:12)
Block(-6,16,-7,CONCRETE:12)
Block(-6,16,-6,CONCRETE:12)
Block(-6,16,-5,CONCRETE:12)
Block(-6,16,-4,CONCRETE:12)
Block(-6,16,-3,CONCRETE:12)
Block(-6,16,-2,CONCRETE:12)
Block(-6,16,-1,CONCRETE:12)
Block(-6,16,0,CONCRETE:12)
Block(-6,16,1,CONCRETE:12)
Block(-6,16,2,CONCRETE:12)
Block(-6,16,3,CONCRETE:12)
Block(-6,16,4,CONCRETE:12)
Block(-6,16,5,CONCRETE:12)
Block(-6,16,6,CONCRETE:12)
Block(-6,16,7,CONCRETE:12)
Block(-6,16,8,CONCRETE:12)
Block(-6,16,9,CONCRETE:12)
Block(-6,16,10,CONCRETE:12)
Block(-6,16,11,CONCRETE:12)
Block(-6,17,-13,CONCRETE:15)
Block(-6,17,-12,CONCRETE:15)
Block(-6,17,-11,CONCRETE:15)
Block(-6,17,-10,CONCRETE:15)
Block(-6,17,-9,CONCRETE:15)
Block(-6,17,-8,CONCRETE:15)
Block(-6,17,-7,CONCRETE:15)
Block(-6,17,-6,CONCRETE:15)
Block(-6,17,-5,CONCRETE:15)
Block(-6,17,-4,CONCRETE:15)
Block(-6,17,-3,CONCRETE:15)
Block(-6,17,-2,CONCRETE:15)
Block(-6,17,-1,CONCRETE:15)
Block(-6,17,0,CONCRETE:15)
Block(-6,17,1,CONCRETE:15)
Block(-6,17,2,CONCRETE:15)
Block(-6,17,3,CONCRETE:15)
Block(-6,17,4,CONCRETE:15)
Block(-6,17,5,CONCRETE:15)
Block(-6,17,6,CONCRETE:15)
Block(-6,17,7,CONCRETE:15)
Block(-6,17,8,CONCRETE:15)
Block(-6,17,9,CONCRETE:15)
Block(-6,17,10,CONCRETE:15)
Block(-6,17,11,CONCRETE:15)
Block(-6,18,-13,CONCRETE:12)
Block(-6,18,-12,CONCRETE:12)
Block(-6,18,-11,CONCRETE:12)
Block(-6,18,-10,CONCRETE:12)
Block(-6,18,-9,CONCRETE:12)
Block(-6,18,-8,CONCRETE:12)
Block(-6,18,-7,CONCRETE:12)
Block(-6,18,-6,CONCRETE:12)
Block(-6,18,-5,CONCRETE:12)
Block(-6,18,-4,CONCRETE:12)
Block(-6,18,-3,CONCRETE:12)
Block(-6,18,-2,CONCRETE:12)
Block(-6,18,-1,CONCRETE:12)
Block(-6,18,0,CONCRETE:12)
Block(-6,18,1,CONCRETE:12)
Block(-6,18,2,CONCRETE:12)
Block(-6,18,3,CONCRETE:12)
Block(-6,18,4,CONCRETE:12)
Block(-6,18,5,CONCRETE:12)
Block(-6,18,6,CONCRETE:12)
Block(-6,18,7,CONCRETE:12)
Block(-6,18,8,CONCRETE:12)
Block(-6,18,9,CONCRETE:12)
Block(-6,18,10,CONCRETE:12)
Block(-6,19,-13,CONCRETE:1)
Block(-6,19,-12,CONCRETE:1)
Block(-6,19,-11,CONCRETE:1)
Block(-6,19,-10,CONCRETE:1)
Block(-6,19,-9,CONCRETE:1)
Block(-6,19,-8,CONCRETE:1)
Block(-6,19,-7,CONCRETE:1)
Block(-6,19,-6,CONCRETE:1)
Block(-6,19,-5,CONCRETE:1)
Block(-6,19,-4,CONCRETE:1)
Block(-6,19,-3,CONCRETE:1)
Block(-6,19,-2,CONCRETE:1)
Block(-6,19,-1,CONCRETE:1)
Block(-6,19,0,CONCRETE:1)
Block(-6,19,1,CONCRETE:1)
Block(-6,19,2,CONCRETE:1)
Block(-6,19,3,CONCRETE:1)
Block(-6,19,4,CONCRETE:1)
Block(-6,19,5,CONCRETE:1)
Block(-6,19,6,CONCRETE:1)
Block(-6,19,7,CONCRETE:1)
Block(-6,19,8,CONCRETE:1)
Block(-6,19,9,CONCRETE:1)
Block(-6,19,10,CONCRETE:1)
Block(-6,20,-13,CONCRETE:1)
Block(-6,20,-12,CONCRETE:1)
Block(-6,20,-11,CONCRETE:1)
Block(-6,20,-10,CONCRETE:1)
Block(-6,20,-9,CONCRETE:1)
Block(-6,20,-8,CONCRETE:1)
Block(-6,20,-7,CONCRETE:1)
Block(-6,20,-6,CONCRETE:1)
Block(-6,20,-5,CONCRETE:1)
Block(-6,20,-4,CONCRETE:1)
Block(-6,20,-3,CONCRETE:1)
Block(-6,20,-2,CONCRETE:1)
Block(-6,20,-1,CONCRETE:1)
Block(-6,20,0,CONCRETE:1)
Block(-6,20,1,CONCRETE:1)
Block(-6,20,2,CONCRETE:1)
Block(-6,20,3,CONCRETE:1)
Block(-6,20,4,CONCRETE:1)
Block(-6,20,5,CONCRETE:1)
Block(-6,20,6,CONCRETE:1)
Block(-6,20,7,CONCRETE:1)
Block(-6,20,8,CONCRETE:1)
Block(-6,20,9,CONCRETE:1)
Block(-6,20,10,CONCRETE:1)
Block(-6,21,-12,CONCRETE:1)
Block(-6,21,-11,CONCRETE:1)
Block(-6,21,-10,CONCRETE:1)
Block(-6,21,-9,CONCRETE:1)
Block(-6,21,-8,CONCRETE:1)
Block(-6,21,-7,CONCRETE:1)
Block(-6,21,-6,CONCRETE:1)
Block(-6,21,-5,CONCRETE:1)
Block(-6,21,-4,CONCRETE:1)
Block(-6,21,-3,CONCRETE:1)
Block(-6,21,-2,CONCRETE:1)
Block(-6,21,-1,CONCRETE:1)
Block(-6,21,0,CONCRETE:1)
Block(-6,21,1,CONCRETE:1)
Block(-6,21,2,CONCRETE:1)
Block(-6,21,3,CONCRETE:1)
Block(-6,21,4,CONCRETE:1)
Block(-6,21,5,CONCRETE:1)
Block(-6,21,6,CONCRETE:1)
Block(-6,21,7,CONCRETE:1)
Block(-6,21,8,CONCRETE:1)
Block(-6,21,9,CONCRETE:1)
Block(-6,22,-12,CONCRETE:14)
Block(-6,22,-11,CONCRETE:14)
Block(-6,22,-10,CONCRETE:14)
Block(-6,22,-9,CONCRETE:14)
Block(-6,22,-8,CONCRETE:14)
Block(-6,22,-7,CONCRETE:14)
Block(-6,22,-6,CONCRETE:14)
Block(-6,22,-5,CONCRETE:14)
Block(-6,22,-4,CONCRETE:14)
Block(-6,22,-3,CONCRETE:14)
Block(-6,22,-2,CONCRETE:14)
Block(-6,22,-1,CONCRETE:14)
Block(-6,22,0,CONCRETE:14)
Block(-6,22,1,CONCRETE:14)
Block(-6,22,2,CONCRETE:14)
Block(-6,22,3,CONCRETE:14)
Block(-6,22,4,CONCRETE:14)
Block(-6,22,5,CONCRETE:14)
Block(-6,22,6,CONCRETE:14)
Block(-6,22,7,CONCRETE:14)
Block(-6,22,8,CONCRETE:14)
Block(-6,22,9,CONCRETE:14)
Block(-6,23,-11,CONCRETE)
Block(-6,23,-10,CONCRETE)
Block(-6,23,-9,CONCRETE)
Block(-6,23,-8,CONCRETE)
Block(-6,23,-7,CONCRETE)
Block(-6,23,-6,CONCRETE)
Block(-6,23,-5,CONCRETE)
Block(-6,23,-4,CONCRETE)
Block(-6,23,-3,CONCRETE)
Block(-6,23,-2,CONCRETE)
Block(-6,23,-1,CONCRETE)
Block(-6,23,0,CONCRETE)
Block(-6,23,1,CONCRETE)
Block(-6,23,2,CONCRETE)
Block(-6,23,3,CONCRETE)
Block(-6,23,4,CONCRETE)
Block(-6,23,5,CONCRETE)
Block(-6,23,6,CONCRETE)
Block(-6,23,7,CONCRETE)
Block(-6,23,8,CONCRETE)
Block(-6,24,-11,CONCRETE:4)
Block(-6,24,-10,CONCRETE:4)
Block(-6,24,-9,CONCRETE:4)
Block(-6,24,-8,CONCRETE:4)
Block(-6,24,-7,CONCRETE:4)
Block(-6,24,-6,CONCRETE:4)
Block(-6,24,-5,CONCRETE:4)
Block(-6,24,-4,CONCRETE:4)
Block(-6,24,-3,CONCRETE:4)
Block(-6,24,-2,CONCRETE:4)
Block(-6,24,-1,CONCRETE:4)
Block(-6,24,0,CONCRETE:4)
Block(-6,24,1,CONCRETE:4)
Block(-6,24,2,CONCRETE:4)
Block(-6,24,3,CONCRETE:4)
Block(-6,24,4,CONCRETE:4)
Block(-6,24,5,CONCRETE:4)
Block(-6,24,6,CONCRETE:4)
Block(-6,24,7,CONCRETE:4)
Block(-6,25,-10,CONCRETE:12)
Block(-6,25,-9,CONCRETE:12)
Block(-6,25,-8,CONCRETE:12)
Block(-6,25,-7,CONCRETE:12)
Block(-6,25,-6,CONCRETE:12)
Block(-6,25,-5,CONCRETE:12)
Block(-6,25,-4,CONCRETE:12)
Block(-6,25,-3,CONCRETE:12)
Block(-6,25,-2,CONCRETE:12)
Block(-6,25,-1,CONCRETE:12)
Block(-6,25,0,CONCRETE:12)
Block(-6,25,1,CONCRETE:12)
Block(-6,25,2,CONCRETE:12)
Block(-6,25,3,CONCRETE:12)
Block(-6,25,4,CONCRETE:12)
Block(-6,25,5,CONCRETE:12)
Block(-6,25,6,CONCRETE:12)
Block(-6,26,-9,CONCRETE:12)
Block(-6,26,-8,CONCRETE:12)
Block(-6,26,-7,CONCRETE:12)
Block(-6,26,-6,CONCRETE:12)
Block(-6,26,-5,CONCRETE:12)
Block(-6,26,-4,CONCRETE:12)
Block(-6,26,-3,CONCRETE:12)
Block(-6,26,-2,CONCRETE:12)
Block(-6,26,-1,CONCRETE:12)
Block(-6,26,0,CONCRETE:12)
Block(-6,26,1,CONCRETE:12)
Block(-6,26,2,CONCRETE:12)
Block(-6,26,3,CONCRETE:12)
Block(-6,26,4,CONCRETE:12)
Block(-6,26,5,CONCRETE:12)
Block(-6,27,-7,CONCRETE)
Block(-6,27,-6,CONCRETE)
Block(-6,27,-5,CONCRETE)
Block(-6,27,-4,CONCRETE)
Block(-6,27,-3,CONCRETE)
Block(-6,27,-2,CONCRETE)
Block(-6,27,-1,CONCRETE)
Block(-6,27,0,CONCRETE)
Block(-6,27,1,CONCRETE)
Block(-6,27,2,CONCRETE)
Block(-6,27,3,CONCRETE)
Block(-6,28,-3,CONCRETE:14)
Block(-6,28,-2,CONCRETE:14)
Block(-6,28,-1,CONCRETE:14)
Block(-6,28,0,CONCRETE:14)
Block(-6,28,1,CONCRETE:14)
Block(-5,1,0,CONCRETE)
Block(-5,2,-4,CONCRETE:1)
Block(-5,2,-3,CONCRETE:1)
Block(-5,2,-2,CONCRETE:1)
Block(-5,2,-1,CONCRETE:1)
Block(-5,2,0,CONCRETE:1)
Block(-5,2,1,CONCRETE:1)
Block(-5,2,2,CONCRETE:1)
Block(-5,2,3,CONCRETE:1)
Block(-5,2,4,CONCRETE:1)
Block(-5,3,-6,CONCRETE:1)
Block(-5,3,-5,CONCRETE:1)
Block(-5,3,-4,CONCRETE:1)
Block(-5,3,-3,CONCRETE:1)
Block(-5,3,-2,CONCRETE:1)
Block(-5,3,-1,CONCRETE:1)
Block(-5,3,0,CONCRETE:1)
Block(-5,3,1,CONCRETE:1)
Block(-5,3,2,CONCRETE:1)
Block(-5,3,3,CONCRETE:1)
Block(-5,3,4,CONCRETE:1)
Block(-5,3,5,CONCRETE:1)
Block(-5,3,6,CONCRETE:1)
Block(-5,4,-8,CONCRETE:14)
Block(-5,4,-7,CONCRETE:14)
Block(-5,4,-6,CONCRETE:14)
Block(-5,4,-5,CONCRETE:14)
Block(-5,4,-4,CONCRETE:14)
Block(-5,4,-3,CONCRETE:14)
Block(-5,4,-2,CONCRETE:14)
Block(-5,4,-1,CONCRETE:14)
Block(-5,4,0,CONCRETE:14)
Block(-5,4,1,CONCRETE:14)
Block(-5,4,2,CONCRETE:14)
Block(-5,4,3,CONCRETE:14)
Block(-5,4,4,CONCRETE:14)
Block(-5,4,5,CONCRETE:14)
Block(-5,4,6,CONCRETE:14)
Block(-5,4,7,CONCRETE:14)
Block(-5,5,-9,CONCRETE)
Block(-5,5,-8,CONCRETE)
Block(-5,5,-7,CONCRETE)
Block(-5,5,-6,CONCRETE)
Block(-5,5,-5,CONCRETE)
Block(-5,5,-4,CONCRETE)
Block(-5,5,-3,CONCRETE)
Block(-5,5,-2,CONCRETE)
Block(-5,5,-1,CONCRETE)
Block(-5,5,0,CONCRETE)
Block(-5,5,1,CONCRETE)
Block(-5,5,2,CONCRETE)
Block(-5,5,3,CONCRETE)
Block(-5,5,4,CONCRETE)
Block(-5,5,5,CONCRETE)
Block(-5,5,6,CONCRETE)
Block(-5,5,7,CONCRETE)
Block(-5,5,8,CONCRETE)
Block(-5,5,9,CONCRETE)
Block(-5,6,-10,CONCRETE)
Block(-5,6,-9,CONCRETE)
Block(-5,6,-8,CONCRETE)
Block(-5,6,-7,CONCRETE)
Block(-5,6,-6,CONCRETE)
Block(-5,6,-5,CONCRETE)
Block(-5,6,-4,CONCRETE)
Block(-5,6,-3,CONCRETE)
Block(-5,6,-2,CONCRETE)
Block(-5,6,-1,CONCRETE)
Block(-5,6,0,CONCRETE)
Block(-5,6,1,CONCRETE)
Block(-5,6,2,CONCRETE)
Block(-5,6,3,CONCRETE)
Block(-5,6,4,CONCRETE)
Block(-5,6,5,CONCRETE)
Block(-5,6,6,CONCRETE)
Block(-5,6,7,CONCRETE)
Block(-5,6,8,CONCRETE)
Block(-5,6,9,CONCRETE)
Block(-5,7,-11,CONCRETE:8)
Block(-5,7,-10,CONCRETE:8)
Block(-5,7,-9,CONCRETE:8)
Block(-5,7,-8,CONCRETE:8)
Block(-5,7,-7,CONCRETE:8)
Block(-5,7,-6,CONCRETE:8)
Block(-5,7,-5,CONCRETE:8)
Block(-5,7,-4,CONCRETE:8)
Block(-5,7,-3,CONCRETE:8)
Block(-5,7,-2,CONCRETE:8)
Block(-5,7,-1,CONCRETE:8)
Block(-5,7,0,CONCRETE:8)
Block(-5,7,1,CONCRETE:8)
Block(-5,7,2,CONCRETE:8)
Block(-5,7,3,CONCRETE:8)
Block(-5,7,4,CONCRETE:8)
Block(-5,7,5,CONCRETE:8)
Block(-5,7,6,CONCRETE:8)
Block(-5,7,7,CONCRETE:8)
Block(-5,7,8,CONCRETE:8)
Block(-5,7,9,CONCRETE:8)
Block(-5,7,10,CONCRETE:8)
Block(-5,8,-11,CONCRETE)
Block(-5,8,-10,CONCRETE)
Block(-5,8,-9,CONCRETE)
Block(-5,8,-8,CONCRETE)
Block(-5,8,-7,CONCRETE)
Block(-5,8,-6,CONCRETE)
Block(-5,8,-5,CONCRETE)
Block(-5,8,-4,CONCRETE)
Block(-5,8,-3,CONCRETE)
Block(-5,8,-2,CONCRETE)
Block(-5,8,-1,CONCRETE)
Block(-5,8,0,CONCRETE)
Block(-5,8,1,CONCRETE)
Block(-5,8,2,CONCRETE)
Block(-5,8,3,CONCRETE)
Block(-5,8,4,CONCRETE)
Block(-5,8,5,CONCRETE)
Block(-5,8,6,CONCRETE)
Block(-5,8,7,CONCRETE)
Block(-5,8,8,CONCRETE)
Block(-5,8,9,CONCRETE)
Block(-5,8,10,CONCRETE)
Block(-5,8,11,CONCRETE)
Block(-5,9,-12,CONCRETE)
Block(-5,9,-11,CONCRETE)
Block(-5,9,-10,CONCRETE)
Block(-5,9,-9,CONCRETE)
Block(-5,9,-8,CONCRETE)
Block(-5,9,-7,CONCRETE)
Block(-5,9,-6,CONCRETE)
Block(-5,9,-5,CONCRETE)
Block(-5,9,-4,CONCRETE)
Block(-5,9,-3,CONCRETE)
Block(-5,9,-2,CONCRETE)
Block(-5,9,-1,CONCRETE)
Block(-5,9,0,CONCRETE)
Block(-5,9,1,CONCRETE)
Block(-5,9,2,CONCRETE)
Block(-5,9,3,CONCRETE)
Block(-5,9,4,CONCRETE)
Block(-5,9,5,CONCRETE)
Block(-5,9,6,CONCRETE)
Block(-5,9,7,CONCRETE)
Block(-5,9,8,CONCRETE)
Block(-5,9,9,CONCRETE)
Block(-5,9,10,CONCRETE)
Block(-5,9,11,CONCRETE)
Block(-5,10,-12,CONCRETE:15)
Block(-5,10,-11,CONCRETE:15)
Block(-5,10,-10,CONCRETE:15)
Block(-5,10,-9,CONCRETE:15)
Block(-5,10,-8,CONCRETE:15)
Block(-5,10,-7,CONCRETE:15)
Block(-5,10,-6,CONCRETE:15)
Block(-5,10,-5,CONCRETE:15)
Block(-5,10,-4,CONCRETE:15)
Block(-5,10,-3,CONCRETE:15)
Block(-5,10,-2,CONCRETE:15)
Block(-5,10,-1,CONCRETE:15)
Block(-5,10,0,CONCRETE:15)
Block(-5,10,1,CONCRETE:15)
Block(-5,10,2,CONCRETE:15)
Block(-5,10,3,CONCRETE:15)
Block(-5,10,4,CONCRETE:15)
Block(-5,10,5,CONCRETE:15)
Block(-5,10,6,CONCRETE:15)
Block(-5,10,7,CONCRETE:15)
Block(-5,10,8,CONCRETE:15)
Block(-5,10,9,CONCRETE:15)
Block(-5,10,10,CONCRETE:15)
Block(-5,10,11,CONCRETE:15)
Block(-5,11,-13,CONCRETE:4)
Block(-5,11,-12,CONCRETE:4)
Block(-5,11,-11,CONCRETE:4)
Block(-5,11,-10,CONCRETE:4)
Block(-5,11,-9,CONCRETE:4)
Block(-5,11,-8,CONCRETE:4)
Block(-5,11,-7,CONCRETE:4)
Block(-5,11,-6,CONCRETE:4)
Block(-5,11,-5,CONCRETE:4)
Block(-5,11,-4,CONCRETE:4)
Block(-5,11,-3,CONCRETE:4)
Block(-5,11,-2,CONCRETE:4)
Block(-5,11,-1,CONCRETE:4)
Block(-5,11,0,CONCRETE:4)
Block(-5,11,1,CONCRETE:4)
Block(-5,11,2,CONCRETE:4)
Block(-5,11,3,CONCRETE:4)
Block(-5,11,4,CONCRETE:4)
Block(-5,11,5,CONCRETE:4)
Block(-5,11,6,CONCRETE:4)
Block(-5,11,7,CONCRETE:4)
Block(-5,11,8,CONCRETE:4)
Block(-5,11,9,CONCRETE:4)
Block(-5,11,10,CONCRETE:4)
Block(-5,11,11,CONCRETE:4)
Block(-5,12,-13,CONCRETE:1)
Block(-5,12,-12,CONCRETE:1)
Block(-5,12,-11,CONCRETE:1)
Block(-5,12,-10,CONCRETE:1)
Block(-5,12,-9,CONCRETE:1)
Block(-5,12,-8,CONCRETE:1)
Block(-5,12,-7,CONCRETE:1)
Block(-5,12,-6,CONCRETE:1)
Block(-5,12,-5,CONCRETE:1)
Block(-5,12,-4,CONCRETE:1)
Block(-5,12,-3,CONCRETE:1)
Block(-5,12,-2,CONCRETE:1)
Block(-5,12,-1,CONCRETE:1)
Block(-5,12,0,CONCRETE:1)
Block(-5,12,1,CONCRETE:1)
Block(-5,12,2,CONCRETE:1)
Block(-5,12,3,CONCRETE:1)
Block(-5,12,4,CONCRETE:1)
Block(-5,12,5,CONCRETE:1)
Block(-5,12,6,CONCRETE:1)
Block(-5,12,7,CONCRETE:1)
Block(-5,12,8,CONCRETE:1)
Block(-5,12,9,CONCRETE:1)
Block(-5,12,10,CONCRETE:1)
Block(-5,12,11,CONCRETE:1)
Block(-5,13,-14,CONCRETE:14)
Block(-5,13,-13,CONCRETE:14)
Block(-5,13,-12,CONCRETE:14)
Block(-5,13,-11,CONCRETE:14)
Block(-5,13,-10,CONCRETE:14)
Block(-5,13,-9,CONCRETE:14)
Block(-5,13,-8,CONCRETE:14)
Block(-5,13,-7,CONCRETE:14)
Block(-5,13,-6,CONCRETE:14)
Block(-5,13,-5,CONCRETE:14)
Block(-5,13,-4,CONCRETE:14)
Block(-5,13,-3,CONCRETE:14)
Block(-5,13,-2,CONCRETE:14)
Block(-5,13,-1,CONCRETE:14)
Block(-5,13,0,CONCRETE:14)
Block(-5,13,1,CONCRETE:14)
Block(-5,13,2,CONCRETE:14)
Block(-5,13,3,CONCRETE:14)
Block(-5,13,4,CONCRETE:14)
Block(-5,13,5,CONCRETE:14)
Block(-5,13,6,CONCRETE:14)
Block(-5,13,7,CONCRETE:14)
Block(-5,13,8,CONCRETE:14)
Block(-5,13,9,CONCRETE:14)
Block(-5,13,10,CONCRETE:14)
Block(-5,13,11,CONCRETE:14)
Block(-5,13,12,CONCRETE:14)
Block(-5,14,-14,CONCRETE)
Block(-5,14,-13,CONCRETE)
Block(-5,14,-12,CONCRETE)
Block(-5,14,-11,CONCRETE)
Block(-5,14,-10,CONCRETE)
Block(-5,14,-9,CONCRETE)
Block(-5,14,-8,CONCRETE)
Block(-5,14,-7,CONCRETE)
Block(-5,14,-6,CONCRETE)
Block(-5,14,-5,CONCRETE)
Block(-5,14,-4,CONCRETE)
Block(-5,14,-3,CONCRETE)
Block(-5,14,-2,CONCRETE)
Block(-5,14,-1,CONCRETE)
Block(-5,14,0,CONCRETE)
Block(-5,14,1,CONCRETE)
Block(-5,14,2,CONCRETE)
Block(-5,14,3,CONCRETE)
Block(-5,14,4,CONCRETE)
Block(-5,14,5,CONCRETE)
Block(-5,14,6,CONCRETE)
Block(-5,14,7,CONCRETE)
Block(-5,14,8,CONCRETE)
Block(-5,14,9,CONCRETE)
Block(-5,14,10,CONCRETE)
Block(-5,14,11,CONCRETE)
Block(-5,14,12,CONCRETE)
Block(-5,15,-14,CONCRETE)
Block(-5,15,-13,CONCRETE)
Block(-5,15,-12,CONCRETE)
Block(-5,15,-11,CONCRETE)
Block(-5,15,-10,CONCRETE)
Block(-5,15,-9,CONCRETE)
Block(-5,15,-8,CONCRETE)
Block(-5,15,-7,CONCRETE)
Block(-5,15,-6,CONCRETE)
Block(-5,15,-5,CONCRETE)
Block(-5,15,-4,CONCRETE)
Block(-5,15,-3,CONCRETE)
Block(-5,15,-2,CONCRETE)
Block(-5,15,-1,CONCRETE)
Block(-5,15,0,CONCRETE)
Block(-5,15,1,CONCRETE)
Block(-5,15,2,CONCRETE)
Block(-5,15,3,CONCRETE)
Block(-5,15,4,CONCRETE)
Block(-5,15,5,CONCRETE)
Block(-5,15,6,CONCRETE)
Block(-5,15,7,CONCRETE)
Block(-5,15,8,CONCRETE)
Block(-5,15,9,CONCRETE)
Block(-5,15,10,CONCRETE)
Block(-5,15,11,CONCRETE)
Block(-5,16,-14,CONCRETE:12)
Block(-5,16,-13,CONCRETE:12)
Block(-5,16,-12,CONCRETE:12)
Block(-5,16,-11,CONCRETE:12)
Block(-5,16,-10,CONCRETE:12)
Block(-5,16,-9,CONCRETE:12)
Block(-5,16,-8,CONCRETE:12)
Block(-5,16,-7,CONCRETE:12)
Block(-5,16,-6,CONCRETE:12)
Block(-5,16,-5,CONCRETE:12)
Block(-5,16,-4,CONCRETE:12)
Block(-5,16,-3,CONCRETE:12)
Block(-5,16,-2,CONCRETE:12)
Block(-5,16,-1,CONCRETE:12)
Block(-5,16,0,CONCRETE:12)
Block(-5,16,1,CONCRETE:12)
Block(-5,16,2,CONCRETE:12)
Block(-5,16,3,CONCRETE:12)
Block(-5,16,4,CONCRETE:12)
Block(-5,16,5,CONCRETE:12)
Block(-5,16,6,CONCRETE:12)
Block(-5,16,7,CONCRETE:12)
Block(-5,16,8,CONCRETE:12)
Block(-5,16,9,CONCRETE:12)
Block(-5,16,10,CONCRETE:12)
Block(-5,16,11,CONCRETE:12)
Block(-5,17,-14,CONCRETE:15)
Block(-5,17,-13,CONCRETE:15)
Block(-5,17,-12,CONCRETE:15)
Block(-5,17,-11,CONCRETE:15)
Block(-5,17,-10,CONCRETE:15)
Block(-5,17,-9,CONCRETE:15)
Block(-5,17,-8,CONCRETE:15)
Block(-5,17,-7,CONCRETE:15)
Block(-5,17,-6,CONCRETE:15)
Block(-5,17,-5,CONCRETE:15)
Block(-5,17,-4,CONCRETE:15)
Block(-5,17,-3,CONCRETE:15)
Block(-5,17,-2,CONCRETE:15)
Block(-5,17,-1,CONCRETE:15)
Block(-5,17,0,CONCRETE:15)
Block(-5,17,1,CONCRETE:15)
Block(-5,17,2,CONCRETE:15)
Block(-5,17,3,CONCRETE:15)
Block(-5,17,4,CONCRETE:15)
Block(-5,17,5,CONCRETE:15)
Block(-5,17,6,CONCRETE:15)
Block(-5,17,7,CONCRETE:15)
Block(-5,17,8,CONCRETE:15)
Block(-5,17,9,CONCRETE:15)
Block(-5,17,10,CONCRETE:15)
Block(-5,17,11,CONCRETE:15)
Block(-5,18,-14,CONCRETE:12)
Block(-5,18,-13,CONCRETE:12)
Block(-5,18,-12,CONCRETE:12)
Block(-5,18,-11,CONCRETE:12)
Block(-5,18,-10,CONCRETE:12)
Block(-5,18,-9,CONCRETE:12)
Block(-5,18,-8,CONCRETE:12)
Block(-5,18,-7,CONCRETE:12)
Block(-5,18,-6,CONCRETE:12)
Block(-5,18,-5,CONCRETE:12)
Block(-5,18,-4,CONCRETE:12)
Block(-5,18,-3,CONCRETE:12)
Block(-5,18,-2,CONCRETE:12)
Block(-5,18,-1,CONCRETE:12)
Block(-5,18,0,CONCRETE:12)
Block(-5,18,1,CONCRETE:12)
Block(-5,18,2,CONCRETE:12)
Block(-5,18,3,CONCRETE:12)
Block(-5,18,4,CONCRETE:12)
Block(-5,18,5,CONCRETE:12)
Block(-5,18,6,CONCRETE:12)
Block(-5,18,7,CONCRETE:12)
Block(-5,18,8,CONCRETE:12)
Block(-5,18,9,CONCRETE:12)
Block(-5,18,10,CONCRETE:12)
Block(-5,18,11,CONCRETE:12)
Block(-5,19,-13,CONCRETE:1)
Block(-5,19,-12,CONCRETE:1)
Block(-5,19,-11,CONCRETE:1)
Block(-5,19,-10,CONCRETE:1)
Block(-5,19,-9,CONCRETE:1)
Block(-5,19,-8,CONCRETE:1)
Block(-5,19,-7,CONCRETE:1)
Block(-5,19,-6,CONCRETE:1)
Block(-5,19,-5,CONCRETE:1)
Block(-5,19,-4,CONCRETE:1)
Block(-5,19,-3,CONCRETE:1)
Block(-5,19,-2,CONCRETE:1)
Block(-5,19,-1,CONCRETE:1)
Block(-5,19,0,CONCRETE:1)
Block(-5,19,1,CONCRETE:1)
Block(-5,19,2,CONCRETE:1)
Block(-5,19,3,CONCRETE:1)
Block(-5,19,4,CONCRETE:1)
Block(-5,19,5,CONCRETE:1)
Block(-5,19,6,CONCRETE:1)
Block(-5,19,7,CONCRETE:1)
Block(-5,19,8,CONCRETE:1)
Block(-5,19,9,CONCRETE:1)
Block(-5,19,10,CONCRETE:1)
Block(-5,20,-13,CONCRETE:1)
Block(-5,20,-12,CONCRETE:1)
Block(-5,20,-11,CONCRETE:1)
Block(-5,20,-10,CONCRETE:1)
Block(-5,20,-9,CONCRETE:1)
Block(-5,20,-8,CONCRETE:1)
Block(-5,20,-7,CONCRETE:1)
Block(-5,20,-6,CONCRETE:1)
Block(-5,20,-5,CONCRETE:1)
Block(-5,20,-4,CONCRETE:1)
Block(-5,20,-3,CONCRETE:1)
Block(-5,20,-2,CONCRETE:1)
Block(-5,20,-1,CONCRETE:1)
Block(-5,20,0,CONCRETE:1)
Block(-5,20,1,CONCRETE:1)
Block(-5,20,2,CONCRETE:1)
Block(-5,20,3,CONCRETE:1)
Block(-5,20,4,CONCRETE:1)
Block(-5,20,5,CONCRETE:1)
Block(-5,20,6,CONCRETE:1)
Block(-5,20,7,CONCRETE:1)
Block(-5,20,8,CONCRETE:1)
Block(-5,20,9,CONCRETE:1)
Block(-5,20,10,CONCRETE:1)
Block(-5,21,-13,CONCRETE:1)
Block(-5,21,-12,CONCRETE:1)
Block(-5,21,-11,CONCRETE:1)
Block(-5,21,-10,CONCRETE:1)
Block(-5,21,-9,CONCRETE:1)
Block(-5,21,-8,CONCRETE:1)
Block(-5,21,-7,CONCRETE:1)
Block(-5,21,-6,CONCRETE:1)
Block(-5,21,-5,CONCRETE:1)
Block(-5,21,-4,CONCRETE:1)
Block(-5,21,-3,CONCRETE:1)
Block(-5,21,-2,CONCRETE:1)
Block(-5,21,-1,CONCRETE:1)
Block(-5,21,0,CONCRETE:1)
Block(-5,21,1,CONCRETE:1)
Block(-5,21,2,CONCRETE:1)
Block(-5,21,3,CONCRETE:1)
Block(-5,21,4,CONCRETE:1)
Block(-5,21,5,CONCRETE:1)
Block(-5,21,6,CONCRETE:1)
Block(-5,21,7,CONCRETE:1)
Block(-5,21,8,CONCRETE:1)
Block(-5,21,9,CONCRETE:1)
Block(-5,22,-13,CONCRETE:14)
Block(-5,22,-12,CONCRETE:14)
Block(-5,22,-11,CONCRETE:14)
Block(-5,22,-10,CONCRETE:14)
Block(-5,22,-9,CONCRETE:14)
Block(-5,22,-8,CONCRETE:14)
Block(-5,22,-7,CONCRETE:14)
Block(-5,22,-6,CONCRETE:14)
Block(-5,22,-5,CONCRETE:14)
Block(-5,22,-4,CONCRETE:14)
Block(-5,22,-3,CONCRETE:14)
Block(-5,22,-2,CONCRETE:14)
Block(-5,22,-1,CONCRETE:14)
Block(-5,22,0,CONCRETE:14)
Block(-5,22,1,CONCRETE:14)
Block(-5,22,2,CONCRETE:14)
Block(-5,22,3,CONCRETE:14)
Block(-5,22,4,CONCRETE:14)
Block(-5,22,5,CONCRETE:14)
Block(-5,22,6,CONCRETE:14)
Block(-5,22,7,CONCRETE:14)
Block(-5,22,8,CONCRETE:14)
Block(-5,22,9,CONCRETE:14)
Block(-5,23,-12,CONCRETE)
Block(-5,23,-11,CONCRETE)
Block(-5,23,-10,CONCRETE)
Block(-5,23,-9,CONCRETE)
Block(-5,23,-8,CONCRETE)
Block(-5,23,-7,CONCRETE)
Block(-5,23,-6,CONCRETE)
Block(-5,23,-5,CONCRETE)
Block(-5,23,-4,CONCRETE)
Block(-5,23,-3,CONCRETE)
Block(-5,23,-2,CONCRETE)
Block(-5,23,-1,CONCRETE)
Block(-5,23,0,CONCRETE)
Block(-5,23,1,CONCRETE)
Block(-5,23,2,CONCRETE)
Block(-5,23,3,CONCRETE)
Block(-5,23,4,CONCRETE)
Block(-5,23,5,CONCRETE)
Block(-5,23,6,CONCRETE)
Block(-5,23,7,CONCRETE)
Block(-5,23,8,CONCRETE)
Block(-5,24,-11,CONCRETE:4)
Block(-5,24,-10,CONCRETE:4)
Block(-5,24,-9,CONCRETE:4)
Block(-5,24,-8,CONCRETE:4)
Block(-5,24,-7,CONCRETE:4)
Block(-5,24,-6,CONCRETE:4)
Block(-5,24,-5,CONCRETE:4)
Block(-5,24,-4,CONCRETE:4)
Block(-5,24,-3,CONCRETE:4)
Block(-5,24,-2,CONCRETE:4)
Block(-5,24,-1,CONCRETE:4)
Block(-5,24,0,CONCRETE:4)
Block(-5,24,1,CONCRETE:4)
Block(-5,24,2,CONCRETE:4)
Block(-5,24,3,CONCRETE:4)
Block(-5,24,4,CONCRETE:4)
Block(-5,24,5,CONCRETE:4)
Block(-5,24,6,CONCRETE:4)
Block(-5,24,7,CONCRETE:4)
Block(-5,24,8,CONCRETE:4)
Block(-5,25,-10,CONCRETE:12)
Block(-5,25,-9,CONCRETE:12)
Block(-5,25,-8,CONCRETE:12)
Block(-5,25,-7,CONCRETE:12)
Block(-5,25,-6,CONCRETE:12)
Block(-5,25,-5,CONCRETE:12)
Block(-5,25,-4,CONCRETE:12)
Block(-5,25,-3,CONCRETE:12)
Block(-5,25,-2,CONCRETE:12)
Block(-5,25,-1,CONCRETE:12)
Block(-5,25,0,CONCRETE:12)
Block(-5,25,1,CONCRETE:12)
Block(-5,25,2,CONCRETE:12)
Block(-5,25,3,CONCRETE:12)
Block(-5,25,4,CONCRETE:12)
Block(-5,25,5,CONCRETE:12)
Block(-5,25,6,CONCRETE:12)
Block(-5,25,7,CONCRETE:12)
Block(-5,26,-9,CONCRETE:12)
Block(-5,26,-8,CONCRETE:12)
Block(-5,26,-7,CONCRETE:12)
Block(-5,26,-6,CONCRETE:12)
Block(-5,26,-5,CONCRETE:12)
Block(-5,26,-4,CONCRETE:12)
Block(-5,26,-3,CONCRETE:12)
Block(-5,26,-2,CONCRETE:12)
Block(-5,26,-1,CONCRETE:12)
Block(-5,26,0,CONCRETE:12)
Block(-5,26,1,CONCRETE:12)
Block(-5,26,2,CONCRETE:12)
Block(-5,26,3,CONCRETE:12)
Block(-5,26,4,CONCRETE:12)
Block(-5,26,5,CONCRETE:12)
Block(-5,27,-8,CONCRETE)
Block(-5,27,-7,CONCRETE)
Block(-5,27,-6,CONCRETE)
Block(-5,27,-5,CONCRETE)
Block(-5,27,-4,CONCRETE)
Block(-5,27,-3,CONCRETE)
Block(-5,27,-2,CONCRETE)
Block(-5,27,-1,CONCRETE)
Block(-5,27,0,CONCRETE)
Block(-5,27,1,CONCRETE)
Block(-5,27,2,CONCRETE)
Block(-5,27,3,CONCRETE)
Block(-5,27,4,CONCRETE)
Block(-5,28,-5,CONCRETE:14)
Block(-5,28,-4,CONCRETE:14)
Block(-5,28,-3,CONCRETE:14)
Block(-5,28,-2,CONCRETE:14)
Block(-5,28,-1,CONCRETE:14)
Block(-5,28,0,CONCRETE:14)
Block(-5,28,1,CONCRETE:14)
Block(-5,28,2,CONCRETE:14)
Block(-5,29,-2,CONCRETE:14)
Block(-4,1,-3,CONCRETE)
Block(-4,1,-2,CONCRETE)
Block(-4,1,-1,CONCRETE)
Block(-4,1,0,CONCRETE)
Block(-4,1,1,CONCRETE)
Block(-4,1,2,CONCRETE)
Block(-4,1,3,CONCRETE)
Block(-4,2,-4,CONCRETE:1)
Block(-4,2,-3,CONCRETE:1)
Block(-4,2,-2,CONCRETE:1)
Block(-4,2,-1,CONCRETE:1)
Block(-4,2,0,CONCRETE:1)
Block(-4,2,1,CONCRETE:1)
Block(-4,2,2,CONCRETE:1)
Block(-4,2,3,CONCRETE:1)
Block(-4,2,4,CONCRETE:1)
Block(-4,2,5,CONCRETE:1)
Block(-4,3,-6,CONCRETE:1)
Block(-4,3,-5,CONCRETE:1)
Block(-4,3,-4,CONCRETE:1)
Block(-4,3,-3,CONCRETE:1)
Block(-4,3,-2,CONCRETE:1)
Block(-4,3,-1,CONCRETE:1)
Block(-4,3,0,CONCRETE:1)
Block(-4,3,1,CONCRETE:1)
Block(-4,3,2,CONCRETE:1)
Block(-4,3,3,CONCRETE:1)
Block(-4,3,4,CONCRETE:1)
Block(-4,3,5,CONCRETE:1)
Block(-4,3,6,CONCRETE:1)
Block(-4,3,7,CONCRETE:1)
Block(-4,4,-8,CONCRETE:14)
Block(-4,4,-7,CONCRETE:14)
Block(-4,4,-6,CONCRETE:14)
Block(-4,4,-5,CONCRETE:14)
Block(-4,4,-4,CONCRETE:14)
Block(-4,4,-3,CONCRETE:14)
Block(-4,4,-2,CONCRETE:14)
Block(-4,4,-1,CONCRETE:14)
Block(-4,4,0,CONCRETE:14)
Block(-4,4,1,CONCRETE:14)
Block(-4,4,2,CONCRETE:14)
Block(-4,4,3,CONCRETE:14)
Block(-4,4,4,CONCRETE:14)
Block(-4,4,5,CONCRETE:14)
Block(-4,4,6,CONCRETE:14)
Block(-4,4,7,CONCRETE:14)
Block(-4,4,8,CONCRETE:14)
Block(-4,5,-10,CONCRETE)
Block(-4,5,-9,CONCRETE)
Block(-4,5,-8,CONCRETE)
Block(-4,5,-7,CONCRETE)
Block(-4,5,-6,CONCRETE)
Block(-4,5,-5,CONCRETE)
Block(-4,5,-4,CONCRETE)
Block(-4,5,-3,CONCRETE)
Block(-4,5,-2,CONCRETE)
Block(-4,5,-1,CONCRETE)
Block(-4,5,0,CONCRETE)
Block(-4,5,1,CONCRETE)
Block(-4,5,2,CONCRETE)
Block(-4,5,3,CONCRETE)
Block(-4,5,4,CONCRETE)
Block(-4,5,5,CONCRETE)
Block(-4,5,6,CONCRETE)
Block(-4,5,7,CONCRETE)
Block(-4,5,8,CONCRETE)
Block(-4,5,9,CONCRETE)
Block(-4,6,-10,CONCRETE)
Block(-4,6,-9,CONCRETE)
Block(-4,6,-8,CONCRETE)
Block(-4,6,-7,CONCRETE)
Block(-4,6,-6,CONCRETE)
Block(-4,6,-5,CONCRETE)
Block(-4,6,-4,CONCRETE)
Block(-4,6,-3,CONCRETE)
Block(-4,6,-2,CONCRETE)
Block(-4,6,-1,CONCRETE)
Block(-4,6,0,CONCRETE)
Block(-4,6,1,CONCRETE)
Block(-4,6,2,CONCRETE)
Block(-4,6,3,CONCRETE)
Block(-4,6,4,CONCRETE)
Block(-4,6,5,CONCRETE)
Block(-4,6,6,CONCRETE)
Block(-4,6,7,CONCRETE)
Block(-4,6,8,CONCRETE)
Block(-4,6,9,CONCRETE)
Block(-4,6,10,CONCRETE)
Block(-4,7,-11,CONCRETE:8)
Block(-4,7,-10,CONCRETE:8)
Block(-4,7,-9,CONCRETE:8)
Block(-4,7,-8,CONCRETE:8)
Block(-4,7,-7,CONCRETE:8)
Block(-4,7,-6,CONCRETE:8)
Block(-4,7,-5,CONCRETE:8)
Block(-4,7,-4,CONCRETE:8)
Block(-4,7,-3,CONCRETE:8)
Block(-4,7,-2,CONCRETE:8)
Block(-4,7,-1,CONCRETE:8)
Block(-4,7,0,CONCRETE:8)
Block(-4,7,1,CONCRETE:8)
Block(-4,7,2,CONCRETE:8)
Block(-4,7,3,CONCRETE:8)
Block(-4,7,4,CONCRETE:8)
Block(-4,7,5,CONCRETE:8)
Block(-4,7,6,CONCRETE:8)
Block(-4,7,7,CONCRETE:8)
Block(-4,7,8,CONCRETE:8)
Block(-4,7,9,CONCRETE:8)
Block(-4,7,10,CONCRETE:8)
Block(-4,7,11,CONCRETE:8)
Block(-4,8,-12,CONCRETE)
Block(-4,8,-11,CONCRETE)
Block(-4,8,-10,CONCRETE)
Block(-4,8,-9,CONCRETE)
Block(-4,8,-8,CONCRETE)
Block(-4,8,-7,CONCRETE)
Block(-4,8,-6,CONCRETE)
Block(-4,8,-5,CONCRETE)
Block(-4,8,-4,CONCRETE)
Block(-4,8,-3,CONCRETE)
Block(-4,8,-2,CONCRETE)
Block(-4,8,-1,CONCRETE)
Block(-4,8,0,CONCRETE)
Block(-4,8,1,CONCRETE)
Block(-4,8,2,CONCRETE)
Block(-4,8,3,CONCRETE)
Block(-4,8,4,CONCRETE)
Block(-4,8,5,CONCRETE)
Block(-4,8,6,CONCRETE)
Block(-4,8,7,CONCRETE)
Block(-4,8,8,CONCRETE)
Block(-4,8,9,CONCRETE)
Block(-4,8,10,CONCRETE)
Block(-4,8,11,CONCRETE)
Block(-4,9,-12,CONCRETE)
Block(-4,9,-11,CONCRETE)
Block(-4,9,-10,CONCRETE)
Block(-4,9,-9,CONCRETE)
Block(-4,9,-8,CONCRETE)
Block(-4,9,-7,CONCRETE)
Block(-4,9,-6,CONCRETE)
Block(-4,9,-5,CONCRETE)
Block(-4,9,-4,CONCRETE)
Block(-4,9,-3,CONCRETE)
Block(-4,9,-2,CONCRETE)
Block(-4,9,-1,CONCRETE)
Block(-4,9,0,CONCRETE)
Block(-4,9,1,CONCRETE)
Block(-4,9,2,CONCRETE)
Block(-4,9,3,CONCRETE)
Block(-4,9,4,CONCRETE)
Block(-4,9,5,CONCRETE)
Block(-4,9,6,CONCRETE)
Block(-4,9,7,CONCRETE)
Block(-4,9,8,CONCRETE)
Block(-4,9,9,CONCRETE)
Block(-4,9,10,CONCRETE)
Block(-4,9,11,CONCRETE)
Block(-4,10,-13,CONCRETE:15)
Block(-4,10,-12,CONCRETE:15)
Block(-4,10,-11,CONCRETE:15)
Block(-4,10,-10,CONCRETE:15)
Block(-4,10,-9,CONCRETE:15)
Block(-4,10,-8,CONCRETE:15)
Block(-4,10,-7,CONCRETE:15)
Block(-4,10,-6,CONCRETE:15)
Block(-4,10,-5,CONCRETE:15)
Block(-4,10,-4,CONCRETE:15)
Block(-4,10,-3,CONCRETE:15)
Block(-4,10,-2,CONCRETE:15)
Block(-4,10,-1,CONCRETE:15)
Block(-4,10,0,CONCRETE:15)
Block(-4,10,1,CONCRETE:15)
Block(-4,10,2,CONCRETE:15)
Block(-4,10,3,CONCRETE:15)
Block(-4,10,4,CONCRETE:15)
Block(-4,10,5,CONCRETE:15)
Block(-4,10,6,CONCRETE:15)
Block(-4,10,7,CONCRETE:15)
Block(-4,10,8,CONCRETE:15)
Block(-4,10,9,CONCRETE:15)
Block(-4,10,10,CONCRETE:15)
Block(-4,10,11,CONCRETE:15)
Block(-4,10,12,CONCRETE:15)
Block(-4,11,-13,CONCRETE:4)
Block(-4,11,-12,CONCRETE:4)
Block(-4,11,-11,CONCRETE:4)
Block(-4,11,-10,CONCRETE:4)
Block(-4,11,-9,CONCRETE:4)
Block(-4,11,-8,CONCRETE:4)
Block(-4,11,-7,CONCRETE:4)
Block(-4,11,-6,CONCRETE:4)
Block(-4,11,-5,CONCRETE:4)
Block(-4,11,-4,CONCRETE:4)
Block(-4,11,-3,CONCRETE:4)
Block(-4,11,-2,CONCRETE:4)
Block(-4,11,-1,CONCRETE:4)
Block(-4,11,0,CONCRETE:4)
Block(-4,11,1,CONCRETE:4)
Block(-4,11,2,CONCRETE:4)
Block(-4,11,3,CONCRETE:4)
Block(-4,11,4,CONCRETE:4)
Block(-4,11,5,CONCRETE:4)
Block(-4,11,6,CONCRETE:4)
Block(-4,11,7,CONCRETE:4)
Block(-4,11,8,CONCRETE:4)
Block(-4,11,9,CONCRETE:4)
Block(-4,11,10,CONCRETE:4)
Block(-4,11,11,CONCRETE:4)
Block(-4,11,12,CONCRETE:4)
Block(-4,12,-13,CONCRETE:1)
Block(-4,12,-12,CONCRETE:1)
Block(-4,12,-11,CONCRETE:1)
Block(-4,12,-10,CONCRETE:1)
Block(-4,12,-9,CONCRETE:1)
Block(-4,12,-8,CONCRETE:1)
Block(-4,12,-7,CONCRETE:1)
Block(-4,12,-6,CONCRETE:1)
Block(-4,12,-5,CONCRETE:1)
Block(-4,12,-4,CONCRETE:1)
Block(-4,12,-3,CONCRETE:1)
Block(-4,12,-2,CONCRETE:1)
Block(-4,12,-1,CONCRETE:1)
Block(-4,12,0,CONCRETE:1)
Block(-4,12,1,CONCRETE:1)
Block(-4,12,2,CONCRETE:1)
Block(-4,12,3,CONCRETE:1)
Block(-4,12,4,CONCRETE:1)
Block(-4,12,5,CONCRETE:1)
Block(-4,12,6,CONCRETE:1)
Block(-4,12,7,CONCRETE:1)
Block(-4,12,8,CONCRETE:1)
Block(-4,12,9,CONCRETE:1)
Block(-4,12,10,CONCRETE:1)
Block(-4,12,11,CONCRETE:1)
Block(-4,12,12,CONCRETE:1)
Block(-4,13,-14,CONCRETE:14)
Block(-4,13,-13,CONCRETE:14)
Block(-4,13,-12,CONCRETE:14)
Block(-4,13,-11,CONCRETE:14)
Block(-4,13,-10,CONCRETE:14)
Block(-4,13,-9,CONCRETE:14)
Block(-4,13,-8,CONCRETE:14)
Block(-4,13,-7,CONCRETE:14)
Block(-4,13,-6,CONCRETE:14)
Block(-4,13,-5,CONCRETE:14)
Block(-4,13,-4,CONCRETE:14)
Block(-4,13,-3,CONCRETE:14)
Block(-4,13,-2,CONCRETE:14)
Block(-4,13,-1,CONCRETE:14)
Block(-4,13,0,CONCRETE:14)
Block(-4,13,1,CONCRETE:14)
Block(-4,13,2,CONCRETE:14)
Block(-4,13,3,CONCRETE:14)
Block(-4,13,4,CONCRETE:14)
Block(-4,13,5,CONCRETE:14)
Block(-4,13,6,CONCRETE:14)
Block(-4,13,7,CONCRETE:14)
Block(-4,13,8,CONCRETE:14)
Block(-4,13,9,CONCRETE:14)
Block(-4,13,10,CONCRETE:14)
Block(-4,13,11,CONCRETE:14)
Block(-4,13,12,CONCRETE:14)
Block(-4,14,-14,CONCRETE)
Block(-4,14,-13,CONCRETE)
Block(-4,14,-12,CONCRETE)
Block(-4,14,-11,CONCRETE)
Block(-4,14,-10,CONCRETE)
Block(-4,14,-9,CONCRETE)
Block(-4,14,-8,CONCRETE)
Block(-4,14,-7,CONCRETE)
Block(-4,14,-6,CONCRETE)
Block(-4,14,-5,CONCRETE)
Block(-4,14,-4,CONCRETE)
Block(-4,14,-3,CONCRETE)
Block(-4,14,-2,CONCRETE)
Block(-4,14,-1,CONCRETE)
Block(-4,14,0,CONCRETE)
Block(-4,14,1,CONCRETE)
Block(-4,14,2,CONCRETE)
Block(-4,14,3,CONCRETE)
Block(-4,14,4,CONCRETE)
Block(-4,14,5,CONCRETE)
Block(-4,14,6,CONCRETE)
Block(-4,14,7,CONCRETE)
Block(-4,14,8,CONCRETE)
Block(-4,14,9,CONCRETE)
Block(-4,14,10,CONCRETE)
Block(-4,14,11,CONCRETE)
Block(-4,14,12,CONCRETE)
Block(-4,15,-14,CONCRETE)
Block(-4,15,-13,CONCRETE)
Block(-4,15,-12,CONCRETE)
Block(-4,15,-11,CONCRETE)
Block(-4,15,-10,CONCRETE)
Block(-4,15,-9,CONCRETE)
Block(-4,15,-8,CONCRETE)
Block(-4,15,-7,CONCRETE)
Block(-4,15,-6,CONCRETE)
Block(-4,15,-5,CONCRETE)
Block(-4,15,-4,CONCRETE)
Block(-4,15,-3,CONCRETE)
Block(-4,15,-2,CONCRETE)
Block(-4,15,-1,CONCRETE)
Block(-4,15,0,CONCRETE)
Block(-4,15,1,CONCRETE)
Block(-4,15,2,CONCRETE)
Block(-4,15,3,CONCRETE)
Block(-4,15,4,CONCRETE)
Block(-4,15,5,CONCRETE)
Block(-4,15,6,CONCRETE)
Block(-4,15,7,CONCRETE)
Block(-4,15,8,CONCRETE)
Block(-4,15,9,CONCRETE)
Block(-4,15,10,CONCRETE)
Block(-4,15,11,CONCRETE)
Block(-4,15,12,CONCRETE)
Block(-4,16,-14,CONCRETE:12)
Block(-4,16,-13,CONCRETE:12)
Block(-4,16,-12,CONCRETE:12)
Block(-4,16,-11,CONCRETE:12)
Block(-4,16,-10,CONCRETE:12)
Block(-4,16,-9,CONCRETE:12)
Block(-4,16,-8,CONCRETE:12)
Block(-4,16,-7,CONCRETE:12)
Block(-4,16,-6,CONCRETE:12)
Block(-4,16,-5,CONCRETE:12)
Block(-4,16,-4,CONCRETE:12)
Block(-4,16,-3,CONCRETE:12)
Block(-4,16,-2,CONCRETE:12)
Block(-4,16,-1,CONCRETE:12)
Block(-4,16,0,CONCRETE:12)
Block(-4,16,1,CONCRETE:12)
Block(-4,16,2,CONCRETE:12)
Block(-4,16,3,CONCRETE:12)
Block(-4,16,4,CONCRETE:12)
Block(-4,16,5,CONCRETE:12)
Block(-4,16,6,CONCRETE:12)
Block(-4,16,7,CONCRETE:12)
Block(-4,16,8,CONCRETE:12)
Block(-4,16,9,CONCRETE:12)
Block(-4,16,10,CONCRETE:12)
Block(-4,16,11,CONCRETE:12)
Block(-4,16,12,CONCRETE:12)
Block(-4,17,-14,CONCRETE:15)
Block(-4,17,-13,CONCRETE:15)
Block(-4,17,-12,CONCRETE:15)
Block(-4,17,-11,CONCRETE:15)
Block(-4,17,-10,CONCRETE:15)
Block(-4,17,-9,CONCRETE:15)
Block(-4,17,-8,CONCRETE:15)
Block(-4,17,-7,CONCRETE:15)
Block(-4,17,-6,CONCRETE:15)
Block(-4,17,-5,CONCRETE:15)
Block(-4,17,-4,CONCRETE:15)
Block(-4,17,-3,CONCRETE:15)
Block(-4,17,-2,CONCRETE:15)
Block(-4,17,-1,CONCRETE:15)
Block(-4,17,0,CONCRETE:15)
Block(-4,17,1,CONCRETE:15)
Block(-4,17,2,CONCRETE:15)
Block(-4,17,3,CONCRETE:15)
Block(-4,17,4,CONCRETE:15)
Block(-4,17,5,CONCRETE:15)
Block(-4,17,6,CONCRETE:15)
Block(-4,17,7,CONCRETE:15)
Block(-4,17,8,CONCRETE:15)
Block(-4,17,9,CONCRETE:15)
Block(-4,17,10,CONCRETE:15)
Block(-4,17,11,CONCRETE:15)
Block(-4,18,-14,CONCRETE:12)
Block(-4,18,-13,CONCRETE:12)
Block(-4,18,-12,CONCRETE:12)
Block(-4,18,-11,CONCRETE:12)
Block(-4,18,-10,CONCRETE:12)
Block(-4,18,-9,CONCRETE:12)
Block(-4,18,-8,CONCRETE:12)
Block(-4,18,-7,CONCRETE:12)
Block(-4,18,-6,CONCRETE:12)
Block(-4,18,-5,CONCRETE:12)
Block(-4,18,-4,CONCRETE:12)
Block(-4,18,-3,CONCRETE:12)
Block(-4,18,-2,CONCRETE:12)
Block(-4,18,-1,CONCRETE:12)
Block(-4,18,0,CONCRETE:12)
Block(-4,18,1,CONCRETE:12)
Block(-4,18,2,CONCRETE:12)
Block(-4,18,3,CONCRETE:12)
Block(-4,18,4,CONCRETE:12)
Block(-4,18,5,CONCRETE:12)
Block(-4,18,6,CONCRETE:12)
Block(-4,18,7,CONCRETE:12)
Block(-4,18,8,CONCRETE:12)
Block(-4,18,9,CONCRETE:12)
Block(-4,18,10,CONCRETE:12)
Block(-4,18,11,CONCRETE:12)
Block(-4,19,-14,CONCRETE:1)
Block(-4,19,-13,CONCRETE:1)
Block(-4,19,-12,CONCRETE:1)
Block(-4,19,-11,CONCRETE:1)
Block(-4,19,-10,CONCRETE:1)
Block(-4,19,-9,CONCRETE:1)
Block(-4,19,-8,CONCRETE:1)
Block(-4,19,-7,CONCRETE:1)
Block(-4,19,-6,CONCRETE:1)
Block(-4,19,-5,CONCRETE:1)
Block(-4,19,-4,CONCRETE:1)
Block(-4,19,-3,CONCRETE:1)
Block(-4,19,-2,CONCRETE:1)
Block(-4,19,-1,CONCRETE:1)
Block(-4,19,0,CONCRETE:1)
Block(-4,19,1,CONCRETE:1)
Block(-4,19,2,CONCRETE:1)
Block(-4,19,3,CONCRETE:1)
Block(-4,19,4,CONCRETE:1)
Block(-4,19,5,CONCRETE:1)
Block(-4,19,6,CONCRETE:1)
Block(-4,19,7,CONCRETE:1)
Block(-4,19,8,CONCRETE:1)
Block(-4,19,9,CONCRETE:1)
Block(-4,19,10,CONCRETE:1)
Block(-4,20,-14,CONCRETE:1)
Block(-4,20,-13,CONCRETE:1)
Block(-4,20,-12,CONCRETE:1)
Block(-4,20,-11,CONCRETE:1)
Block(-4,20,-10,CONCRETE:1)
Block(-4,20,-9,CONCRETE:1)
Block(-4,20,-8,CONCRETE:1)
Block(-4,20,-7,CONCRETE:1)
Block(-4,20,-6,CONCRETE:1)
Block(-4,20,-5,CONCRETE:1)
Block(-4,20,-4,CONCRETE:1)
Block(-4,20,-3,CONCRETE:1)
Block(-4,20,-2,CONCRETE:1)
Block(-4,20,-1,CONCRETE:1)
Block(-4,20,0,CONCRETE:1)
Block(-4,20,1,CONCRETE:1)
Block(-4,20,2,CONCRETE:1)
Block(-4,20,3,CONCRETE:1)
Block(-4,20,4,CONCRETE:1)
Block(-4,20,5,CONCRETE:1)
Block(-4,20,6,CONCRETE:1)
Block(-4,20,7,CONCRETE:1)
Block(-4,20,8,CONCRETE:1)
Block(-4,20,9,CONCRETE:1)
Block(-4,20,10,CONCRETE:1)
Block(-4,21,-13,CONCRETE:1)
Block(-4,21,-12,CONCRETE:1)
Block(-4,21,-11,CONCRETE:1)
Block(-4,21,-10,CONCRETE:1)
Block(-4,21,-9,CONCRETE:1)
Block(-4,21,-8,CONCRETE:1)
Block(-4,21,-7,CONCRETE:1)
Block(-4,21,-6,CONCRETE:1)
Block(-4,21,-5,CONCRETE:1)
Block(-4,21,-4,CONCRETE:1)
Block(-4,21,-3,CONCRETE:1)
Block(-4,21,-2,CONCRETE:1)
Block(-4,21,-1,CONCRETE:1)
Block(-4,21,0,CONCRETE:1)
Block(-4,21,1,CONCRETE:1)
Block(-4,21,2,CONCRETE:1)
Block(-4,21,3,CONCRETE:1)
Block(-4,21,4,CONCRETE:1)
Block(-4,21,5,CONCRETE:1)
Block(-4,21,6,CONCRETE:1)
Block(-4,21,7,CONCRETE:1)
Block(-4,21,8,CONCRETE:1)
Block(-4,21,9,CONCRETE:1)
Block(-4,22,-13,CONCRETE:14)
Block(-4,22,-12,CONCRETE:14)
Block(-4,22,-11,CONCRETE:14)
Block(-4,22,-10,CONCRETE:14)
Block(-4,22,-9,CONCRETE:14)
Block(-4,22,-8,CONCRETE:14)
Block(-4,22,-7,CONCRETE:14)
Block(-4,22,-6,CONCRETE:14)
Block(-4,22,-5,CONCRETE:14)
Block(-4,22,-4,CONCRETE:14)
Block(-4,22,-3,CONCRETE:14)
Block(-4,22,-2,CONCRETE:14)
Block(-4,22,-1,CONCRETE:14)
Block(-4,22,0,CONCRETE:14)
Block(-4,22,1,CONCRETE:14)
Block(-4,22,2,CONCRETE:14)
Block(-4,22,3,CONCRETE:14)
Block(-4,22,4,CONCRETE:14)
Block(-4,22,5,CONCRETE:14)
Block(-4,22,6,CONCRETE:14)
Block(-4,22,7,CONCRETE:14)
Block(-4,22,8,CONCRETE:14)
Block(-4,22,9,CONCRETE:14)
Block(-4,23,-12,CONCRETE)
Block(-4,23,-11,CONCRETE)
Block(-4,23,-10,CONCRETE)
Block(-4,23,-9,CONCRETE)
Block(-4,23,-8,CONCRETE)
Block(-4,23,-7,CONCRETE)
Block(-4,23,-6,CONCRETE)
Block(-4,23,-5,CONCRETE)
Block(-4,23,-4,CONCRETE)
Block(-4,23,-3,CONCRETE)
Block(-4,23,-2,CONCRETE)
Block(-4,23,-1,CONCRETE)
Block(-4,23,0,CONCRETE)
Block(-4,23,1,CONCRETE)
Block(-4,23,2,CONCRETE)
Block(-4,23,3,CONCRETE)
Block(-4,23,4,CONCRETE)
Block(-4,23,5,CONCRETE)
Block(-4,23,6,CONCRETE)
Block(-4,23,7,CONCRETE)
Block(-4,23,8,CONCRETE)
Block(-4,24,-12,CONCRETE:4)
Block(-4,24,-11,CONCRETE:4)
Block(-4,24,-10,CONCRETE:4)
Block(-4,24,-9,CONCRETE:4)
Block(-4,24,-8,CONCRETE:4)
Block(-4,24,-7,CONCRETE:4)
Block(-4,24,-6,CONCRETE:4)
Block(-4,24,-5,CONCRETE:4)
Block(-4,24,-4,CONCRETE:4)
Block(-4,24,-3,CONCRETE:4)
Block(-4,24,-2,CONCRETE:4)
Block(-4,24,-1,CONCRETE:4)
Block(-4,24,0,CONCRETE:4)
Block(-4,24,1,CONCRETE:4)
Block(-4,24,2,CONCRETE:4)
Block(-4,24,3,CONCRETE:4)
Block(-4,24,4,CONCRETE:4)
Block(-4,24,5,CONCRETE:4)
Block(-4,24,6,CONCRETE:4)
Block(-4,24,7,CONCRETE:4)
Block(-4,24,8,CONCRETE:4)
Block(-4,25,-11,CONCRETE:12)
Block(-4,25,-10,CONCRETE:12)
Block(-4,25,-9,CONCRETE:12)
Block(-4,25,-8,CONCRETE:12)
Block(-4,25,-7,CONCRETE:12)
Block(-4,25,-6,CONCRETE:12)
Block(-4,25,-5,CONCRETE:12)
Block(-4,25,-4,CONCRETE:12)
Block(-4,25,-3,CONCRETE:12)
Block(-4,25,-2,CONCRETE:12)
Block(-4,25,-1,CONCRETE:12)
Block(-4,25,0,CONCRETE:12)
Block(-4,25,1,CONCRETE:12)
Block(-4,25,2,CONCRETE:12)
Block(-4,25,3,CONCRETE:12)
Block(-4,25,4,CONCRETE:12)
Block(-4,25,5,CONCRETE:12)
Block(-4,25,6,CONCRETE:12)
Block(-4,25,7,CONCRETE:12)
Block(-4,26,-10,CONCRETE:12)
Block(-4,26,-9,CONCRETE:12)
Block(-4,26,-8,CONCRETE:12)
Block(-4,26,-7,CONCRETE:12)
Block(-4,26,-6,CONCRETE:12)
Block(-4,26,-5,CONCRETE:12)
Block(-4,26,-4,CONCRETE:12)
Block(-4,26,-3,CONCRETE:12)
Block(-4,26,-2,CONCRETE:12)
Block(-4,26,-1,CONCRETE:12)
Block(-4,26,0,CONCRETE:12)
Block(-4,26,1,CONCRETE:12)
Block(-4,26,2,CONCRETE:12)
Block(-4,26,3,CONCRETE:12)
Block(-4,26,4,CONCRETE:12)
Block(-4,26,5,CONCRETE:12)
Block(-4,27,-9,CONCRETE)
Block(-4,27,-8,CONCRETE)
Block(-4,27,-7,CONCRETE)
Block(-4,27,-6,CONCRETE)
Block(-4,27,-5,CONCRETE)
Block(-4,27,-4,CONCRETE)
Block(-4,27,-3,CONCRETE)
Block(-4,27,-2,CONCRETE)
Block(-4,27,-1,CONCRETE)
Block(-4,27,0,CONCRETE)
Block(-4,27,1,CONCRETE)
Block(-4,27,2,CONCRETE)
Block(-4,27,3,CONCRETE)
Block(-4,27,4,CONCRETE)
Block(-4,28,-7,CONCRETE:14)
Block(-4,28,-6,CONCRETE:14)
Block(-4,28,-5,CONCRETE:14)
Block(-4,28,-4,CONCRETE:14)
Block(-4,28,-3,CONCRETE:14)
Block(-4,28,-2,CONCRETE:14)
Block(-4,28,-1,CONCRETE:14)
Block(-4,28,0,CONCRETE:14)
Block(-4,28,1,CONCRETE:14)
Block(-4,28,2,CONCRETE:14)
Block(-4,29,-4,CONCRETE:14)
Block(-4,29,-3,CONCRETE:14)
Block(-4,29,-2,CONCRETE:14)
Block(-4,29,-1,CONCRETE:14)
Block(-4,29,0,CONCRETE:14)
Block(-3,1,-3,CONCRETE)
Block(-3,1,-2,CONCRETE)
Block(-3,1,-1,CONCRETE)
Block(-3,1,0,CONCRETE)
Block(-3,1,1,CONCRETE)
Block(-3,1,2,CONCRETE)
Block(-3,1,3,CONCRETE)
Block(-3,1,4,CONCRETE)
Block(-3,2,-5,CONCRETE:1)
Block(-3,2,-4,CONCRETE:1)
Block(-3,2,-3,CONCRETE:1)
Block(-3,2,-2,CONCRETE:1)
Block(-3,2,-1,CONCRETE:1)
Block(-3,2,0,CONCRETE:1)
Block(-3,2,1,CONCRETE:1)
Block(-3,2,2,CONCRETE:1)
Block(-3,2,3,CONCRETE:1)
Block(-3,2,4,CONCRETE:1)
Block(-3,2,5,CONCRETE:1)
Block(-3,2,6,CONCRETE:1)
Block(-3,3,-7,CONCRETE:1)
Block(-3,3,-6,CONCRETE:1)
Block(-3,3,-5,CONCRETE:1)
Block(-3,3,-4,CONCRETE:1)
Block(-3,3,-3,CONCRETE:1)
Block(-3,3,-2,CONCRETE:1)
Block(-3,3,-1,CONCRETE:1)
Block(-3,3,0,CONCRETE:1)
Block(-3,3,1,CONCRETE:1)
Block(-3,3,2,CONCRETE:1)
Block(-3,3,3,CONCRETE:1)
Block(-3,3,4,CONCRETE:1)
Block(-3,3,5,CONCRETE:1)
Block(-3,3,6,CONCRETE:1)
Block(-3,3,7,CONCRETE:1)
Block(-3,4,-9,CONCRETE:14)
Block(-3,4,-8,CONCRETE:14)
Block(-3,4,-7,CONCRETE:14)
Block(-3,4,-6,CONCRETE:14)
Block(-3,4,-5,CONCRETE:14)
Block(-3,4,-4,CONCRETE:14)
Block(-3,4,-3,CONCRETE:14)
Block(-3,4,-2,CONCRETE:14)
Block(-3,4,-1,CONCRETE:14)
Block(-3,4,0,CONCRETE:14)
Block(-3,4,1,CONCRETE:14)
Block(-3,4,2,CONCRETE:14)
Block(-3,4,3,CONCRETE:14)
Block(-3,4,4,CONCRETE:14)
Block(-3,4,5,CONCRETE:14)
Block(-3,4,6,CONCRETE:14)
Block(-3,4,7,CONCRETE:14)
Block(-3,4,8,CONCRETE:14)
Block(-3,4,9,CONCRETE:14)
Block(-3,5,-10,CONCRETE)
Block(-3,5,-9,CONCRETE)
Block(-3,5,-8,CONCRETE)
Block(-3,5,-7,CONCRETE)
Block(-3,5,-6,CONCRETE)
Block(-3,5,-5,CONCRETE)
Block(-3,5,-4,CONCRETE)
Block(-3,5,-3,CONCRETE)
Block(-3,5,-2,CONCRETE)
Block(-3,5,-1,CONCRETE)
Block(-3,5,0,CONCRETE)
Block(-3,5,1,CONCRETE)
Block(-3,5,2,CONCRETE)
Block(-3,5,3,CONCRETE)
Block(-3,5,4,CONCRETE)
Block(-3,5,5,CONCRETE)
Block(-3,5,6,CONCRETE)
Block(-3,5,7,CONCRETE)
Block(-3,5,8,CONCRETE)
Block(-3,5,9,CONCRETE)
Block(-3,5,10,CONCRETE)
Block(-3,6,-11,CONCRETE)
Block(-3,6,-10,CONCRETE)
Block(-3,6,-9,CONCRETE)
Block(-3,6,-8,CONCRETE)
Block(-3,6,-7,CONCRETE)
Block(-3,6,-6,CONCRETE)
Block(-3,6,-5,CONCRETE)
Block(-3,6,-4,CONCRETE)
Block(-3,6,-3,CONCRETE)
Block(-3,6,-2,CONCRETE)
Block(-3,6,-1,CONCRETE)
Block(-3,6,0,CONCRETE)
Block(-3,6,1,CONCRETE)
Block(-3,6,2,CONCRETE)
Block(-3,6,3,CONCRETE)
Block(-3,6,4,CONCRETE)
Block(-3,6,5,CONCRETE)
Block(-3,6,6,CONCRETE)
Block(-3,6,7,CONCRETE)
Block(-3,6,8,CONCRETE)
Block(-3,6,9,CONCRETE)
Block(-3,6,10,CONCRETE)
Block(-3,7,-12,CONCRETE:8)
Block(-3,7,-11,CONCRETE:8)
Block(-3,7,-10,CONCRETE:8)
Block(-3,7,-9,CONCRETE:8)
Block(-3,7,-8,CONCRETE:8)
Block(-3,7,-7,CONCRETE:8)
Block(-3,7,-6,CONCRETE:8)
Block(-3,7,-5,CONCRETE:8)
Block(-3,7,-4,CONCRETE:8)
Block(-3,7,-3,CONCRETE:8)
Block(-3,7,-2,CONCRETE:8)
Block(-3,7,-1,CONCRETE:8)
Block(-3,7,0,CONCRETE:8)
Block(-3,7,1,CONCRETE:8)
Block(-3,7,2,CONCRETE:8)
Block(-3,7,3,CONCRETE:8)
Block(-3,7,4,CONCRETE:8)
Block(-3,7,5,CONCRETE:8)
Block(-3,7,6,CONCRETE:8)
Block(-3,7,7,CONCRETE:8)
Block(-3,7,8,CONCRETE:8)
Block(-3,7,9,CONCRETE:8)
Block(-3,7,10,CONCRETE:8)
Block(-3,7,11,CONCRETE:8)
Block(-3,8,-12,CONCRETE)
Block(-3,8,-11,CONCRETE)
Block(-3,8,-10,CONCRETE)
Block(-3,8,-9,CONCRETE)
Block(-3,8,-8,CONCRETE)
Block(-3,8,-7,CONCRETE)
Block(-3,8,-6,CONCRETE)
Block(-3,8,-5,CONCRETE)
Block(-3,8,-4,CONCRETE)
Block(-3,8,-3,CONCRETE)
Block(-3,8,-2,CONCRETE)
Block(-3,8,-1,CONCRETE)
Block(-3,8,0,CONCRETE)
Block(-3,8,1,CONCRETE)
Block(-3,8,2,CONCRETE)
Block(-3,8,3,CONCRETE)
Block(-3,8,4,CONCRETE)
Block(-3,8,5,CONCRETE)
Block(-3,8,6,CONCRETE)
Block(-3,8,7,CONCRETE)
Block(-3,8,8,CONCRETE)
Block(-3,8,9,CONCRETE)
Block(-3,8,10,CONCRETE)
Block(-3,8,11,CONCRETE)
Block(-3,9,-12,CONCRETE)
Block(-3,9,-11,CONCRETE)
Block(-3,9,-10,CONCRETE)
Block(-3,9,-9,CONCRETE)
Block(-3,9,-8,CONCRETE)
Block(-3,9,-7,CONCRETE)
Block(-3,9,-6,CONCRETE)
Block(-3,9,-5,CONCRETE)
Block(-3,9,-4,CONCRETE)
Block(-3,9,-3,CONCRETE)
Block(-3,9,-2,CONCRETE)
Block(-3,9,-1,CONCRETE)
Block(-3,9,0,CONCRETE)
Block(-3,9,1,CONCRETE)
Block(-3,9,2,CONCRETE)
Block(-3,9,3,CONCRETE)
Block(-3,9,4,CONCRETE)
Block(-3,9,5,CONCRETE)
Block(-3,9,6,CONCRETE)
Block(-3,9,7,CONCRETE)
Block(-3,9,8,CONCRETE)
Block(-3,9,9,CONCRETE)
Block(-3,9,10,CONCRETE)
Block(-3,9,11,CONCRETE)
Block(-3,9,12,CONCRETE)
Block(-3,10,-13,CONCRETE:15)
Block(-3,10,-12,CONCRETE:15)
Block(-3,10,-11,CONCRETE:15)
Block(-3,10,-10,CONCRETE:15)
Block(-3,10,-9,CONCRETE:15)
Block(-3,10,-8,CONCRETE:15)
Block(-3,10,-7,CONCRETE:15)
Block(-3,10,-6,CONCRETE:15)
Block(-3,10,-5,CONCRETE:15)
Block(-3,10,-4,CONCRETE:15)
Block(-3,10,-3,CONCRETE:15)
Block(-3,10,-2,CONCRETE:15)
Block(-3,10,-1,CONCRETE:15)
Block(-3,10,0,CONCRETE:15)
Block(-3,10,1,CONCRETE:15)
Block(-3,10,2,CONCRETE:15)
Block(-3,10,3,CONCRETE:15)
Block(-3,10,4,CONCRETE:15)
Block(-3,10,5,CONCRETE:15)
Block(-3,10,6,CONCRETE:15)
Block(-3,10,7,CONCRETE:15)
Block(-3,10,8,CONCRETE:15)
Block(-3,10,9,CONCRETE:15)
Block(-3,10,10,CONCRETE:15)
Block(-3,10,11,CONCRETE:15)
Block(-3,10,12,CONCRETE:15)
Block(-3,11,-13,CONCRETE:4)
Block(-3,11,-12,CONCRETE:4)
Block(-3,11,-11,CONCRETE:4)
Block(-3,11,-10,CONCRETE:4)
Block(-3,11,-9,CONCRETE:4)
Block(-3,11,-8,CONCRETE:4)
Block(-3,11,-7,CONCRETE:4)
Block(-3,11,-6,CONCRETE:4)
Block(-3,11,-5,CONCRETE:4)
Block(-3,11,-4,CONCRETE:4)
Block(-3,11,-3,CONCRETE:4)
Block(-3,11,-2,CONCRETE:4)
Block(-3,11,-1,CONCRETE:4)
Block(-3,11,0,CONCRETE:4)
Block(-3,11,1,CONCRETE:4)
Block(-3,11,2,CONCRETE:4)
Block(-3,11,3,CONCRETE:4)
Block(-3,11,4,CONCRETE:4)
Block(-3,11,5,CONCRETE:4)
Block(-3,11,6,CONCRETE:4)
Block(-3,11,7,CONCRETE:4)
Block(-3,11,8,CONCRETE:4)
Block(-3,11,9,CONCRETE:4)
Block(-3,11,10,CONCRETE:4)
Block(-3,11,11,CONCRETE:4)
Block(-3,11,12,CONCRETE:4)
Block(-3,12,-14,CONCRETE:1)
Block(-3,12,-13,CONCRETE:1)
Block(-3,12,-12,CONCRETE:1)
Block(-3,12,-11,CONCRETE:1)
Block(-3,12,-10,CONCRETE:1)
Block(-3,12,-9,CONCRETE:1)
Block(-3,12,-8,CONCRETE:1)
Block(-3,12,-7,CONCRETE:1)
Block(-3,12,-6,CONCRETE:1)
Block(-3,12,-5,CONCRETE:1)
Block(-3,12,-4,CONCRETE:1)
Block(-3,12,-3,CONCRETE:1)
Block(-3,12,-2,CONCRETE:1)
Block(-3,12,-1,CONCRETE:1)
Block(-3,12,0,CONCRETE:1)
Block(-3,12,1,CONCRETE:1)
Block(-3,12,2,CONCRETE:1)
Block(-3,12,3,CONCRETE:1)
Block(-3,12,4,CONCRETE:1)
Block(-3,12,5,CONCRETE:1)
Block(-3,12,6,CONCRETE:1)
Block(-3,12,7,CONCRETE:1)
Block(-3,12,8,CONCRETE:1)
Block(-3,12,9,CONCRETE:1)
Block(-3,12,10,CONCRETE:1)
Block(-3,12,11,CONCRETE:1)
Block(-3,12,12,CONCRETE:1)
Block(-3,12,13,CONCRETE:1)
Block(-3,13,-14,CONCRETE:14)
Block(-3,13,-13,CONCRETE:14)
Block(-3,13,-12,CONCRETE:14)
Block(-3,13,-11,CONCRETE:14)
Block(-3,13,-10,CONCRETE:14)
Block(-3,13,-9,CONCRETE:14)
Block(-3,13,-8,CONCRETE:14)
Block(-3,13,-7,CONCRETE:14)
Block(-3,13,-6,CONCRETE:14)
Block(-3,13,-5,CONCRETE:14)
Block(-3,13,-4,CONCRETE:14)
Block(-3,13,-3,CONCRETE:14)
Block(-3,13,-2,CONCRETE:14)
Block(-3,13,-1,CONCRETE:14)
Block(-3,13,0,CONCRETE:14)
Block(-3,13,1,CONCRETE:14)
Block(-3,13,2,CONCRETE:14)
Block(-3,13,3,CONCRETE:14)
Block(-3,13,4,CONCRETE:14)
Block(-3,13,5,CONCRETE:14)
Block(-3,13,6,CONCRETE:14)
Block(-3,13,7,CONCRETE:14)
Block(-3,13,8,CONCRETE:14)
Block(-3,13,9,CONCRETE:14)
Block(-3,13,10,CONCRETE:14)
Block(-3,13,11,CONCRETE:14)
Block(-3,13,12,CONCRETE:14)
Block(-3,13,13,CONCRETE:14)
Block(-3,14,-14,CONCRETE)
Block(-3,14,-13,CONCRETE)
Block(-3,14,-12,CONCRETE)
Block(-3,14,-11,CONCRETE)
Block(-3,14,-10,CONCRETE)
Block(-3,14,-9,CONCRETE)
Block(-3,14,-8,CONCRETE)
Block(-3,14,-7,CONCRETE)
Block(-3,14,-6,CONCRETE)
Block(-3,14,-5,CONCRETE)
Block(-3,14,-4,CONCRETE)
Block(-3,14,-3,CONCRETE)
Block(-3,14,-2,CONCRETE)
Block(-3,14,-1,CONCRETE)
Block(-3,14,0,CONCRETE)
Block(-3,14,1,CONCRETE)
Block(-3,14,2,CONCRETE)
Block(-3,14,3,CONCRETE)
Block(-3,14,4,CONCRETE)
Block(-3,14,5,CONCRETE)
Block(-3,14,6,CONCRETE)
Block(-3,14,7,CONCRETE)
Block(-3,14,8,CONCRETE)
Block(-3,14,9,CONCRETE)
Block(-3,14,10,CONCRETE)
Block(-3,14,11,CONCRETE)
Block(-3,14,12,CONCRETE)
Block(-3,14,13,CONCRETE)
Block(-3,15,-14,CONCRETE)
Block(-3,15,-13,CONCRETE)
Block(-3,15,-12,CONCRETE)
Block(-3,15,-11,CONCRETE)
Block(-3,15,-10,CONCRETE)
Block(-3,15,-9,CONCRETE)
Block(-3,15,-8,CONCRETE)
Block(-3,15,-7,CONCRETE)
Block(-3,15,-6,CONCRETE)
Block(-3,15,-5,CONCRETE)
Block(-3,15,-4,CONCRETE)
Block(-3,15,-3,CONCRETE)
Block(-3,15,-2,CONCRETE)
Block(-3,15,-1,CONCRETE)
Block(-3,15,0,CONCRETE)
Block(-3,15,1,CONCRETE)
Block(-3,15,2,CONCRETE)
Block(-3,15,3,CONCRETE)
Block(-3,15,4,CONCRETE)
Block(-3,15,5,CONCRETE)
Block(-3,15,6,CONCRETE)
Block(-3,15,7,CONCRETE)
Block(-3,15,8,CONCRETE)
Block(-3,15,9,CONCRETE)
Block(-3,15,10,CONCRETE)
Block(-3,15,11,CONCRETE)
Block(-3,15,12,CONCRETE)
Block(-3,15,13,CONCRETE)
Block(-3,16,-14,CONCRETE:12)
Block(-3,16,-13,CONCRETE:12)
Block(-3,16,-12,CONCRETE:12)
Block(-3,16,-11,CONCRETE:12)
Block(-3,16,-10,CONCRETE:12)
Block(-3,16,-9,CONCRETE:12)
Block(-3,16,-8,CONCRETE:12)
Block(-3,16,-7,CONCRETE:12)
Block(-3,16,-6,CONCRETE:12)
Block(-3,16,-5,CONCRETE:12)
Block(-3,16,-4,CONCRETE:12)
Block(-3,16,-3,CONCRETE:12)
Block(-3,16,-2,CONCRETE:12)
Block(-3,16,-1,CONCRETE:12)
Block(-3,16,0,CONCRETE:12)
Block(-3,16,1,CONCRETE:12)
Block(-3,16,2,CONCRETE:12)
Block(-3,16,3,CONCRETE:12)
Block(-3,16,4,CONCRETE:12)
Block(-3,16,5,CONCRETE:12)
Block(-3,16,6,CONCRETE:12)
Block(-3,16,7,CONCRETE:12)
Block(-3,16,8,CONCRETE:12)
Block(-3,16,9,CONCRETE:12)
Block(-3,16,10,CONCRETE:12)
Block(-3,16,11,CONCRETE:12)
Block(-3,16,12,CONCRETE:12)
Block(-3,17,-14,CONCRETE:15)
Block(-3,17,-13,CONCRETE:15)
Block(-3,17,-12,CONCRETE:15)
Block(-3,17,-11,CONCRETE:15)
Block(-3,17,-10,CONCRETE:15)
Block(-3,17,-9,CONCRETE:15)
Block(-3,17,-8,CONCRETE:15)
Block(-3,17,-7,CONCRETE:15)
Block(-3,17,-6,CONCRETE:15)
Block(-3,17,-5,CONCRETE:15)
Block(-3,17,-4,CONCRETE:15)
Block(-3,17,-3,CONCRETE:15)
Block(-3,17,-2,CONCRETE:15)
Block(-3,17,-1,CONCRETE:15)
Block(-3,17,0,CONCRETE:15)
Block(-3,17,1,CONCRETE:15)
Block(-3,17,2,CONCRETE:15)
Block(-3,17,3,CONCRETE:15)
Block(-3,17,4,CONCRETE:15)
Block(-3,17,5,CONCRETE:15)
Block(-3,17,6,CONCRETE:15)
Block(-3,17,7,CONCRETE:15)
Block(-3,17,8,CONCRETE:15)
Block(-3,17,9,CONCRETE:15)
Block(-3,17,10,CONCRETE:15)
Block(-3,17,11,CONCRETE:15)
Block(-3,18,-14,CONCRETE:12)
Block(-3,18,-13,CONCRETE:12)
Block(-3,18,-12,CONCRETE:12)
Block(-3,18,-11,CONCRETE:12)
Block(-3,18,-10,CONCRETE:12)
Block(-3,18,-9,CONCRETE:12)
Block(-3,18,-8,CONCRETE:12)
Block(-3,18,-7,CONCRETE:12)
Block(-3,18,-6,CONCRETE:12)
Block(-3,18,-5,CONCRETE:12)
Block(-3,18,-4,CONCRETE:12)
Block(-3,18,-3,CONCRETE:12)
Block(-3,18,-2,CONCRETE:12)
Block(-3,18,-1,CONCRETE:12)
Block(-3,18,0,CONCRETE:12)
Block(-3,18,1,CONCRETE:12)
Block(-3,18,2,CONCRETE:12)
Block(-3,18,3,CONCRETE:12)
Block(-3,18,4,CONCRETE:12)
Block(-3,18,5,CONCRETE:12)
Block(-3,18,6,CONCRETE:12)
Block(-3,18,7,CONCRETE:12)
Block(-3,18,8,CONCRETE:12)
Block(-3,18,9,CONCRETE:12)
Block(-3,18,10,CONCRETE:12)
Block(-3,18,11,CONCRETE:12)
Block(-3,19,-14,CONCRETE:1)
Block(-3,19,-13,CONCRETE:1)
Block(-3,19,-12,CONCRETE:1)
Block(-3,19,-11,CONCRETE:1)
Block(-3,19,-10,CONCRETE:1)
Block(-3,19,-9,CONCRETE:1)
Block(-3,19,-8,CONCRETE:1)
Block(-3,19,-7,CONCRETE:1)
Block(-3,19,-6,CONCRETE:1)
Block(-3,19,-5,CONCRETE:1)
Block(-3,19,-4,CONCRETE:1)
Block(-3,19,-3,CONCRETE:1)
Block(-3,19,-2,CONCRETE:1)
Block(-3,19,-1,CONCRETE:1)
Block(-3,19,0,CONCRETE:1)
Block(-3,19,1,CONCRETE:1)
Block(-3,19,2,CONCRETE:1)
Block(-3,19,3,CONCRETE:1)
Block(-3,19,4,CONCRETE:1)
Block(-3,19,5,CONCRETE:1)
Block(-3,19,6,CONCRETE:1)
Block(-3,19,7,CONCRETE:1)
Block(-3,19,8,CONCRETE:1)
Block(-3,19,9,CONCRETE:1)
Block(-3,19,10,CONCRETE:1)
Block(-3,20,-14,CONCRETE:1)
Block(-3,20,-13,CONCRETE:1)
Block(-3,20,-12,CONCRETE:1)
Block(-3,20,-11,CONCRETE:1)
Block(-3,20,-10,CONCRETE:1)
Block(-3,20,-9,CONCRETE:1)
Block(-3,20,-8,CONCRETE:1)
Block(-3,20,-7,CONCRETE:1)
Block(-3,20,-6,CONCRETE:1)
Block(-3,20,-5,CONCRETE:1)
Block(-3,20,-4,CONCRETE:1)
Block(-3,20,-3,CONCRETE:1)
Block(-3,20,-2,CONCRETE:1)
Block(-3,20,-1,CONCRETE:1)
Block(-3,20,0,CONCRETE:1)
Block(-3,20,1,CONCRETE:1)
Block(-3,20,2,CONCRETE:1)
Block(-3,20,3,CONCRETE:1)
Block(-3,20,4,CONCRETE:1)
Block(-3,20,5,CONCRETE:1)
Block(-3,20,6,CONCRETE:1)
Block(-3,20,7,CONCRETE:1)
Block(-3,20,8,CONCRETE:1)
Block(-3,20,9,CONCRETE:1)
Block(-3,21,-14,CONCRETE:1)
Block(-3,21,-13,CONCRETE:1)
Block(-3,21,-12,CONCRETE:1)
Block(-3,21,-11,CONCRETE:1)
Block(-3,21,-10,CONCRETE:1)
Block(-3,21,-9,CONCRETE:1)
Block(-3,21,-8,CONCRETE:1)
Block(-3,21,-7,CONCRETE:1)
Block(-3,21,-6,CONCRETE:1)
Block(-3,21,-5,CONCRETE:1)
Block(-3,21,-4,CONCRETE:1)
Block(-3,21,-3,CONCRETE:1)
Block(-3,21,-2,CONCRETE:1)
Block(-3,21,-1,CONCRETE:1)
Block(-3,21,0,CONCRETE:1)
Block(-3,21,1,CONCRETE:1)
Block(-3,21,2,CONCRETE:1)
Block(-3,21,3,CONCRETE:1)
Block(-3,21,4,CONCRETE:1)
Block(-3,21,5,CONCRETE:1)
Block(-3,21,6,CONCRETE:1)
Block(-3,21,7,CONCRETE:1)
Block(-3,21,8,CONCRETE:1)
Block(-3,21,9,CONCRETE:1)
Block(-3,22,-14,CONCRETE:14)
Block(-3,22,-13,CONCRETE:14)
Block(-3,22,-12,CONCRETE:14)
Block(-3,22,-11,CONCRETE:14)
Block(-3,22,-10,CONCRETE:14)
Block(-3,22,-9,CONCRETE:14)
Block(-3,22,-8,CONCRETE:14)
Block(-3,22,-7,CONCRETE:14)
Block(-3,22,-6,CONCRETE:14)
Block(-3,22,-5,CONCRETE:14)
Block(-3,22,-4,CONCRETE:14)
Block(-3,22,-3,CONCRETE:14)
Block(-3,22,-2,CONCRETE:14)
Block(-3,22,-1,CONCRETE:14)
Block(-3,22,0,CONCRETE:14)
Block(-3,22,1,CONCRETE:14)
Block(-3,22,2,CONCRETE:14)
Block(-3,22,3,CONCRETE:14)
Block(-3,22,4,CONCRETE:14)
Block(-3,22,5,CONCRETE:14)
Block(-3,22,6,CONCRETE:14)
Block(-3,22,7,CONCRETE:14)
Block(-3,22,8,CONCRETE:14)
Block(-3,23,-13,CONCRETE)
Block(-3,23,-12,CONCRETE)
Block(-3,23,-11,CONCRETE)
Block(-3,23,-10,CONCRETE)
Block(-3,23,-9,CONCRETE)
Block(-3,23,-8,CONCRETE)
Block(-3,23,-7,CONCRETE)
Block(-3,23,-6,CONCRETE)
Block(-3,23,-5,CONCRETE)
Block(-3,23,-4,CONCRETE)
Block(-3,23,-3,CONCRETE)
Block(-3,23,-2,CONCRETE)
Block(-3,23,-1,CONCRETE)
Block(-3,23,0,CONCRETE)
Block(-3,23,1,CONCRETE)
Block(-3,23,2,CONCRETE)
Block(-3,23,3,CONCRETE)
Block(-3,23,4,CONCRETE)
Block(-3,23,5,CONCRETE)
Block(-3,23,6,CONCRETE)
Block(-3,23,7,CONCRETE)
Block(-3,23,8,CONCRETE)
Block(-3,24,-12,CONCRETE:4)
Block(-3,24,-11,CONCRETE:4)
Block(-3,24,-10,CONCRETE:4)
Block(-3,24,-9,CONCRETE:4)
Block(-3,24,-8,CONCRETE:4)
Block(-3,24,-7,CONCRETE:4)
Block(-3,24,-6,CONCRETE:4)
Block(-3,24,-5,CONCRETE:4)
Block(-3,24,-4,CONCRETE:4)
Block(-3,24,-3,CONCRETE:4)
Block(-3,24,-2,CONCRETE:4)
Block(-3,24,-1,CONCRETE:4)
Block(-3,24,0,CONCRETE:4)
Block(-3,24,1,CONCRETE:4)
Block(-3,24,2,CONCRETE:4)
Block(-3,24,3,CONCRETE:4)
Block(-3,24,4,CONCRETE:4)
Block(-3,24,5,CONCRETE:4)
Block(-3,24,6,CONCRETE:4)
Block(-3,24,7,CONCRETE:4)
Block(-3,24,8,CONCRETE:4)
Block(-3,25,-11,CONCRETE:12)
Block(-3,25,-10,CONCRETE:12)
Block(-3,25,-9,CONCRETE:12)
Block(-3,25,-8,CONCRETE:12)
Block(-3,25,-7,CONCRETE:12)
Block(-3,25,-6,CONCRETE:12)
Block(-3,25,-5,CONCRETE:12)
Block(-3,25,-4,CONCRETE:12)
Block(-3,25,-3,CONCRETE:12)
Block(-3,25,-2,CONCRETE:12)
Block(-3,25,-1,CONCRETE:12)
Block(-3,25,0,CONCRETE:12)
Block(-3,25,1,CONCRETE:12)
Block(-3,25,2,CONCRETE:12)
Block(-3,25,3,CONCRETE:12)
Block(-3,25,4,CONCRETE:12)
Block(-3,25,5,CONCRETE:12)
Block(-3,25,6,CONCRETE:12)
Block(-3,25,7,CONCRETE:12)
Block(-3,26,-10,CONCRETE:12)
Block(-3,26,-9,CONCRETE:12)
Block(-3,26,-8,CONCRETE:12)
Block(-3,26,-7,CONCRETE:12)
Block(-3,26,-6,CONCRETE:12)
Block(-3,26,-5,CONCRETE:12)
Block(-3,26,-4,CONCRETE:12)
Block(-3,26,-3,CONCRETE:12)
Block(-3,26,-2,CONCRETE:12)
Block(-3,26,-1,CONCRETE:12)
Block(-3,26,0,CONCRETE:12)
Block(-3,26,1,CONCRETE:12)
Block(-3,26,2,CONCRETE:12)
Block(-3,26,3,CONCRETE:12)
Block(-3,26,4,CONCRETE:12)
Block(-3,26,5,CONCRETE:12)
Block(-3,26,6,CONCRETE:12)
Block(-3,27,-9,CONCRETE)
Block(-3,27,-8,CONCRETE)
Block(-3,27,-7,CONCRETE)
Block(-3,27,-6,CONCRETE)
Block(-3,27,-5,CONCRETE)
Block(-3,27,-4,CONCRETE)
Block(-3,27,-3,CONCRETE)
Block(-3,27,-2,CONCRETE)
Block(-3,27,-1,CONCRETE)
Block(-3,27,0,CONCRETE)
Block(-3,27,1,CONCRETE)
Block(-3,27,2,CONCRETE)
Block(-3,27,3,CONCRETE)
Block(-3,27,4,CONCRETE)
Block(-3,28,-8,CONCRETE:14)
Block(-3,28,-7,CONCRETE:14)
Block(-3,28,-6,CONCRETE:14)
Block(-3,28,-5,CONCRETE:14)
Block(-3,28,-4,CONCRETE:14)
Block(-3,28,-3,CONCRETE:14)
Block(-3,28,-2,CONCRETE:14)
Block(-3,28,-1,CONCRETE:14)
Block(-3,28,0,CONCRETE:14)
Block(-3,28,1,CONCRETE:14)
Block(-3,28,2,CONCRETE:14)
Block(-3,28,3,CONCRETE:14)
Block(-3,29,-6,CONCRETE:14)
Block(-3,29,-5,CONCRETE:14)
Block(-3,29,-4,CONCRETE:14)
Block(-3,29,-3,CONCRETE:14)
Block(-3,29,-2,CONCRETE:14)
Block(-3,29,-1,CONCRETE:14)
Block(-3,29,0,CONCRETE:14)
Block(-3,29,1,CONCRETE:14)
Block(-2,0,0,CONCRETE)
Block(-2,1,-4,CONCRETE)
Block(-2,1,-3,CONCRETE)
Block(-2,1,-2,CONCRETE)
Block(-2,1,-1,CONCRETE)
Block(-2,1,0,CONCRETE)
Block(-2,1,1,CONCRETE)
Block(-2,1,2,CONCRETE)
Block(-2,1,3,CONCRETE)
Block(-2,1,4,CONCRETE)
Block(-2,2,-6,CONCRETE:1)
Block(-2,2,-5,CONCRETE:1)
Block(-2,2,-4,CONCRETE:1)
Block(-2,2,-3,CONCRETE:1)
Block(-2,2,-2,CONCRETE:1)
Block(-2,2,-1,CONCRETE:1)
Block(-2,2,0,CONCRETE:1)
Block(-2,2,1,CONCRETE:1)
Block(-2,2,2,CONCRETE:1)
Block(-2,2,3,CONCRETE:1)
Block(-2,2,4,CONCRETE:1)
Block(-2,2,5,CONCRETE:1)
Block(-2,2,6,CONCRETE:1)
Block(-2,3,-8,CONCRETE:1)
Block(-2,3,-7,CONCRETE:1)
Block(-2,3,-6,CONCRETE:1)
Block(-2,3,-5,CONCRETE:1)
Block(-2,3,-4,CONCRETE:1)
Block(-2,3,-3,CONCRETE:1)
Block(-2,3,-2,CONCRETE:1)
Block(-2,3,-1,CONCRETE:1)
Block(-2,3,0,CONCRETE:1)
Block(-2,3,1,CONCRETE:1)
Block(-2,3,2,CONCRETE:1)
Block(-2,3,3,CONCRETE:1)
Block(-2,3,4,CONCRETE:1)
Block(-2,3,5,CONCRETE:1)
Block(-2,3,6,CONCRETE:1)
Block(-2,3,7,CONCRETE:1)
Block(-2,3,8,CONCRETE:1)
Block(-2,4,-9,CONCRETE:14)
Block(-2,4,-8,CONCRETE:14)
Block(-2,4,-7,CONCRETE:14)
Block(-2,4,-6,CONCRETE:14)
Block(-2,4,-5,CONCRETE:14)
Block(-2,4,-4,CONCRETE:14)
Block(-2,4,-3,CONCRETE:14)
Block(-2,4,-2,CONCRETE:14)
Block(-2,4,-1,CONCRETE:14)
Block(-2,4,0,CONCRETE:14)
Block(-2,4,1,CONCRETE:14)
Block(-2,4,2,CONCRETE:14)
Block(-2,4,3,CONCRETE:14)
Block(-2,4,4,CONCRETE:14)
Block(-2,4,5,CONCRETE:14)
Block(-2,4,6,CONCRETE:14)
Block(-2,4,7,CONCRETE:14)
Block(-2,4,8,CONCRETE:14)
Block(-2,4,9,CONCRETE:14)
Block(-2,5,-10,CONCRETE)
Block(-2,5,-9,CONCRETE)
Block(-2,5,-8,CONCRETE)
Block(-2,5,-7,CONCRETE)
Block(-2,5,-6,CONCRETE)
Block(-2,5,-5,CONCRETE)
Block(-2,5,-4,CONCRETE)
Block(-2,5,-3,CONCRETE)
Block(-2,5,-2,CONCRETE)
Block(-2,5,-1,CONCRETE)
Block(-2,5,0,CONCRETE)
Block(-2,5,1,CONCRETE)
Block(-2,5,2,CONCRETE)
Block(-2,5,3,CONCRETE)
Block(-2,5,4,CONCRETE)
Block(-2,5,5,CONCRETE)
Block(-2,5,6,CONCRETE)
Block(-2,5,7,CONCRETE)
Block(-2,5,8,CONCRETE)
Block(-2,5,9,CONCRETE)
Block(-2,5,10,CONCRETE)
Block(-2,6,-11,CONCRETE)
Block(-2,6,-10,CONCRETE)
Block(-2,6,-9,CONCRETE)
Block(-2,6,-8,CONCRETE)
Block(-2,6,-7,CONCRETE)
Block(-2,6,-6,CONCRETE)
Block(-2,6,-5,CONCRETE)
Block(-2,6,-4,CONCRETE)
Block(-2,6,-3,CONCRETE)
Block(-2,6,-2,CONCRETE)
Block(-2,6,-1,CONCRETE)
Block(-2,6,0,CONCRETE)
Block(-2,6,1,CONCRETE)
Block(-2,6,2,CONCRETE)
Block(-2,6,3,CONCRETE)
Block(-2,6,4,CONCRETE)
Block(-2,6,5,CONCRETE)
Block(-2,6,6,CONCRETE)
Block(-2,6,7,CONCRETE)
Block(-2,6,8,CONCRETE)
Block(-2,6,9,CONCRETE)
Block(-2,6,10,CONCRETE)
Block(-2,6,11,CONCRETE)
Block(-2,7,-11,CONCRETE:8)
Block(-2,7,-10,CONCRETE:8)
Block(-2,7,-9,CONCRETE:8)
Block(-2,7,-8,CONCRETE:8)
Block(-2,7,-7,CONCRETE:8)
Block(-2,7,-6,CONCRETE:8)
Block(-2,7,-5,CONCRETE:8)
Block(-2,7,-4,CONCRETE:8)
Block(-2,7,-3,CONCRETE:8)
Block(-2,7,-2,CONCRETE:8)
Block(-2,7,-1,CONCRETE:8)
Block(-2,7,0,CONCRETE:8)
Block(-2,7,1,CONCRETE:8)
Block(-2,7,2,CONCRETE:8)
Block(-2,7,3,CONCRETE:8)
Block(-2,7,4,CONCRETE:8)
Block(-2,7,5,CONCRETE:8)
Block(-2,7,6,CONCRETE:8)
Block(-2,7,7,CONCRETE:8)
Block(-2,7,8,CONCRETE:8)
Block(-2,7,9,CONCRETE:8)
Block(-2,7,10,CONCRETE:8)
Block(-2,7,11,CONCRETE:8)
Block(-2,8,-12,CONCRETE)
Block(-2,8,-11,CONCRETE)
Block(-2,8,-10,CONCRETE)
Block(-2,8,-9,CONCRETE)
Block(-2,8,-8,CONCRETE)
Block(-2,8,-7,CONCRETE)
Block(-2,8,-6,CONCRETE)
Block(-2,8,-5,CONCRETE)
Block(-2,8,-4,CONCRETE)
Block(-2,8,-3,CONCRETE)
Block(-2,8,-2,CONCRETE)
Block(-2,8,-1,CONCRETE)
Block(-2,8,0,CONCRETE)
Block(-2,8,1,CONCRETE)
Block(-2,8,2,CONCRETE)
Block(-2,8,3,CONCRETE)
Block(-2,8,4,CONCRETE)
Block(-2,8,5,CONCRETE)
Block(-2,8,6,CONCRETE)
Block(-2,8,7,CONCRETE)
Block(-2,8,8,CONCRETE)
Block(-2,8,9,CONCRETE)
Block(-2,8,10,CONCRETE)
Block(-2,8,11,CONCRETE)
Block(-2,8,12,CONCRETE)
Block(-2,9,-12,CONCRETE)
Block(-2,9,-11,CONCRETE)
Block(-2,9,-10,CONCRETE)
Block(-2,9,-9,CONCRETE)
Block(-2,9,-8,CONCRETE)
Block(-2,9,-7,CONCRETE)
Block(-2,9,-6,CONCRETE)
Block(-2,9,-5,CONCRETE)
Block(-2,9,-4,CONCRETE)
Block(-2,9,-3,CONCRETE)
Block(-2,9,-2,CONCRETE)
Block(-2,9,-1,CONCRETE)
Block(-2,9,0,CONCRETE)
Block(-2,9,1,CONCRETE)
Block(-2,9,2,CONCRETE)
Block(-2,9,3,CONCRETE)
Block(-2,9,4,CONCRETE)
Block(-2,9,5,CONCRETE)
